File: TGA/cellulose sponge 1.txt
CLOSED
Version	1
Language	English
Run	1
RunSerial	819
Instrument	TGA Q500 V6.7 Build 203
Module	TGA
InstSerial	0500-0499
Operator	at615
File	C:\TA\Data\TGA\ak794\anders\cellulose sponge 1.001
FurnaceType	Standard
Sample	Cellulose sponge 1
Size	1.386	mg
ProcName
Method
Comment
Xcomment	Pan: Platinum
Xcomment	Gas1: Air
Xcomment	Gas2: Air
Xcomment	Balance Gas: Air 40.0 ml/min
Xcomment	Sample Gas: Air 60.0 ml/min
Text	cellulose degradation
Kcell	1
TempCal	3	pts	20	"20.00,364.00"	"356.00,776.00"	770
InstCalDate	Weight Date 2013-03-01 10:10:44
Controls	Gas 2  Event Off  Sampling 2.0
Nsig	3
Sig1	Time (min)
Sig2	Temperature (°C)
Sig3	Weight (mg)
AirCoolTime	20.0 min
AutoAnalysis	Off
MacroFile
Date	11/03/2013
Time	09:57:57
OrgMethod	1: Ramp 10.00 °C/min to 600.00 °C
OrgFile	C:\Users\AIM_Group\Desktop\post doc cambridge\Students files\Internships\Anders\anders tga\anders\cellulose sponge 1.001
.001116667 16.12102 1.385537
0.05000000 16.12762 1.384716
0.1166666 16.23988 1.384745
0.1833334 16.45608 1.385500
0.2500000 16.75990 1.384953
0.3166666 17.13296 1.385181
0.3833333 17.55793 1.385579
0.4500000 18.02719 1.385475
0.5166666 18.53028 1.384789
0.5833332 19.06101 1.385419
0.6500000 19.61532 1.385001
0.7166666 20.18973 1.384586
0.7833334 20.78066 1.384348
0.8500000 21.38586 1.384271
0.9166668 22.00075 1.383828
0.9833334 22.62752 1.383208
1.050000 23.25895 1.382398
1.116667 23.89786 1.381861
1.183333 24.54033 1.381684
1.250000 25.18663 1.381581
1.316667 25.83473 1.381280
1.383333 26.48392 1.380864
1.450000 27.13429 1.380769
1.516666 27.78466 1.380546
1.583334 28.43258 1.379228
1.650000 29.08506 1.378899
1.716667 29.73313 1.378565
1.783333 30.38159 1.378040
1.850000 31.02858 1.377417
1.916666 31.67724 1.376983
1.983334 32.32315 1.376706
2.050000 32.97095 1.376455
2.116666 33.61575 1.376082
2.183334 34.26062 1.375512
2.250000 34.90424 1.375132
2.316666 35.54861 1.374653
2.383334 36.19306 1.374130
2.450000 36.83790 1.374064
2.516666 37.48234 1.373892
2.583333 38.12654 1.373390
2.650000 38.77130 1.373241
2.716667 39.41678 1.372758
2.783333 40.06288 1.372349
2.850000 40.71009 1.372407
2.916667 41.35887 1.372012
2.983334 42.00461 1.371345
3.050000 42.65356 1.370932
3.116666 43.30124 1.370484
3.183334 43.95220 1.370697
3.250000 44.60292 1.370496
3.316666 45.25329 1.369819
3.383334 45.90626 1.369515
3.450000 46.55920 1.369368
3.516667 47.21283 1.369306
3.583333 47.86744 1.368922
3.650000 48.52295 1.369000
3.716667 49.17824 1.368231
3.783333 49.83482 1.368368
3.850000 50.49150 1.367970
3.916667 51.14804 1.366941
3.983333 51.80616 1.366792
4.050000 52.46472 1.366227
4.116667 53.12494 1.366178
4.183334 53.78637 1.366317
4.250000 54.44746 1.365882
4.316666 55.10756 1.365095
4.383333 55.76665 1.364622
4.450000 56.42994 1.365156
4.516667 57.09100 1.364563
4.583334 57.75492 1.364742
4.650000 58.41886 1.364408
4.716667 59.08190 1.364362
4.783333 59.74524 1.364316
4.850000 60.41016 1.364456
4.916666 61.07257 1.363418
4.983333 61.73645 1.363208
5.050000 62.39995 1.362852
5.116667 63.06402 1.362712
5.183334 63.72916 1.362651
5.250000 64.39901 1.363848
5.316666 65.06241 1.362508
5.383332 65.72744 1.362278
5.450000 66.39566 1.362430
5.516668 67.06296 1.362553
5.583334 67.72626 1.361692
5.650000 68.39413 1.361983
5.716668 69.06048 1.361627
5.783332 69.72918 1.361776
5.850000 70.39594 1.361400
5.916666 71.06301 1.361304
5.983332 71.73043 1.360913
6.050000 72.39710 1.360644
6.116668 73.06412 1.360386
6.183334 73.73028 1.360399
6.250000 74.39795 1.360223
6.316666 75.06470 1.360156
6.383332 75.73153 1.359842
6.450000 76.39790 1.359779
6.516668 77.06408 1.359694
6.583334 77.73141 1.359511
6.650000 78.39955 1.359433
6.716666 79.06494 1.359166
6.783334 79.73199 1.359079
6.850000 80.39888 1.359040
6.916666 81.06811 1.358929
6.983332 81.73706 1.358824
7.050000 82.40392 1.358832
7.116668 83.07176 1.358474
7.183334 83.73707 1.358308
7.250000 84.40587 1.358456
7.316666 85.07019 1.357964
7.383332 85.73900 1.358155
7.450000 86.40580 1.357917
7.516668 87.07251 1.357732
7.583334 87.73897 1.357619
7.650000 88.40918 1.357926
7.716666 89.07776 1.358248
7.783334 89.74116 1.356990
7.850000 90.40697 1.356828
7.916666 91.07319 1.356727
7.983332 91.74082 1.356953
8.050000 92.40825 1.356768
8.116668 93.07700 1.356982
8.183334 93.74320 1.356522
8.250000 94.41116 1.356691
8.316666 95.07739 1.356421
8.383332 95.74355 1.356261
8.450000 96.40936 1.356186
8.516666 97.07438 1.355695
8.583332 97.73866 1.355776
8.650000 98.40812 1.355929
8.716666 99.07426 1.355769
8.783334 99.74319 1.355867
8.850000 100.4118 1.355809
8.916668 101.0815 1.355993
8.983334 101.7482 1.355679
9.050000 102.4100 1.354803
9.116668 103.0798 1.355621
9.183334 103.7470 1.355426
9.250000 104.4112 1.355043
9.316666 105.0758 1.354794
9.383332 105.7440 1.355138
9.450000 106.4081 1.354480
9.516666 107.0756 1.354670
9.583332 107.7448 1.354921
9.650000 108.4148 1.355123
9.716666 109.0828 1.354989
9.783334 109.7435 1.353790
9.850000 110.4094 1.354330
9.916668 111.0724 1.353624
9.983334 111.7395 1.353674
10.05000 112.4078 1.354044
10.11667 113.0742 1.353754
10.18333 113.7447 1.354532
10.25000 114.4095 1.353693
10.31667 115.0786 1.354083
10.38333 115.7468 1.354147
10.45000 116.4119 1.353569
10.51666 117.0776 1.353287
10.58333 117.7453 1.353569
10.65000 118.4124 1.353491
10.71666 119.0744 1.352861
10.78334 119.7406 1.352849
10.85000 120.4072 1.352624
10.91667 121.0865 1.354797
10.98334 121.7490 1.353315
11.05000 122.4089 1.352008
11.11667 123.0744 1.352716
11.18334 123.7420 1.352884
11.25000 124.4068 1.352759
11.31666 125.0734 1.352414
11.38333 125.7405 1.352499
11.45000 126.4067 1.352590
11.51666 127.0724 1.352188
11.58333 127.7379 1.351988
11.65000 128.4056 1.352364
11.71666 129.0719 1.351937
11.78334 129.7374 1.351834
11.85000 130.4057 1.351891
11.91667 131.0759 1.352337
11.98334 131.7421 1.351912
12.05000 132.4003 1.350719
12.11667 133.0692 1.351374
12.18334 133.7406 1.352112
12.25000 134.4094 1.351991
12.31666 135.0735 1.351490
12.38333 135.7407 1.351562
12.45000 136.4026 1.350960
12.51666 137.0665 1.350738
12.58333 137.7356 1.351213
12.65000 138.4037 1.351259
12.71666 139.0650 1.350276
12.78334 139.7360 1.350966
12.85000 140.4030 1.350855
12.91667 141.0676 1.350495
12.98334 141.7341 1.350312
13.05000 142.4021 1.350592
13.11667 143.0711 1.350804
13.18333 143.7363 1.350378
13.25000 144.4031 1.350394
13.31667 145.0714 1.350619
13.38333 145.7378 1.350478
13.45000 146.3980 1.349459
13.51666 147.0692 1.350600
13.58333 147.7330 1.350166
13.65000 148.3955 1.349409
13.71666 149.0650 1.350029
13.78334 149.7326 1.349994
13.85000 150.3961 1.349474
13.91667 151.0620 1.349216
13.98334 151.7293 1.349578
14.05000 152.3999 1.349957
14.11667 153.0637 1.349316
14.18333 153.7293 1.349276
14.25000 154.3948 1.349315
14.31667 155.0603 1.349251
14.38333 155.7276 1.349426
14.45000 156.3975 1.349619
14.51666 157.0642 1.349384
14.58333 157.7329 1.349170
14.65000 158.3942 1.348306
14.71666 159.0569 1.348059
14.78334 159.7217 1.347875
14.85000 160.3922 1.348530
14.91667 161.0566 1.348019
14.98334 161.7232 1.347802
15.05000 162.3908 1.347944
15.11667 163.0562 1.347604
15.18333 163.7231 1.347740
15.25000 164.3871 1.347447
15.31667 165.0603 1.348147
15.38333 165.7266 1.347752
15.45000 166.3949 1.347885
15.51666 167.0649 1.348017
15.58333 167.7302 1.347700
15.65000 168.3888 1.346982
15.71666 169.0469 1.346188
15.78334 169.7144 1.346784
15.85000 170.3828 1.347052
15.91667 171.0570 1.347638
15.98334 171.7220 1.346962
16.05000 172.3866 1.346837
16.11667 173.0482 1.346306
16.18333 173.7145 1.346398
16.25000 174.3786 1.346184
16.31667 175.0458 1.346349
16.38333 175.7174 1.346720
16.45000 176.3840 1.346417
16.51666 177.0466 1.345864
16.58334 177.7151 1.346008
16.65000 178.3810 1.345928
16.71667 179.0479 1.345805
16.78333 179.7159 1.346062
16.85000 180.3822 1.345771
16.91666 181.0474 1.345766
16.98334 181.7124 1.345383
17.05000 182.3811 1.345455
17.11667 183.0454 1.345152
17.18333 183.7103 1.345098
17.25000 184.3742 1.344828
17.31667 185.0439 1.345005
17.38333 185.7112 1.344914
17.45000 186.3752 1.344434
17.51666 187.0444 1.344810
17.58334 187.7046 1.343956
17.65000 188.3706 1.344086
17.71667 189.0342 1.343690
17.78333 189.7098 1.344705
17.85000 190.3812 1.344816
17.91666 191.0460 1.343994
17.98334 191.7095 1.343732
18.05000 192.3740 1.343554
18.11667 193.0356 1.343132
18.18333 193.7006 1.342889
18.25000 194.3698 1.343420
18.31667 195.0369 1.342958
18.38333 195.7043 1.343044
18.45000 196.3711 1.342782
18.51666 197.0384 1.342541
18.58334 197.7049 1.342601
18.65000 198.3743 1.342829
18.71667 199.0408 1.342498
18.78333 199.7043 1.342053
18.85000 200.3636 1.341320
18.91666 201.0343 1.341940
18.98334 201.6965 1.341351
19.05000 202.3666 1.341595
19.11667 203.0326 1.341317
19.18333 203.7029 1.341599
19.25000 204.3658 1.340938
19.31667 205.0242 1.340171
19.38333 205.6914 1.340657
19.45000 206.3639 1.340922
19.51666 207.0339 1.341057
19.58334 207.6926 1.339935
19.65000 208.3590 1.340151
19.71667 209.0241 1.340029
19.78333 209.6902 1.339850
19.85000 210.3562 1.339587
19.91666 211.0209 1.339169
19.98334 211.6848 1.339170
20.05000 212.3520 1.339031
20.11667 213.0172 1.338666
20.18333 213.6858 1.338712
20.25000 214.3553 1.338788
20.31667 215.0209 1.338261
20.38333 215.6916 1.338569
20.45000 216.3541 1.337704
20.51666 217.0195 1.337754
20.58334 217.6828 1.337129
20.65000 218.3496 1.337066
20.71667 219.0175 1.337019
20.78333 219.6861 1.336872
20.85000 220.3476 1.336082
20.91666 221.0108 1.335622
20.98334 221.6793 1.335819
21.05000 222.3552 1.336445
21.11667 223.0183 1.335397
21.18333 223.6806 1.334932
21.25000 224.3441 1.334362
21.31667 225.0184 1.335029
21.38333 225.6807 1.334012
21.45000 226.3460 1.333606
21.51666 227.0145 1.333549
21.58334 227.6803 1.333185
21.65000 228.3468 1.332672
21.71667 229.0145 1.332480
21.78333 229.6834 1.332248
21.85000 230.3540 1.332279
21.91666 231.0163 1.331156
21.98334 231.6777 1.330386
22.05000 232.3424 1.329975
22.11667 233.0148 1.330246
22.18333 233.6832 1.329844
22.25000 234.3452 1.328592
22.31667 235.0090 1.328095
22.38333 235.6728 1.327491
22.45000 236.3440 1.327470
22.51666 237.0138 1.326877
22.58334 237.6796 1.326063
22.65000 238.3459 1.325488
22.71667 239.0135 1.324932
22.78333 239.6789 1.324152
22.85000 240.3446 1.323494
22.91666 241.0088 1.322465
22.98334 241.6787 1.322204
23.05000 242.3438 1.321191
23.11667 243.0078 1.320194
23.18333 243.6734 1.319442
23.25000 244.3400 1.318516
23.31667 245.0062 1.317509
23.38333 245.6755 1.316671
23.45000 246.3427 1.315706
23.51666 247.0106 1.314711
23.58334 247.6762 1.313552
23.65000 248.3418 1.312392
23.71667 249.0116 1.311500
23.78333 249.6804 1.310503
23.85000 250.3417 1.308601
23.91666 251.0075 1.307391
23.98334 251.6732 1.306030
24.05000 252.3360 1.304268
24.11667 253.0011 1.302948
24.18333 253.6652 1.301292
24.25000 254.3371 1.300187
24.31667 255.0129 1.299295
24.38333 255.6806 1.297446
24.45000 256.3377 1.294592
24.51666 256.9941 1.292445
24.58334 257.6675 1.291668
24.65000 258.3401 1.290034
24.71667 259.0137 1.288694
24.78333 259.6722 1.285806
24.85000 260.3414 1.284354
24.91666 261.0031 1.281705
24.98334 261.6681 1.279717
25.05000 262.3322 1.277458
25.11667 263.0021 1.275646
25.18333 263.6704 1.273336
25.25000 264.3354 1.270841
25.31667 265.0036 1.268791
25.38333 265.6630 1.265666
25.45000 266.3254 1.262992
25.51666 266.9920 1.260649
25.58334 267.6650 1.258656
25.65000 268.3367 1.256344
25.71667 269.0066 1.253871
25.78333 269.6704 1.250639
25.85000 270.3350 1.247790
25.91666 271.0009 1.245130
25.98334 271.6655 1.242077
26.05000 272.3308 1.239026
26.11666 272.9938 1.235830
26.18333 273.6592 1.232506
26.25000 274.3359 1.230320
26.31667 275.0115 1.227480
26.38334 275.6791 1.223961
26.45000 276.3299 1.219127
26.51666 276.9913 1.215840
26.58334 277.6575 1.212521
26.65000 278.3338 1.209645
26.71667 279.0022 1.205730
26.78333 279.6578 1.200526
26.85000 280.3389 1.198449
26.91666 281.0033 1.193604
26.98334 281.6634 1.188758
27.05000 282.3332 1.185209
27.11666 282.9928 1.179672
27.18333 283.6582 1.175433
27.25000 284.3274 1.170961
27.31667 284.9954 1.166266
27.38334 285.6621 1.161159
27.45000 286.3308 1.156189
27.51666 286.9961 1.150737
27.58334 287.6687 1.146015
27.65000 288.3295 1.139628
27.71667 288.9980 1.134473
27.78333 289.6600 1.128061
27.85000 290.3260 1.122139
27.91666 290.9910 1.115852
27.98334 291.6542 1.109081
28.05000 292.3223 1.102794
28.11666 292.9987 1.097069
28.18333 293.6620 1.089272
28.25000 294.3287 1.082237
28.31667 294.9942 1.074913
28.38334 295.6592 1.067278
28.45000 296.3288 1.059936
28.51666 296.9973 1.051994
28.58334 297.6610 1.043710
28.65000 298.3304 1.035614
28.71667 298.9950 1.026930
28.78333 299.6616 1.018223
28.85000 300.3229 1.008825
28.91666 300.9894 0.9997625
28.98334 301.6564 0.9903303
29.05000 302.3234 0.9807256
29.11666 302.9913 0.9709416
29.18333 303.6577 0.9608330
29.25000 304.3250 0.9505800
29.31667 304.9956 0.9405099
29.38334 305.6590 0.9292906
29.45000 306.3229 0.9181939
29.51666 306.9877 0.9070786
29.58334 307.6573 0.8959444
29.65000 308.3181 0.8838653
29.71667 308.9827 0.8719906
29.78333 309.6474 0.8599214
29.85000 310.3132 0.8476626
29.91666 310.9800 0.8351922
29.98334 311.6552 0.8232288
30.05000 312.3348 0.8113939
30.11666 312.9946 0.7974335
30.18333 313.6492 0.7837466
30.25000 314.3132 0.7708762
30.31667 314.9823 0.7580203
30.38334 315.6424 0.7437329
30.45000 316.3148 0.7309132
30.51666 316.9804 0.7170188
30.58334 317.6508 0.7035181
30.65000 318.3255 0.6904340
30.71667 318.9900 0.6761848
30.78333 319.6556 0.6623194
30.85000 320.3177 0.6482695
30.91666 320.9795 0.6342058
30.98334 321.6450 0.6203716
31.05000 322.3114 0.6064820
31.11666 322.9852 0.5930290
31.18333 323.6560 0.5793945
31.25000 324.3163 0.5646889
31.31667 324.9790 0.5508448
31.38334 325.6489 0.5375937
31.45000 326.3241 0.5247284
31.51666 326.9880 0.5106298
31.58334 327.6475 0.4968527
31.65000 328.3098 0.4832721
31.71667 328.9780 0.4705104
31.78333 329.6463 0.4572859
31.85000 330.3153 0.4442685
31.91666 330.9882 0.4320407
31.98334 331.6541 0.4190897
32.05000 332.3137 0.4059717
32.11666 332.9869 0.3944312
32.18334 333.6550 0.3824684
32.25000 334.3206 0.3702761
32.31666 334.9844 0.3587114
32.38334 335.6462 0.3471447
32.45000 336.3153 0.3366254
32.51666 336.9862 0.3262398
32.58333 337.6536 0.3159136
32.65000 338.3134 0.3054156
32.71667 338.9807 0.2962724
32.78333 339.6484 0.2871860
32.85000 340.3192 0.2787726
32.91667 340.9831 0.2702850
32.98334 341.6451 0.2623710
33.05000 342.3136 0.2553322
33.11666 342.9780 0.2481465
33.18334 343.6428 0.2415713
33.25000 344.3080 0.2356627
33.31666 344.9766 0.2304094
33.38334 345.6375 0.2246692
33.45000 346.3046 0.2201216
33.51666 346.9724 0.2156398
33.58333 347.6394 0.2116114
33.65000 348.3040 0.2074887
33.71667 348.9723 0.2039068
33.78333 349.6407 0.2007026
33.85000 350.3075 0.1975644
33.91667 350.9710 0.1944205
33.98334 351.6367 0.1915426
34.05000 352.3040 0.1888945
34.11666 352.9720 0.1865859
34.18334 353.6434 0.1845124
34.25000 354.3085 0.1820303
34.31666 354.9718 0.1795433
34.38334 355.6498 0.1785810
34.45000 356.3142 0.1760836
34.51666 356.9740 0.1734685
34.58333 357.6406 0.1717715
34.65000 358.3055 0.1698259
34.71667 358.9754 0.1684396
34.78333 359.6461 0.1668553
34.85000 360.3144 0.1652620
34.91667 360.9828 0.1637052
34.98334 361.6445 0.1616247
35.05000 362.3108 0.1602234
35.11666 362.9798 0.1588878
35.18334 363.6478 0.1572417
35.25000 364.3152 0.1557366
35.31666 364.9835 0.1543482
35.38334 365.6509 0.1527196
35.45000 366.3186 0.1513942
35.51666 366.9854 0.1497241
35.58333 367.6548 0.1485290
35.65000 368.3210 0.1469030
35.71667 368.9890 0.1456785
35.78333 369.6526 0.1438962
35.85000 370.3216 0.1428950
35.91667 370.9883 0.1413064
35.98334 371.6534 0.1395851
36.05000 372.3206 0.1384939
36.11666 372.9907 0.1372931
36.18334 373.6604 0.1360513
36.25000 374.3240 0.1343980
36.31666 374.9898 0.1331141
36.38334 375.6618 0.1323472
36.45000 376.3244 0.1304269
36.51666 376.9884 0.1291228
36.58333 377.6532 0.1275734
36.65000 378.3272 0.1271261
36.71667 378.9970 0.1258314
36.78333 379.6605 0.1242031
36.85000 380.3203 0.1226025
36.91667 380.9876 0.1215805
36.98334 381.6562 0.1202144
37.05000 382.3353 0.1202769
37.11666 382.9923 0.1177842
37.18334 383.6554 0.1165877
37.25000 384.3255 0.1160074
37.31666 384.9868 0.1141895
37.38334 385.6536 0.1131760
37.45000 386.3219 0.1122551
37.51666 386.9902 0.1113314
37.58333 387.6570 0.1099049
37.65000 388.3305 0.1096149
37.71667 388.9914 0.1079528
37.78333 389.6577 0.1067153
37.85000 390.3274 0.1063056
37.91667 390.9934 0.1050165
37.98334 391.6612 0.1043442
38.05000 392.3248 0.1030703
38.11666 392.9902 0.1019831
38.18334 393.6585 0.1014833
38.25000 394.3213 0.1000180
38.31666 394.9906 0.09948500
38.38334 395.6590 0.09862250
38.45000 396.3259 0.09753399
38.51666 396.9918 0.09679556
38.58333 397.6568 0.09562508
38.65000 398.3220 0.09479053
38.71667 398.9946 0.09444321
38.78333 399.6645 0.09377478
38.85000 400.3301 0.09276249
38.91667 400.9969 0.09225196
38.98334 401.6628 0.09128445
39.05000 402.3308 0.09071793
39.11666 402.9922 0.08947514
39.18334 403.6583 0.08879981
39.25000 404.3289 0.08851630
39.31666 404.9961 0.08769501
39.38334 405.6621 0.08683232
39.45000 406.3286 0.08642211
39.51666 406.9963 0.08579681
39.58333 407.6650 0.08531792
39.65000 408.3333 0.08465424
39.71667 408.9981 0.08402465
39.78333 409.6619 0.08301634
39.85000 410.3250 0.08235898
39.91667 410.9962 0.08224768
39.98334 411.6625 0.08141094
40.05000 412.3332 0.08114648
40.11666 413.0016 0.08058762
40.18334 413.6707 0.08026062
40.25000 414.3340 0.07905282
40.31666 415.0002 0.07815320
40.38334 415.6655 0.07734870
40.45000 416.3338 0.07692505
40.51666 416.9974 0.07585641
40.58333 417.6635 0.07546274
40.65000 418.3310 0.07495370
40.71667 419.0007 0.07469722
40.78333 419.6696 0.07418238
40.85000 420.3270 0.07260220
40.91667 421.0004 0.07338852
40.98334 421.6694 0.07279156
41.05000 422.3366 0.07214030
41.11666 423.0036 0.07162010
41.18334 423.6632 0.07039631
41.25000 424.3293 0.06970202
41.31666 425.0008 0.06998450
41.38334 425.6756 0.06993922
41.45000 426.3402 0.06895242
41.51666 427.0030 0.06829129
41.58333 427.6682 0.06787472
41.65000 428.3260 0.06651782
41.71667 429.0068 0.06769855
41.78333 429.6760 0.06714136
41.85000 430.3418 0.06668468
41.91667 431.0010 0.06581415
41.98334 431.6700 0.06589848
42.05000 432.3324 0.06499720
42.11666 433.0066 0.06515606
42.18334 433.6777 0.06497063
42.25000 434.3443 0.06443639
42.31666 435.0048 0.06374480
42.38334 435.6680 0.06307149
42.45000 436.3344 0.06294013
42.51666 437.0078 0.06305325
42.58333 437.6782 0.06273170
42.65000 438.3441 0.06216101
42.71667 439.0072 0.06171446
42.78333 439.6710 0.06115190
42.85000 440.3414 0.06122795
42.91667 441.0072 0.06053228
42.98334 441.6776 0.06043669
43.05000 442.3485 0.06031424
43.11666 443.0148 0.06013965
43.18334 443.6754 0.05904691
43.25000 444.3511 0.05966908
43.31666 445.0195 0.05890913
43.38334 445.6928 0.05841004
43.45000 446.3697 0.05847424
43.51666 447.0450 0.05807888
43.58333 447.7206 0.05824052
43.65000 448.3844 0.05677216
43.71667 449.0550 0.05683725
43.78333 449.7250 0.05659555
43.85000 450.3919 0.05618401
43.91667 451.0638 0.05631108
43.98334 451.7272 0.05550644
44.05000 452.3966 0.05559334
44.11666 453.0618 0.05504950
44.18334 453.7260 0.05464605
44.25000 454.3933 0.05454476
44.31666 455.0605 0.05432944
44.38334 455.7254 0.05373920
44.45000 456.3953 0.05393906
44.51666 457.0605 0.05344988
44.58333 457.7196 0.05236748
44.65000 458.3913 0.05311632
44.71667 459.0588 0.05275550
44.78333 459.7234 0.05246594
44.85000 460.3878 0.05203791
44.91667 461.0487 0.05143039
44.98334 461.7124 0.05113670
45.05000 462.3750 0.05064042
45.11666 463.0404 0.05042743
45.18334 463.7090 0.05031702
45.25000 464.3762 0.05004154
45.31666 465.0422 0.04991053
45.38334 465.7094 0.05003139
45.45000 466.3690 0.04927614
45.51666 467.0300 0.04870112
45.58333 467.6966 0.04877154
45.65000 468.3646 0.04838906
45.71667 469.0320 0.04814357
45.78333 469.7017 0.04816650
45.85000 470.3679 0.04818836
45.91667 471.0248 0.04659788
45.98334 471.6949 0.04699664
46.05000 472.3648 0.04629581
46.11666 473.0301 0.04560140
46.18334 473.6964 0.04532449
46.25000 474.3578 0.04433948
46.31666 475.0238 0.04417888
46.38334 475.6942 0.04425718
46.45000 476.3628 0.04419772
46.51666 477.0361 0.04445220
46.58333 477.7015 0.04385490
46.65000 478.3580 0.04277150
46.71667 479.0260 0.04274938
46.78333 479.6994 0.04301788
46.85000 480.3665 0.04245504
46.91667 481.0367 0.04257436
46.98334 481.7012 0.04212509
47.05000 482.3672 0.04207878
47.11666 483.0350 0.04189343
47.18334 483.7032 0.04167809
47.25000 484.3694 0.04146965
47.31666 485.0326 0.04103645
47.38334 485.6920 0.04008402
47.45000 486.3647 0.04045386
47.51666 487.0421 0.04128090
47.58333 487.7066 0.04044065
47.65000 488.3721 0.04033824
47.71667 489.0322 0.03949566
47.78333 489.7064 0.04015572
47.85000 490.3696 0.03944600
47.91667 491.0412 0.03970199
47.98334 491.7144 0.04008946
48.05000 492.3795 0.03934488
48.11666 493.0546 0.04052098
48.18334 493.7094 0.03877565
48.25000 494.3786 0.03949717
48.31666 495.0578 0.04073971
48.38334 495.7085 0.03865063
48.45000 496.3652 0.03776263
48.51666 497.0383 0.03860140
48.58333 497.7240 0.03977084
48.65000 498.3896 0.03915785
48.71667 499.0541 0.03892061
48.78333 499.7178 0.03898126
48.85000 500.3844 0.03888886
48.91667 501.0498 0.03888156
48.98334 501.7143 0.03844150
49.05000 502.3891 0.03905500
49.11666 503.0600 0.03937828
49.18334 503.7134 0.03763254
49.25000 504.3906 0.03924198
49.31666 505.0598 0.03907690
49.38334 505.7195 0.03792589
49.45000 506.3896 0.03843773
49.51666 507.0625 0.03911738
49.58333 507.7268 0.03860690
49.65000 508.3902 0.03833046
49.71667 509.0540 0.03802512
49.78333 509.7278 0.03894832
49.85000 510.3912 0.03828508
49.91667 511.0621 0.03882236
49.98334 511.7206 0.03778425
50.05000 512.3916 0.03844778
50.11666 513.0586 0.03814480
50.18334 513.7264 0.03815350
50.25000 514.3964 0.03863517
50.31666 515.0652 0.03878933
50.38334 515.7262 0.03830756
50.45000 516.3912 0.03815368
50.51666 517.0626 0.03860140
50.58333 517.7309 0.03844858
50.65000 518.3926 0.03802146
50.71667 519.0537 0.03734392
50.78333 519.7276 0.03818469
50.85000 520.4008 0.03840964
50.91667 521.0664 0.03823960
50.98334 521.7244 0.03735920
51.05000 522.3894 0.03737464
51.11666 523.0675 0.03853015
51.18334 523.7370 0.03872031
51.25000 524.3980 0.03805955
51.31666 525.0622 0.03790593
51.38334 525.7263 0.03756242
51.45000 526.3970 0.03785730
51.51667 527.0644 0.03766897
51.58333 527.7302 0.03752642
51.65000 528.3980 0.03754852
51.71667 529.0674 0.03771260
51.78333 529.7312 0.03728902
51.85000 530.4054 0.03790828
51.91667 531.0711 0.03777261
51.98333 531.7262 0.03646036
52.05000 532.4026 0.03779256
52.11666 533.0628 0.03659950
52.18334 533.7306 0.03668484
52.25000 534.4072 0.03777204
52.31666 535.0793 0.03830188
52.38334 535.7466 0.03830565
52.45000 536.4080 0.03785872
52.51668 537.0652 0.03721246
52.58332 537.7266 0.03674562
52.65000 538.3968 0.03687638
52.71668 539.0680 0.03690934
52.78332 539.7418 0.03766320
52.85000 540.4015 0.03675024
52.91668 541.0632 0.03648306
52.98332 541.7375 0.03730217
53.05000 542.4053 0.03693860
53.11666 543.0730 0.03716862
53.18334 543.7368 0.03675332
53.25000 544.3982 0.03633974
53.31666 545.0598 0.03587362
53.38334 545.7414 0.03701153
53.45000 546.4164 0.03732525
53.51668 547.0711 0.03598380
53.58332 547.7298 0.03537786
53.65000 548.4040 0.03647676
53.71668 549.0724 0.03588195
53.78332 549.7444 0.03643739
53.85000 550.4101 0.03597414
53.91668 551.0761 0.03632962
53.98332 551.7406 0.03601340
54.05000 552.4045 0.03568007
54.11666 553.0708 0.03541797
54.18334 553.7459 0.03594538
54.25000 554.4150 0.03573567
54.31666 555.0818 0.03591265
54.38334 555.7563 0.03696443
54.45000 556.4170 0.03589785
54.51668 557.0774 0.03551234
54.58332 557.7464 0.03533886
54.65000 558.4172 0.03566098
54.71668 559.0868 0.03551772
54.78332 559.7569 0.03554007
54.85000 560.4207 0.03527560
54.91668 561.0900 0.03540064
54.98332 561.7626 0.03607548
55.05000 562.4209 0.03489192
55.11666 563.0859 0.03469033
55.18334 563.7574 0.03527450
55.25000 564.4240 0.03493836
55.31666 565.0955 0.03545480
55.38334 565.7605 0.03507639
55.45000 566.4256 0.03517262
55.51668 567.0886 0.03454025
55.58332 567.7578 0.03457484
55.65000 568.4281 0.03469602
55.71668 569.0943 0.03451961
55.78332 569.7638 0.03484710
55.85000 570.4263 0.03433784
55.91668 571.0938 0.03427310
55.98332 571.7622 0.03441590
56.05000 572.4370 0.03533168
56.11666 573.1028 0.03504922
56.18334 573.7599 0.03405787
56.25000 574.4219 0.03375290
56.31666 575.0951 0.03414063
56.38334 575.7641 0.03389013
56.45000 576.4284 0.03333589
56.51668 577.1044 0.03420572
56.58332 577.7824 0.03559256
56.65000 578.4370 0.03386235
56.71668 579.1039 0.03478515
56.78332 579.7650 0.03409140
56.85000 580.4302 0.03387050
56.91668 581.0966 0.03300694
56.98332 581.7690 0.03357152
57.05000 582.4371 0.03328653
57.11666 583.1054 0.03321725
57.18334 583.7757 0.03353096
57.25000 584.4352 0.03309641
57.31666 585.1007 0.03307886
57.38334 585.7744 0.03342930
57.45000 586.4404 0.03331474
57.51668 587.1098 0.03337166
57.58332 587.7741 0.03281540
57.65000 588.4390 0.03239162
57.71668 589.1071 0.03247787
57.78332 589.7825 0.03335512
57.85000 590.4482 0.03296471
57.91668 591.1090 0.03220254
57.98332 591.7799 0.03264310
58.05000 592.4514 0.03292870
58.11666 593.1144 0.03210735
58.18334 593.7771 0.03150890
58.25000 594.4482 0.03175512
58.31666 595.1250 0.03255464
58.35000 595.4585 0.03216268