File: TGA/cellulose nanorods 1.txt
CLOSED
Version	1.0
Language	English
Run	1
RunSerial	820
Instrument	TGA Q500 V6.7 Build 203
Module	TGA
InstSerial	0500-0499
Operator	at615
File	C:\TA\Data\TGA\ak794\anders\cellulose nanorods 1.001
FurnaceType	Standard
Sample	Cellulose Nanorods 1 Air
Size	4.70800	mg
ProcName
Method
Comment
Xcomment	Pan: Platinum
Xcomment	Gas1: Air
Xcomment	Gas2: Air
Xcomment	Balance Gas: Air 40.0 ml/min
Xcomment	Sample Gas: Air 60.0 ml/min
Text	cellulose nanorods degradation in air
Kcell	1.00000
TempCal	3	pts	20.00	20.00,364.00	356.00,776.00	770.00
InstCalDate	Weight Date 2013-03-01 10:10:44
Controls	Gas 2  Event Off  Sampling 2.0
Nsig	5
Sig1	Time (min)
Sig2	Temperature (°C)
Sig3	Weight (mg)
Sig4	Balance Purge Flow (mL/min)
Sig5	Sample Purge Flow (mL/min)
AirCoolTime	20.0 min
AutoAnalysis	Off
MacroFile
Date	2013-03-11
Time	11:27:22
OrgMethod	1: Ramp 10.00 °C/min to 600.00 °C
OrgFile	C:\Users\AIM_Group\Desktop\post doc cambridge\Students files\Internships\Anders\anders tga\anders\cellulose nanorods 1.001
6.66667E-4 18.70534 4.708418 39.99904 59.99120
0.05000000 18.73930 4.709024 39.99606 59.98738
0.1166666 18.86459 4.709222 40.00119 60.00902
0.1833334 19.08654 4.709687 39.98441 59.98956
0.2500000 19.38886 4.710312 40.00102 60.00084
0.3166666 19.75446 4.710774 39.99174 59.99848
0.3833333 20.17046 4.711398 40.00416 59.99156
0.4500000 20.63003 4.710736 40.01768 60.01108
0.5166666 21.12406 4.710340 39.99470 59.99838
0.5833332 21.64636 4.709798 40.00474 59.99889
0.6500000 22.19580 4.709900 40.00376 59.98686
0.7166666 22.76294 4.710250 39.99810 59.98640
0.7833334 23.34598 4.710504 40.01415 60.00060
0.8500000 23.94588 4.710122 39.99883 59.98611
0.9166668 24.55564 4.710086 39.99118 59.99988
0.9833334 25.17582 4.709928 40.00467 60.00430
1.050000 25.80453 4.708900 39.98342 59.99370
1.116667 26.43837 4.708630 39.99785 60.00699
1.183333 27.07646 4.708574 40.00511 60.00722
1.250000 27.71905 4.708219 40.00725 59.99467
1.316667 28.36253 4.708144 40.00206 59.98660
1.383333 29.00785 4.708064 39.99383 60.00410
1.450000 29.65505 4.707038 40.00356 60.00161
1.516666 30.30113 4.706484 40.00711 59.99883
1.583334 30.95002 4.706447 40.00620 60.00127
1.650000 31.59704 4.706030 40.00512 59.99824
1.716667 32.24333 4.705310 39.99934 59.99648
1.783333 32.88882 4.705042 39.98964 59.99889
1.850000 33.53460 4.704693 39.98656 59.99557
1.916666 34.18022 4.703585 39.99968 59.99710
1.983334 34.82478 4.704336 39.99431 59.98837
2.050000 35.46882 4.702779 40.00608 60.00482
2.116666 36.11276 4.702199 40.01146 60.00715
2.183334 36.75622 4.702316 40.01164 60.01440
2.250000 37.40042 4.701935 39.98786 60.00400
2.316666 38.04411 4.700574 40.00232 60.00093
2.383334 38.68695 4.700063 39.97910 59.99038
2.450000 39.33034 4.699954 39.99532 59.99478
2.516666 39.97496 4.699174 39.98810 59.99680
2.583333 40.61680 4.698282 39.99246 59.99494
2.650000 41.26186 4.697788 39.98955 59.99656
2.716667 41.90671 4.697372 40.00450 60.00925
2.783333 42.55291 4.696716 39.98599 59.99112
2.850000 43.19894 4.695734 40.00439 59.99114
2.916667 43.84488 4.695109 39.99346 60.00184
2.983334 44.49258 4.694676 39.99630 60.00150
3.050000 45.14215 4.694124 39.98852 59.99047
3.116666 45.79096 4.693570 40.00556 60.00620
3.183334 46.44072 4.692916 39.97780 59.99540
3.250000 47.09122 4.692459 40.00654 59.99352
3.316666 47.74164 4.691438 39.99837 59.99830
3.383334 48.39708 4.691100 39.99887 59.99086
3.450000 49.04831 4.690059 39.99560 60.00512
3.516667 49.70122 4.689119 39.99669 59.99534
3.583333 50.35813 4.688852 39.99409 60.00295
3.650000 51.01297 4.687962 39.99667 59.99071
3.716667 51.66807 4.686739 39.98088 59.99741
3.783333 52.32534 4.686591 40.00027 60.00168
3.850000 52.98230 4.685698 39.98462 59.99729
3.916667 53.64006 4.684844 40.00287 59.98980
3.983333 54.29902 4.684717 39.99500 60.00224
4.050000 54.95675 4.683934 39.99588 59.99550
4.116667 55.61674 4.683150 40.00637 59.99466
4.183334 56.27620 4.682187 40.00026 59.99063
4.250000 56.93840 4.681710 39.97695 60.01300
4.316666 57.59951 4.681181 39.99586 60.01201
4.383333 58.26075 4.679808 39.98134 60.00384
4.450000 58.92296 4.679300 40.00922 60.00489
4.516667 59.58796 4.678967 40.00212 60.00328
4.583334 60.25045 4.678161 40.01653 59.99888
4.650000 60.91324 4.677266 40.00886 59.99684
4.716667 61.57598 4.676309 40.00063 59.99631
4.783333 62.23940 4.675612 40.02000 59.98782
4.850000 62.90359 4.674635 40.01389 60.01380
4.916666 63.56568 4.673867 39.97672 59.98700
4.983333 64.23287 4.673422 39.99300 60.01911
5.050000 64.89876 4.672545 40.00834 60.00928
5.116667 65.56545 4.672116 39.99353 60.00789
5.183334 66.23020 4.671020 40.00578 60.01306
5.250000 66.89538 4.669916 40.01040 60.00097
5.316666 67.56110 4.669266 39.99462 60.00342
5.383332 68.22618 4.668168 40.01150 60.00532
5.450000 68.89098 4.667164 39.99207 59.98524
5.516668 69.55655 4.666450 40.00764 60.00213
5.583334 70.22495 4.665894 40.00237 59.99768
5.650000 70.89100 4.664737 39.99754 60.00121
5.716668 71.55871 4.664118 40.00100 60.00520
5.783332 72.22570 4.663234 40.00584 60.00828
5.850000 72.89225 4.662293 40.00370 60.00058
5.916666 73.55790 4.661434 40.00944 59.99627
5.983332 74.22678 4.660796 40.00074 60.00449
6.050000 74.89163 4.659650 39.99817 60.00196
6.116668 75.55835 4.658552 39.98494 60.01050
6.183334 76.22500 4.657988 39.99664 59.99174
6.250000 76.89250 4.657152 39.98941 59.99957
6.316666 77.56084 4.655758 39.99875 59.99940
6.383332 78.22732 4.654814 39.99365 59.99851
6.450000 78.89374 4.653933 40.00237 59.99676
6.516668 79.56176 4.652637 40.00831 59.99750
6.583334 80.22808 4.651752 39.99994 59.99478
6.650000 80.89706 4.651071 40.00378 60.00142
6.716666 81.56434 4.650047 40.01183 60.00735
6.783334 82.23165 4.648929 39.99187 60.00178
6.850000 82.90228 4.648782 40.00711 59.99818
6.916666 83.57020 4.647559 39.98782 59.99680
6.983332 84.23582 4.646308 39.99039 60.00346
7.050000 84.90259 4.645248 40.00616 60.00842
7.116668 85.56915 4.644153 39.99961 59.99512
7.183334 86.23895 4.644102 40.00228 60.00762
7.250000 86.90549 4.643144 39.99766 60.00942
7.316666 87.57079 4.641919 40.00140 59.99800
7.383332 88.23908 4.641150 40.00012 60.00136
7.450000 88.90662 4.640013 39.99990 60.00234
7.516668 89.57550 4.638367 39.99490 60.00531
7.583334 90.24580 4.637984 39.97600 59.99720
7.650000 90.91007 4.636457 40.00034 60.00175
7.716666 91.57609 4.635101 39.98642 60.00720
7.783334 92.24169 4.634137 40.00162 59.99870
7.850000 92.90949 4.633360 39.99356 60.00648
7.916666 93.57568 4.632074 40.00392 60.00639
7.983332 94.24261 4.631424 39.99748 60.00652
8.050000 94.91199 4.630761 40.00587 60.00008
8.116668 95.58139 4.629944 39.99984 60.00086
8.183334 96.24528 4.628090 40.00710 60.00470
8.250000 96.90824 4.626930 40.00278 59.99001
8.316666 97.57605 4.626339 39.99312 59.99837
8.383332 98.24325 4.625262 39.99542 59.99631
8.450000 98.91063 4.624303 39.99617 60.01448
8.516666 99.57629 4.623041 40.00217 60.00130
8.583332 100.2436 4.622171 40.00539 59.99124
8.650000 100.9116 4.621240 40.00629 60.00256
8.716666 101.5782 4.620080 39.99924 60.00312
8.783334 102.2435 4.618676 39.99636 60.00255
8.850000 102.9084 4.618006 40.00322 59.99246
8.916668 103.5768 4.617210 39.98734 60.00098
8.983334 104.2455 4.616081 40.00522 59.99060
9.050000 104.9130 4.615146 39.98989 60.00852
9.116668 105.5796 4.613914 40.00330 59.99484
9.183334 106.2452 4.612664 40.00283 60.00955
9.250000 106.9102 4.611433 40.00066 60.00258
9.316666 107.5768 4.610550 39.99834 60.00373
9.383332 108.2458 4.609997 39.99700 59.99776
9.450000 108.9127 4.608554 40.00140 59.99234
9.516666 109.5780 4.607270 40.00117 59.99949
9.583332 110.2446 4.606259 39.99870 59.99939
9.650000 110.9106 4.605134 40.00687 60.00460
9.716666 111.5775 4.604287 39.98572 59.99432
9.783334 112.2438 4.603000 39.99841 59.99300
9.850000 112.9111 4.601944 39.98684 60.00420
9.916668 113.5777 4.600834 39.99904 59.99910
9.983334 114.2442 4.599672 40.00340 59.99071
10.05000 114.9098 4.598580 39.99416 59.98668
10.11667 115.5806 4.598010 39.99646 60.00962
10.18333 116.2470 4.596406 39.99250 59.99912
10.25000 116.9130 4.595361 39.99396 59.99894
10.31667 117.5834 4.594816 39.99813 60.00445
10.38333 118.2497 4.593191 39.99750 60.00166
10.45000 118.9166 4.592266 39.99408 59.99852
10.51666 119.5828 4.591067 40.00378 60.00902
10.58333 120.2480 4.589956 39.99834 60.01030
10.65000 120.9130 4.588713 40.00002 60.00410
10.71666 121.5801 4.587952 40.00094 59.98511
10.78334 122.2480 4.586939 39.99822 59.99900
10.85000 122.9136 4.585902 39.99366 60.00169
10.91667 123.5804 4.585326 40.00465 60.00675
10.98334 124.2460 4.583956 39.98853 60.00362
11.05000 124.9112 4.582816 39.99362 60.00356
11.11667 125.5810 4.582011 40.00110 60.00322
11.18334 126.2485 4.580869 39.99530 59.98839
11.25000 126.9111 4.579257 39.99465 60.00126
11.31666 127.5774 4.578410 40.00199 60.00530
11.38333 128.2458 4.577610 39.99846 60.00578
11.45000 128.9137 4.576435 39.98708 60.00688
11.51666 129.5806 4.575492 39.99808 60.00170
11.58333 130.2464 4.574226 39.99776 60.00156
11.65000 130.9104 4.572685 39.98822 60.01458
11.71666 131.5795 4.572096 39.99456 60.01813
11.78334 132.2430 4.570570 39.99782 60.00668
11.85000 132.9106 4.569723 40.00036 59.99855
11.91667 133.5789 4.568917 40.00598 60.00097
11.98334 134.2469 4.567636 39.99953 59.99852
12.05000 134.9135 4.566610 40.00054 59.99628
12.11667 135.5795 4.565454 40.01193 59.99145
12.18334 136.2424 4.563921 39.99814 59.99934
12.25000 136.9073 4.562796 39.99541 60.01092
12.31666 137.5746 4.561840 39.99120 60.00530
12.38333 138.2414 4.560838 39.99379 60.01376
12.45000 138.9086 4.559654 40.00855 59.99976
12.51666 139.5761 4.558653 40.00019 60.00395
12.58333 140.2440 4.557720 40.00302 59.99668
12.65000 140.9101 4.556396 39.99263 60.01362
12.71666 141.5750 4.555225 39.98671 59.99804
12.78334 142.2439 4.554446 40.00738 59.99555
12.85000 142.9074 4.552804 40.00116 60.00365
12.91667 143.5734 4.551870 39.99012 59.99449
12.98334 144.2427 4.551093 40.01190 60.01365
13.05000 144.9081 4.549710 39.99025 59.99910
13.11667 145.5757 4.548887 40.00462 59.99368
13.18333 146.2423 4.547698 40.00046 59.99730
13.25000 146.9092 4.546726 39.98902 59.99604
13.31667 147.5736 4.545376 40.00160 59.99740
13.38333 148.2448 4.544885 39.98489 59.99134
13.45000 148.9066 4.543015 39.98993 60.00620
13.51666 149.5746 4.542172 39.99971 60.00717
13.58333 150.2409 4.541086 40.01217 59.98441
13.65000 150.9068 4.539910 39.99942 60.00103
13.71666 151.5759 4.539224 39.99370 60.00462
13.78334 152.2400 4.537671 39.99518 60.00054
13.85000 152.9066 4.536590 40.01224 59.99347
13.91667 153.5718 4.535326 40.00807 60.00286
13.98334 154.2359 4.533980 39.99492 59.99426
14.05000 154.9057 4.533540 39.98880 59.99329
14.11667 155.5774 4.532965 39.99470 60.00569
14.18333 156.2443 4.531561 39.99998 59.98863
14.25000 156.9082 4.529992 39.98968 60.00824
14.31667 157.5711 4.528713 39.99631 60.01004
14.38333 158.2364 4.527914 39.99697 60.00055
14.45000 158.9039 4.526752 39.99494 59.99542
14.51666 159.5682 4.525396 39.99124 60.01066
14.58333 160.2344 4.524491 39.98761 60.01052
14.65000 160.9010 4.523399 40.00598 59.99082
14.71666 161.5690 4.522534 40.00428 60.00070
14.78334 162.2368 4.521506 39.99896 60.00893
14.85000 162.8997 4.519734 40.00234 59.99818
14.91667 163.5652 4.518835 39.99420 59.99042
14.98334 164.2381 4.518432 40.00467 60.00488
15.05000 164.9082 4.517463 39.98210 60.00124
15.11667 165.5693 4.515628 39.99847 60.00430
15.18333 166.2298 4.514090 40.00313 60.01550
15.25000 166.8922 4.512891 40.01240 59.99716
15.31667 167.5604 4.512309 40.00630 60.00598
15.38333 168.2275 4.511050 39.99900 59.97937
15.45000 168.8994 4.510556 40.00770 59.99403
15.51666 169.5663 4.509350 39.99926 60.00176
15.58333 170.2309 4.507679 39.98818 60.00157
15.65000 170.8941 4.506330 40.00095 60.01232
15.71666 171.5564 4.504997 40.00490 60.00389
15.78334 172.2206 4.503836 39.99923 60.02004
15.85000 172.8908 4.503400 40.00446 60.00846
15.91667 173.5583 4.502002 39.99746 60.00123
15.98334 174.2248 4.500722 39.99736 60.00510
16.05000 174.8932 4.499863 40.00072 59.99510
16.11667 175.5621 4.498690 39.99994 60.00270
16.18333 176.2262 4.497205 39.99658 59.99750
16.25000 176.8922 4.495996 40.00437 60.00132
16.31667 177.5572 4.494752 39.99317 59.99700
16.38333 178.2225 4.493596 39.98657 60.00084
16.45000 178.8889 4.492385 39.99008 59.99646
16.51666 179.5542 4.491150 40.00633 60.02002
16.58334 180.2191 4.489630 39.99432 60.00776
16.65000 180.8835 4.488262 39.99824 59.98943
16.71667 181.5533 4.487391 40.00124 60.00416
16.78333 182.2218 4.485988 40.00211 59.99160
16.85000 182.8887 4.484814 40.01045 60.00322
16.91666 183.5530 4.483356 39.98775 60.00040
16.98334 184.2184 4.481858 39.99962 59.99891
17.05000 184.8821 4.479896 40.00568 60.01084
17.11667 185.5534 4.478470 39.99700 60.01390
17.18333 186.2226 4.475941 39.98369 59.99856
17.25000 186.8836 4.472866 40.00281 59.99030
17.31667 187.5472 4.470446 40.00250 60.00121
17.38333 188.2138 4.468284 40.00578 60.00312
17.45000 188.8784 4.465604 39.99362 60.00459
17.51666 189.5441 4.462872 40.00050 60.00268
17.58334 190.2119 4.460342 40.00384 60.00490
17.65000 190.8905 4.458545 40.00215 59.99074
17.71667 191.5538 4.454687 40.01182 60.00845
17.78333 192.2201 4.451694 39.99676 60.00740
17.85000 192.8836 4.448360 39.99727 60.00990
17.91666 193.5408 4.444544 40.01122 59.99588
17.98334 194.2125 4.442164 39.99964 59.99262
18.05000 194.8790 4.438769 40.00003 59.99269
18.11667 195.5414 4.434910 40.00409 60.00546
18.18333 196.2088 4.431763 40.00176 60.00030
18.25000 196.8767 4.428282 39.98920 60.00836
18.31667 197.5425 4.424484 39.99402 59.99480
18.38333 198.2127 4.421230 40.00685 59.99878
18.45000 198.8829 4.417889 39.99506 59.99742
18.51666 199.5527 4.414566 39.98687 60.00380
18.58334 200.2158 4.410540 39.99339 60.00636
18.65000 200.8768 4.406576 39.99946 60.00459
18.71667 201.5390 4.403000 40.01020 60.00772
18.78333 202.2090 4.399886 40.00830 60.00709
18.85000 202.8845 4.397183 39.99050 59.99026
18.91666 203.5582 4.393832 40.00586 60.00124
18.98334 204.2240 4.389925 39.99232 60.00103
19.05000 204.8874 4.385887 40.00506 60.00818
19.11667 205.5484 4.381629 40.00383 60.01048
19.18333 206.2155 4.378208 39.99072 60.00220
19.25000 206.8825 4.374354 40.00986 59.99750
19.31667 207.5501 4.370436 40.00426 59.99951
19.38333 208.2108 4.365699 40.01813 59.99832
19.45000 208.8745 4.361526 39.98883 59.98652
19.51666 209.5445 4.357750 40.00842 60.00981
19.58334 210.2145 4.353384 39.99524 60.00115
19.65000 210.8808 4.348934 39.99421 60.00708
19.71667 211.5508 4.344608 40.00256 60.00301
19.78333 212.2130 4.339234 39.99744 59.98856
19.85000 212.8754 4.334075 40.00256 60.00502
19.91666 213.5414 4.329288 39.99795 59.99968
19.98334 214.2116 4.324720 39.99979 59.99570
20.05000 214.8777 4.319216 39.99767 59.99250
20.11667 215.5450 4.313962 40.01778 59.99076
20.18333 216.2109 4.308097 40.00294 60.01302
20.25000 216.8742 4.302283 40.00711 59.98584
20.31667 217.5372 4.296152 39.98495 60.00930
20.38333 218.2110 4.291156 39.99767 59.99154
20.45000 218.8670 4.283648 40.01080 59.98974
20.51666 219.5418 4.278883 40.00150 60.00026
20.58334 220.2159 4.273082 40.00461 60.01069
20.65000 220.8761 4.265381 40.01076 60.01936
20.71667 221.5418 4.258952 39.99984 60.01661
20.78333 222.2020 4.251546 40.00519 59.98789
20.85000 222.8669 4.244719 40.00844 60.01895
20.91666 223.5281 4.237439 39.99160 59.99250
20.98334 224.1930 4.230037 39.99682 60.00709
21.05000 224.8718 4.224090 39.99546 60.01512
21.11667 225.5436 4.216475 39.99617 60.01555
21.18333 226.2020 4.207607 39.99324 60.00182
21.25000 226.8684 4.199976 40.00052 59.99414
21.31667 227.5354 4.192302 40.00784 60.00149
21.38333 228.1986 4.183815 39.99722 59.99940
21.45000 228.8616 4.175282 40.00674 59.99664
21.51666 229.5276 4.167164 40.01502 60.00303
21.58334 230.1978 4.158926 39.97683 59.99971
21.65000 230.8614 4.149725 39.99370 60.00068
21.71667 231.5273 4.140982 39.98310 59.99816
21.78333 232.1966 4.132415 39.98841 60.00218
21.85000 232.8644 4.123316 39.98813 59.99175
21.91666 233.5290 4.113840 40.00153 60.00336
21.98334 234.1936 4.104430 40.00217 60.00108
22.05000 234.8565 4.094610 40.00602 59.99216
22.11667 235.5250 4.085610 39.99496 60.00160
22.18333 236.1939 4.075964 39.99802 59.99990
22.25000 236.8572 4.065732 39.98648 60.00945
22.31667 237.5202 4.055340 39.99174 60.00279
22.38333 238.1863 4.045628 39.99256 60.01000
22.45000 238.8581 4.035957 40.00780 60.00910
22.51666 239.5213 4.025246 40.00276 59.99082
22.58334 240.1887 4.015082 40.00224 59.99963
22.65000 240.8570 4.004812 39.99760 59.99189
22.71667 241.5239 3.994004 39.99990 59.99838
22.78333 242.1833 3.982812 40.00019 60.00062
22.85000 242.8487 3.972320 39.99142 59.99862
22.91666 243.5150 3.961488 39.99974 60.00548
22.98334 244.1828 3.950878 40.00035 59.99402
23.05000 244.8538 3.940277 40.00783 60.01328
23.11667 245.5202 3.929046 40.00504 59.99970
23.18333 246.1869 3.917985 39.99722 59.99444
23.25000 246.8501 3.906578 39.99100 60.00154
23.31667 247.5187 3.895813 40.00000 59.99702
23.38333 248.1850 3.884619 40.00440 60.00215
23.45000 248.8526 3.873530 40.01263 59.98809
23.51666 249.5176 3.862038 39.99582 59.99482
23.58334 250.1840 3.850992 39.99668 60.00055
23.65000 250.8518 3.839869 39.99328 60.00636
23.71667 251.5163 3.828494 40.01646 60.00626
23.78333 252.1790 3.816968 40.00852 59.99586
23.85000 252.8462 3.806058 40.00896 59.99913
23.91666 253.5147 3.794990 40.01012 59.98268
23.98334 254.1846 3.784045 39.98290 60.01954
24.05000 254.8468 3.772410 39.98883 60.01187
24.11667 255.5162 3.761704 40.01532 59.97901
24.18333 256.1854 3.750890 40.00288 59.99990
24.25000 256.8534 3.739825 39.99996 59.99620
24.31667 257.5175 3.728791 40.00994 59.99568
24.38333 258.1803 3.717616 40.00325 60.00511
24.45000 258.8404 3.706247 39.99649 60.01248
24.51666 259.5122 3.696434 40.01279 59.99160
24.58334 260.1800 3.685534 39.99805 60.00666
24.65000 260.8422 3.674494 40.00396 59.99824
24.71667 261.5108 3.664471 39.99963 60.00308
24.78333 262.1796 3.654053 39.98761 60.00820
24.85000 262.8470 3.643796 40.01019 59.99761
24.91666 263.5102 3.633237 39.99494 60.00955
24.98334 264.1810 3.623658 39.99985 59.99814
25.05000 264.8456 3.613122 39.99416 59.99082
25.11667 265.5039 3.602317 39.98761 59.99562
25.18333 266.1730 3.592740 39.98663 59.99722
25.25000 266.8454 3.583638 40.00024 59.99731
25.31667 267.5074 3.573097 39.99858 60.00176
25.38333 268.1807 3.564081 39.99548 60.01330
25.45000 268.8464 3.554240 40.00350 59.99976
25.51666 269.5095 3.544269 40.00329 59.99041
25.58334 270.1712 3.534017 39.98516 60.00348
25.65000 270.8401 3.524987 39.99430 59.99719
25.71667 271.5129 3.516046 39.97290 60.00187
25.78333 272.1795 3.506186 40.00918 59.99741
25.85000 272.8426 3.496275 39.98898 60.02282
25.91666 273.5066 3.486914 39.99605 60.00310
25.98334 274.1690 3.477126 40.00381 59.99566
26.05000 274.8418 3.468300 40.00449 59.99472
26.11666 275.5056 3.458620 39.99268 59.99199
26.18333 276.1710 3.449096 40.00332 60.00378
26.25000 276.8369 3.439675 39.99123 59.99900
26.31667 277.5053 3.430346 39.99276 60.00658
26.38334 278.1738 3.420940 39.99930 59.98880
26.45000 278.8410 3.411591 40.00406 59.99478
26.51666 279.5069 3.402000 39.99771 59.98821
26.58334 280.1712 3.392316 40.00697 60.00615
26.65000 280.8363 3.382774 39.99772 60.00150
26.71667 281.5027 3.373286 40.00870 60.00087
26.78333 282.1714 3.363952 40.00090 60.00450
26.85000 282.8386 3.354217 40.00596 59.99801
26.91666 283.5031 3.344421 39.98372 60.00266
26.98334 284.1746 3.335208 39.98437 59.99842
27.05000 284.8430 3.325645 39.98725 60.00329
27.11666 285.5072 3.315578 40.00008 60.01186
27.18333 286.1730 3.305706 40.00046 60.00741
27.25000 286.8373 3.295693 40.01092 59.99386
27.31667 287.5033 3.285730 40.01004 59.98672
27.38334 288.1709 3.275926 40.01450 59.99252
27.45000 288.8366 3.265831 40.00734 59.98852
27.51666 289.5057 3.255865 40.00730 59.99230
27.58334 290.1713 3.245612 39.97120 60.00489
27.65000 290.8363 3.235280 39.99701 60.00260
27.71667 291.4992 3.224811 40.00740 59.98750
27.78333 292.1664 3.214585 40.00187 60.00557
27.85000 292.8372 3.204380 39.98749 59.99862
27.91666 293.5118 3.194484 39.99336 59.99332
27.98334 294.1706 3.182811 40.00346 60.00113
28.05000 294.8297 3.171742 39.99176 60.00387
28.11666 295.4918 3.160966 39.98820 59.99963
28.18333 296.1590 3.150034 40.00836 59.98852
28.25000 296.8346 3.139908 40.00268 60.01372
28.31667 297.5092 3.129272 39.99870 59.99728
28.38334 298.1764 3.117830 39.98758 59.98898
28.45000 298.8413 3.106377 40.01133 60.00534
28.51666 299.5008 3.094379 40.01120 60.00396
28.58334 300.1616 3.082685 39.99211 59.99226
28.65000 300.8330 3.071682 39.99989 60.00984
28.71667 301.5028 3.060180 40.00415 59.99266
28.78333 302.1675 3.048092 39.99518 59.99671
28.85000 302.8330 3.036184 39.99962 59.99898
28.91666 303.5039 3.024764 39.99416 60.00992
28.98334 304.1712 3.012488 40.00272 60.02071
29.05000 304.8340 2.999882 39.99532 59.99044
29.11666 305.4978 2.987291 40.00136 60.00098
29.18333 306.1684 2.975310 39.98777 59.99336
29.25000 306.8316 2.962185 39.98996 59.99418
29.31667 307.4963 2.949435 40.00955 59.98950
29.38334 308.1660 2.936875 40.00358 59.99746
29.45000 308.8356 2.924054 40.00318 60.00491
29.51666 309.4994 2.910400 40.00485 59.99922
29.58334 310.1650 2.897072 39.99882 60.00445
29.65000 310.8310 2.883592 40.01693 60.00982
29.71667 311.5008 2.870282 40.00714 59.98989
29.78333 312.1650 2.856409 39.99668 60.00472
29.85000 312.8309 2.842518 39.99094 60.00020
29.91666 313.4984 2.828682 40.00078 60.00587
29.98334 314.1662 2.814676 40.00542 60.00260
30.05000 314.8334 2.800274 40.00891 60.02004
30.11666 315.4996 2.786048 39.98703 59.98874
30.18333 316.1644 2.771203 40.01594 60.01006
30.25000 316.8284 2.756338 39.98735 60.00796
30.31667 317.4907 2.741180 39.99622 59.99711
30.38334 318.1583 2.726219 40.00222 59.99255
30.45000 318.8278 2.711224 39.99058 59.98918
30.51666 319.4963 2.695994 39.99437 59.99320
30.58334 320.1626 2.680347 39.99267 59.99039
30.65000 320.8318 2.665141 39.99538 59.99345
30.71667 321.4969 2.649048 39.98656 59.98799
30.78333 322.1662 2.633540 40.00825 60.01111
30.85000 322.8262 2.616694 40.00760 59.99329
30.91666 323.4926 2.600618 39.99593 60.01240
30.98334 324.1624 2.584515 39.99270 59.99866
31.05000 324.8322 2.568105 39.98904 59.99663
31.11666 325.4986 2.551344 39.99112 60.00278
31.18333 326.1580 2.533955 40.00508 60.01358
31.25000 326.8211 2.517062 39.99854 59.99864
31.31667 327.4935 2.500791 39.99008 59.98878
31.38334 328.1590 2.483097 39.99760 60.00682
31.45000 328.8272 2.466006 40.00468 60.00597
31.51666 329.4912 2.448285 39.99554 59.98703
31.58334 330.1605 2.431387 39.99402 59.99960
31.65000 330.8271 2.413904 39.99091 59.99022
31.71667 331.4970 2.396734 39.99050 60.01041
31.78333 332.1610 2.379025 40.00033 59.99901
31.85000 332.8246 2.361315 40.00153 60.01024
31.91666 333.4895 2.343928 39.99502 59.98165
31.98334 334.1594 2.327036 40.00684 60.00138
32.05000 334.8280 2.310042 39.98542 59.99700
32.11666 335.4970 2.293034 39.99540 59.99425
32.18334 336.1609 2.275798 39.99984 59.99914
32.25000 336.8233 2.259082 39.99328 60.00033
32.31666 337.4891 2.242765 39.98736 59.98550
32.38334 338.1586 2.227115 39.97798 59.99652
32.45000 338.8266 2.211332 39.99959 59.99254
32.51666 339.4989 2.196593 40.01195 60.01537
32.58333 340.1590 2.180977 40.01991 60.00234
32.65000 340.8150 2.165846 40.00590 60.00332
32.71667 341.4804 2.152244 40.00355 59.98414
32.78333 342.1568 2.139405 39.98624 59.99624
32.85000 342.8217 2.125612 39.99700 59.99702
32.91667 343.4840 2.112837 39.98083 60.00576
32.98334 344.1600 2.102102 40.00400 60.01494
33.05000 344.8205 2.089914 39.99426 60.00181
33.11666 345.4792 2.078502 40.00152 59.99829
33.18334 346.1470 2.068444 39.97618 60.00190
33.25000 346.8079 2.057922 39.99834 60.00457
33.31666 347.4856 2.049719 39.98680 59.99415
33.38334 348.1511 2.040133 39.99272 60.00430
33.45000 348.8167 2.031449 40.00726 59.99789
33.51666 349.4844 2.023617 39.99965 59.99947
33.58333 350.1513 2.015952 39.99333 59.99963
33.65000 350.8191 2.008823 39.99055 59.99125
33.71667 351.4828 2.001615 40.00015 59.99636
33.78333 352.1476 1.994616 40.00888 60.01035
33.85000 352.8194 1.988844 40.00630 60.00761
33.91667 353.4962 1.983963 39.99680 60.00471
33.98334 354.1544 1.977063 40.00776 60.00178
34.05000 354.8181 1.971478 39.99575 59.99408
34.11666 355.4814 1.965881 40.00300 59.99800
34.18334 356.1515 1.961224 39.98996 59.98930
34.25000 356.8235 1.956645 39.99118 60.00987
34.31666 357.4980 1.952372 40.00865 59.99590
34.38334 358.1628 1.947378 40.00084 59.99488
34.45000 358.8236 1.942317 39.99500 60.00600
34.51666 359.4874 1.937733 40.01520 60.00074
34.58333 360.1618 1.934348 39.98965 59.99146
34.65000 360.8269 1.929659 39.99644 60.00251
34.71667 361.4938 1.925697 40.00469 59.99434
34.78333 362.1640 1.922001 39.97900 60.00347
34.85000 362.8307 1.917837 39.99835 59.98806
34.91667 363.4964 1.913944 39.99309 60.00185
34.98334 364.1672 1.910576 40.00942 59.99802
35.05000 364.8342 1.906806 40.00160 60.01901
35.11666 365.4966 1.902731 39.99927 60.00839
35.18334 366.1631 1.899220 40.00454 60.00163
35.25000 366.8328 1.895931 40.01406 59.99664
35.31666 367.5036 1.892655 39.99808 60.01626
35.38334 368.1677 1.888912 39.99297 59.99679
35.45000 368.8345 1.885660 40.00261 60.00310
35.51666 369.4968 1.881768 39.99700 59.99757
35.58333 370.1663 1.878844 39.99424 59.99669
35.65000 370.8388 1.875919 39.99468 60.00418
35.71667 371.5059 1.872496 40.00016 60.00699
35.78333 372.1702 1.868914 39.99746 60.00859
35.85000 372.8355 1.865656 39.99463 60.01414
35.91667 373.5046 1.862784 40.00394 60.00854
35.98334 374.1706 1.859633 40.00370 59.99926
36.05000 374.8369 1.856306 40.00194 59.99543
36.11666 375.5030 1.853284 39.99417 59.99563
36.18334 376.1716 1.850371 40.00742 59.99126
36.25000 376.8392 1.847491 39.98960 60.00641
36.31666 377.5014 1.843948 40.01167 59.99443
36.38334 378.1648 1.840862 40.00402 60.00680
36.45000 378.8424 1.838911 40.00150 60.00186
36.51666 379.5094 1.835580 39.98497 60.01248
36.58333 380.1734 1.832401 40.00798 59.99518
36.65000 380.8344 1.829056 40.01789 59.99624
36.71667 381.5012 1.826320 39.98695 60.00337
36.78333 382.1738 1.823959 39.98201 60.00945
36.85000 382.8418 1.820972 40.00625 59.98856
36.91667 383.5100 1.818021 40.01236 59.99199
36.98334 384.1717 1.814541 40.00439 60.00680
37.05000 384.8413 1.812292 39.99870 59.99630
37.11666 385.5066 1.809266 39.99525 59.99750
37.18334 386.1750 1.806563 39.99950 59.99852
37.25000 386.8420 1.803660 40.00730 59.99132
37.31666 387.4996 1.800194 39.99929 60.01269
37.38334 388.1682 1.797736 39.99682 60.00305
37.45000 388.8375 1.795020 40.00511 60.00807
37.51666 389.5055 1.792152 40.00476 60.01042
37.58333 390.1719 1.789146 39.99652 60.00280
37.65000 390.8389 1.786352 40.00582 60.00209
37.71667 391.5078 1.783658 39.98376 59.98966
37.78333 392.1778 1.780962 39.99773 60.00288
37.85000 392.8536 1.779150 39.99847 60.00122
37.91667 393.5109 1.775200 40.00590 60.01168
37.98334 394.1744 1.772317 39.99854 59.99949
38.05000 394.8380 1.769220 39.99132 59.99629
38.11666 395.4983 1.765752 40.00155 60.00198
38.18334 396.1725 1.763598 39.99340 60.00435
38.25000 396.8416 1.760562 39.99625 59.99936
38.31666 397.5032 1.756916 40.00175 60.01396
38.38334 398.1789 1.755075 40.00998 60.00653
38.45000 398.8460 1.751928 39.99494 59.99693
38.51666 399.5098 1.748580 39.99748 60.00602
38.58333 400.1736 1.745444 39.99933 60.00216
38.65000 400.8350 1.741848 40.01295 59.98412
38.71667 401.4966 1.738359 39.98552 60.00568
38.78333 402.1735 1.736126 40.01230 59.98911
38.85000 402.8507 1.733606 40.01574 59.98865
38.91667 403.5210 1.730352 40.00882 60.00543
38.98334 404.1801 1.726281 40.00671 59.99844
39.05000 404.8420 1.723091 39.99709 59.99816
39.11666 405.4970 1.718554 40.01397 59.98548
39.18334 406.1691 1.715759 40.00875 60.00110
39.25000 406.8466 1.713350 39.99838 59.98640
39.31666 407.5110 1.708926 40.01144 60.00437
39.38334 408.1722 1.705010 39.99912 60.01729
39.45000 408.8451 1.702214 39.99994 59.99444
39.51666 409.5152 1.698695 39.99983 59.99099
39.58333 410.1832 1.694822 39.99076 60.00182
39.65000 410.8619 1.692311 40.00556 60.00454
39.71667 411.5176 1.687146 40.00487 60.00012
39.78333 412.1727 1.682482 39.99617 59.99828
39.85000 412.8375 1.678694 39.99141 60.00874
39.91667 413.5120 1.675341 39.99784 59.99874
39.98334 414.1772 1.670654 39.99922 59.99834
40.05000 414.8496 1.666563 40.00732 59.98824
40.11666 415.5317 1.663584 40.00456 59.99137
40.18334 416.2018 1.659330 40.00897 60.00160
40.25000 416.8508 1.653231 39.98981 59.98719
40.31666 417.5186 1.649540 40.00662 60.01661
40.38334 418.1840 1.644642 40.00822 59.99285
40.45000 418.8456 1.639244 40.01232 60.00516
40.51666 419.5105 1.634141 39.98648 59.99008
40.58333 420.1808 1.629116 39.99880 60.01218
40.65000 420.8519 1.624128 39.99847 59.99138
40.71667 421.5250 1.618894 40.00853 60.01057
40.78333 422.1932 1.613237 40.00360 59.99747
40.85000 422.8796 1.609313 39.98135 60.00871
40.91667 423.5403 1.602304 39.99929 60.00768
40.98334 424.1870 1.594519 40.00910 59.99051
41.05000 424.8526 1.588569 40.00295 59.99620
41.11666 425.5291 1.582706 40.00210 60.00510
41.18334 426.2037 1.575786 39.99947 60.01057
41.25000 426.8723 1.568637 40.00625 59.99332
41.31666 427.5354 1.560809 40.00682 60.00158
41.38334 428.2058 1.553491 40.01058 59.99744
41.45000 428.8700 1.544998 39.99242 59.99586
41.51666 429.5340 1.536583 39.98762 59.99042
41.58333 430.2041 1.528391 39.99079 59.99510
41.65000 430.8803 1.520324 40.01160 60.00340
41.71667 431.5410 1.510334 39.99280 59.98907
41.78333 432.2086 1.501084 40.00766 60.00671
41.85000 432.8713 1.491200 39.99922 60.00015
41.91667 433.5412 1.481686 40.00891 60.00894
41.98334 434.2109 1.471610 39.99567 59.98943
42.05000 434.8734 1.460594 39.99091 59.99275
42.11666 435.5406 1.450005 39.99766 59.99623
42.18334 436.2100 1.439165 40.00329 60.00498
42.25000 436.8776 1.427982 39.98610 59.99932
42.31666 437.5522 1.417340 39.99962 60.00786
42.38334 438.2140 1.404874 40.00400 60.00908
42.45000 438.8753 1.392612 39.99280 59.98982
42.51666 439.5358 1.380116 39.99614 59.99975
42.58333 440.2024 1.367748 39.99884 59.99668
42.65000 440.8676 1.354650 40.00090 59.99846
42.71667 441.5395 1.341912 39.99690 59.99390
42.78333 442.2166 1.329525 39.99063 60.00604
42.85000 442.8828 1.315574 39.99852 60.00265
42.91667 443.5520 1.302407 40.01045 60.00761
42.98334 444.2129 1.285278 40.00069 60.00186
43.05000 444.8738 1.270915 40.00144 60.00684
43.11666 445.5366 1.256118 40.01742 60.00990
43.18334 446.1994 1.240702 39.98000 59.98900
43.25000 446.8737 1.225785 40.01104 60.00822
43.31666 447.5464 1.210140 39.99682 60.00208
43.38334 448.2166 1.194174 39.99111 59.99407
43.45000 448.8854 1.178318 39.99938 59.99762
43.51666 449.5474 1.161617 39.98956 59.99326
43.58333 450.2122 1.145366 39.98112 59.99863
43.65000 450.8756 1.128624 39.99530 60.00605
43.71667 451.5378 1.111443 39.99472 60.00322
43.78333 452.2039 1.094301 40.00790 60.01320
43.85000 452.8761 1.077359 39.99970 59.99378
43.91667 453.5457 1.059897 40.00876 59.98342
43.98334 454.2113 1.041977 40.00555 60.00538
44.05000 454.8798 1.024269 40.00424 60.00274
44.11666 455.5471 1.005986 40.00132 59.99746
44.18334 456.2133 0.9873672 40.00182 60.00166
44.25000 456.8778 0.9679778 39.99947 60.01047
44.31666 457.5454 0.9490089 39.98982 59.99355
44.38334 458.2058 0.9298101 39.98696 59.99370
44.45000 458.8640 0.9110901 40.00118 60.00486
44.51666 459.5224 0.8928426 39.99741 60.01642
44.58333 460.1852 0.8752524 39.99522 60.01492
44.65000 460.8494 0.8578953 39.99967 59.99444
44.71667 461.5179 0.8409269 39.99235 59.99312
44.78333 462.1838 0.8238663 40.00820 59.99485
44.85000 462.8533 0.8071438 40.00706 60.00590
44.91667 463.5197 0.7902603 39.99948 60.01030
44.98334 464.1848 0.7735662 40.00030 60.00286
45.05000 464.8503 0.7570955 39.99004 60.01191
45.11666 465.5139 0.7401774 40.00458 60.00722
45.18334 466.1804 0.7241264 40.01502 60.00422
45.25000 466.8486 0.7082325 40.01123 59.99280
45.31666 467.5225 0.6930420 40.00402 60.00630
45.38334 468.1908 0.6775024 40.00986 59.98482
45.45000 468.8511 0.6614502 40.00246 60.00547
45.51666 469.5101 0.6459536 39.98798 59.99452
45.58333 470.1742 0.6310380 40.00878 60.00370
45.65000 470.8481 0.6169841 40.00104 59.99118
45.71667 471.5170 0.6026459 39.99453 60.01334
45.78333 472.1826 0.5885993 40.00361 60.00520
45.85000 472.8461 0.5744593 39.99765 59.99594
45.91667 473.5163 0.5614518 40.00668 59.99895
45.98334 474.1834 0.5479882 39.99557 60.00551
46.05000 474.8512 0.5349847 39.98770 60.00284
46.11666 475.5180 0.5219944 39.99402 59.99915
46.18334 476.1810 0.5090227 39.99767 59.98925
46.25000 476.8466 0.4965040 39.99760 60.00566
46.31666 477.5174 0.4847338 40.00891 59.99500
46.38334 478.1856 0.4731164 39.99062 59.99644
46.45000 478.8459 0.4608040 40.00289 59.99774
46.51666 479.5137 0.4499494 40.00012 59.99330
46.58333 480.1843 0.4391084 40.00750 59.99390
46.65000 480.8521 0.4284790 39.98967 60.00981
46.71667 481.5246 0.4184338 40.01056 60.00036
46.78333 482.1900 0.4081638 40.00780 59.99718
46.85000 482.8545 0.3982160 39.99220 59.99766
46.91667 483.5203 0.3882958 39.99360 60.00020
46.98334 484.1872 0.3788378 39.99441 59.99844
47.05000 484.8553 0.3698230 39.98703 60.00682
47.11666 485.5257 0.3611945 39.99058 60.00030
47.18334 486.1860 0.3517198 39.99287 60.01556
47.25000 486.8562 0.3436852 40.01531 59.98188
47.31666 487.5270 0.3358148 40.01521 59.99124
47.38334 488.1971 0.3282028 40.02206 59.99034
47.45000 488.8656 0.3206710 40.00023 60.00037
47.51666 489.5274 0.3125900 40.00149 60.01429
47.58333 490.1972 0.3058078 40.00664 59.99916
47.65000 490.8668 0.2990748 40.00150 59.99750
47.71667 491.5348 0.2922609 39.99420 60.00470
47.78333 492.2000 0.2853450 40.00634 60.00089
47.85000 492.8668 0.2791417 39.99537 60.00970
47.91667 493.5358 0.2730146 39.99103 60.00384
47.98334 494.2008 0.2668102 39.99236 60.00338
48.05000 494.8702 0.2613329 39.99544 60.00288
48.11666 495.5408 0.2559633 39.99890 59.99556
48.18334 496.2060 0.2502246 40.00546 60.00152
48.25000 496.8766 0.2454004 39.98767 60.00439
48.31666 497.5457 0.2405163 40.00198 60.00063
48.38334 498.2074 0.2352525 40.00710 59.99390
48.45000 498.8728 0.2306725 39.99120 60.00937
48.51666 499.5418 0.2263968 39.99797 60.01730
48.58333 500.2164 0.2228383 39.99805 60.01021
48.65000 500.8838 0.2186150 39.99219 59.99970
48.71667 501.5512 0.2148292 40.00167 60.00250
48.78333 502.2096 0.2104851 40.00003 59.99776
48.85000 502.8784 0.2070204 39.98792 60.00762
48.91667 503.5463 0.2034322 39.98742 60.00828
48.98334 504.2163 0.2005196 39.99845 60.01122
49.05000 504.8846 0.1972146 40.00126 59.99378
49.11666 505.5523 0.1944152 40.00080 60.01437
49.18334 506.2153 0.1913829 39.99983 60.01558
49.25000 506.8841 0.1887533 40.00303 60.00250
49.31666 507.5600 0.1871994 39.99463 59.99418
49.38334 508.2270 0.1847308 39.99973 60.00147
49.45000 508.8863 0.1820092 40.00138 60.00816
49.51666 509.5528 0.1802179 39.98910 59.99940
49.58333 510.2230 0.1784877 39.99425 59.98437
49.65000 510.8920 0.1767875 39.98657 60.00658
49.71667 511.5606 0.1754307 40.01079 59.99500
49.78333 512.2287 0.1742081 39.98989 60.01801
49.85000 512.8966 0.1726649 39.98920 60.01578
49.91667 513.5615 0.1710222 40.00581 59.98004
49.98334 514.2287 0.1703280 39.98168 60.00550
50.05000 514.8955 0.1692720 39.99463 60.00344
50.11666 515.5619 0.1682114 40.01384 59.97620
50.18334 516.2304 0.1677136 40.01100 59.99319
50.25000 516.9013 0.1674012 39.98600 59.99288
50.31666 517.5699 0.1669668 40.00068 60.00004
50.38334 518.2378 0.1666270 40.00778 59.99530
50.45000 518.9065 0.1662647 40.00018 60.00952
50.51666 519.5740 0.1660452 40.00264 60.01378
50.58333 520.2383 0.1656893 39.99402 59.98784
50.65000 520.9000 0.1646675 39.99636 59.99006
50.71667 521.5686 0.1647618 40.00210 59.99988
50.78333 522.2414 0.1647074 40.00632 59.99672
50.85000 522.9126 0.1647424 40.00153 59.99541
50.91667 523.5802 0.1644888 39.98358 60.00579
50.98334 524.2434 0.1640075 39.99222 60.00191
51.05000 524.9100 0.1638446 39.99550 60.01260
51.11666 525.5777 0.1638450 39.99091 60.00202
51.18334 526.2454 0.1635849 39.99431 59.99863
51.25000 526.9124 0.1633663 39.99951 60.00518
51.31666 527.5766 0.1626752 40.01013 59.99842
51.38334 528.2529 0.1635392 40.00108 59.99430
51.45000 528.9172 0.1627027 40.00844 60.00260
51.51667 529.5824 0.1623329 40.00222 60.00455
51.58333 530.2484 0.1620580 40.00039 59.99850
51.65000 530.9184 0.1622106 39.98662 60.00288
51.71667 531.5852 0.1617584 39.99030 59.99258
51.78333 532.2566 0.1619380 39.98865 60.00532
51.85000 532.9239 0.1618510 39.99024 60.00754
51.91667 533.5865 0.1611699 40.00852 60.00430
51.98333 534.2519 0.1608840 40.00360 59.99814
52.05000 534.9216 0.1609350 40.01416 59.98896
52.11666 535.5918 0.1610687 39.99841 60.00500
52.18334 536.2568 0.1605493 40.00691 60.00412
52.25000 536.9226 0.1603183 39.98614 59.98632
52.31666 537.5894 0.1601010 39.99062 60.01090
52.38334 538.2551 0.1598686 40.00920 59.99275
52.45000 538.9224 0.1594438 39.99368 60.01910
52.51668 539.5920 0.1592702 39.99722 60.00060
52.58332 540.2588 0.1591703 40.01624 59.99916
52.65000 540.9265 0.1590130 39.98024 59.98356
52.71668 541.5888 0.1582663 39.98334 60.01104
52.78332 542.2566 0.1580917 40.00021 60.00357
52.85000 542.9286 0.1582990 40.01345 60.01074
52.91668 543.5970 0.1580912 39.99618 59.99837
52.98332 544.2598 0.1571839 39.99575 59.98988
53.05000 544.9239 0.1566467 39.99214 59.98132
53.11666 545.5858 0.1554254 39.99556 60.02166
53.18334 546.2670 0.1568001 39.99250 59.99788
53.25000 546.9378 0.1566243 39.99492 59.99446
53.31666 547.5955 0.1555051 40.00518 60.00708
53.38334 548.2535 0.1543566 39.99509 59.98704
53.45000 548.9224 0.1543983 39.99232 59.99278
53.51668 549.5945 0.1543983 39.99231 59.98564
53.58332 550.2650 0.1544029 40.00586 60.00943
53.65000 550.9307 0.1537085 39.99331 59.99870
53.71668 551.5980 0.1537503 39.99608 59.98660
53.78332 552.2634 0.1532578 39.99124 59.99296
53.85000 552.9265 0.1525274 39.99886 60.00182
53.91668 553.5932 0.1523131 40.00662 59.99508
53.98332 554.2626 0.1519238 39.99424 60.00027
54.05000 554.9296 0.1514528 40.00265 59.99526
54.11666 555.5984 0.1512499 39.99470 60.00866
54.18334 556.2674 0.1508284 40.00918 59.99795
54.25000 556.9340 0.1503159 39.98897 59.99443
54.31666 557.6021 0.1499944 39.99364 59.99087
54.38334 558.2720 0.1499596 39.99742 60.00537
54.45000 558.9350 0.1490517 40.01068 60.01171
54.51668 559.6006 0.1486020 39.98780 59.99164
54.58332 560.2678 0.1479130 39.99594 59.99548
54.65000 560.9353 0.1473384 39.99836 59.99558
54.71668 561.6035 0.1466727 40.00770 60.00278
54.78332 562.2705 0.1460810 39.99902 60.00463
54.85000 562.9409 0.1458342 40.00120 59.99941
54.91668 563.6044 0.1445790 39.98850 59.99895
54.98332 564.2699 0.1438480 40.01437 60.01470
55.05000 564.9426 0.1434002 40.01273 60.01425
55.11666 565.6142 0.1431348 40.00742 59.99800
55.18334 566.2766 0.1418156 39.98776 59.99805
55.25000 566.9424 0.1412660 40.01348 59.99975
55.31666 567.6110 0.1405643 39.99518 59.99688
55.38334 568.2748 0.1397496 39.99340 60.00122
55.45000 568.9355 0.1382377 40.00462 59.99663
55.51668 569.6050 0.1379111 40.00586 60.00840
55.58332 570.2720 0.1372888 39.99900 59.99710
55.65000 570.9472 0.1376122 40.00378 59.99966
55.71668 571.6082 0.1360095 40.00491 60.00130
55.78332 572.2778 0.1361299 39.98826 60.00842
55.85000 572.9455 0.1358678 39.98757 60.00424
55.91668 573.6060 0.1346735 39.99893 59.99581
55.98332 574.2724 0.1343659 40.00181 60.00459
56.05000 574.9430 0.1342611 40.00959 59.99493
56.11666 575.6172 0.1345474 40.00073 60.00461
56.18334 576.2797 0.1334406 39.99703 60.00188
56.25000 576.9457 0.1334102 39.98928 60.00400
56.31666 577.6129 0.1332900 39.99973 60.00332
56.38334 578.2760 0.1326134 40.00065 59.99698
56.45000 578.9449 0.1326188 40.00682 59.99855
56.51668 579.6133 0.1322756 40.00444 60.00934
56.58332 580.2808 0.1320422 40.00642 60.00449
56.65000 580.9479 0.1317324 40.00228 59.99326
56.71668 581.6169 0.1319149 40.00412 59.99851
56.78332 582.2824 0.1313646 39.98889 59.99526
56.85000 582.9498 0.1314757 39.98982 60.00210
56.91668 583.6122 0.1306674 40.00217 60.00235
56.98332 584.2842 0.1311389 40.00990 60.00295
57.05000 584.9560 0.1314782 40.00633 59.99130
57.11666 585.6230 0.1312075 39.98798 60.00709
57.18334 586.2800 0.1299770 39.99980 60.01360
57.25000 586.9491 0.1302737 39.99200 59.99903
57.31666 587.6216 0.1302521 40.01884 59.98822
57.38334 588.2888 0.1300329 39.98913 60.00305
57.45000 588.9578 0.1300290 39.98282 59.99707
57.51668 589.6264 0.1303575 40.01994 60.00464
57.58332 590.2891 0.1298600 39.99465 59.99776
57.65000 590.9563 0.1298805 40.00012 59.99395
57.71668 591.6246 0.1298204 40.00234 60.01660
57.78332 592.2910 0.1295692 39.98787 59.99990
57.85000 592.9613 0.1296088 39.99786 60.01765
57.91668 593.6344 0.1303958 40.00210 60.00462
57.98332 594.3000 0.1303518 40.00060 59.99594
58.05000 594.9594 0.1296398 40.00074 60.00412
58.08332 595.2908 0.1294543 40.00100 59.99540