File: TGA/ZIF8cellulose sponge extraction component sample2.txt
CLOSED
Version	1.0
Language	English
Run	1
RunSerial	822
Instrument	TGA Q500 V6.7 Build 203
Module	TGA
InstSerial	0500-0499
Operator	at615
File	C:\TA\Data\TGA\ak794\anders\ZIF8cellulose rods sample2.001
FurnaceType	Standard
Sample	ZIF8 cellulose rods in air s2
Size	1.91300	mg
ProcName
Method
Comment
Xcomment	Pan: Platinum
Xcomment	Gas1: Air
Xcomment	Gas2: Air
Xcomment	Balance Gas: Air 40.0 ml/min
Xcomment	Sample Gas: Air 60.0 ml/min
Text	Cellulose rods and zif8 degradation in air. Sample 2
Kcell	1.00000
TempCal	3	pts	20.00	20.00,364.00	356.00,776.00	770.00
InstCalDate	Weight Date 2013-03-01 10:10:44
Controls	Gas 2  Event Off  Sampling 2.0
Nsig	5
Sig1	Time (min)
Sig2	Temperature (°C)
Sig3	Weight (mg)
Sig4	Balance Purge Flow (mL/min)
Sig5	Sample Purge Flow (mL/min)
AirCoolTime	20.0 min
AutoAnalysis	Off
MacroFile
Date	2013-03-11
Time	16:25:15
OrgMethod	1: Ramp 10.00 °C/min to 600.00 °C
OrgFile	C:\Users\AIM_Group\Desktop\post doc cambridge\Students files\Internships\Anders\anders tga\anders\ZIF8cellulose sponge extraction component sample2.001
7.33333E-4 18.68135 1.913044 39.98864 59.99692
0.05000000 18.71738 1.913158 40.00153 59.99714
0.1166666 18.84739 1.913960 40.00814 59.99521
0.1833334 19.07352 1.913978 39.98887 60.00184
0.2500000 19.38068 1.914537 39.99998 59.99729
0.3166666 19.75130 1.915140 40.00421 59.99360
0.3833333 20.17365 1.915365 39.99286 60.00510
0.4500000 20.63827 1.915839 40.01070 59.99885
0.5166666 21.13425 1.915935 40.01224 59.99700
0.5833332 21.66011 1.916475 40.00140 60.00130
0.6500000 22.21018 1.915949 40.00460 60.01016
0.7166666 22.78004 1.916592 40.02072 59.99800
0.7833334 23.36688 1.916526 39.99230 60.00566
0.8500000 23.96741 1.916628 40.00324 60.00086
0.9166668 24.58045 1.916247 39.99620 59.99296
0.9833334 25.20348 1.916375 40.00857 59.99998
1.050000 25.83334 1.916236 40.00556 59.99510
1.116667 26.46785 1.916390 40.00040 60.00815
1.183333 27.10758 1.916395 40.00975 59.99898
1.250000 27.75175 1.916409 39.99850 60.00209
1.316667 28.39818 1.915618 40.00630 60.00816
1.383333 29.04496 1.915166 40.00978 59.99244
1.450000 29.69389 1.914914 40.00542 59.99360
1.516666 30.34208 1.916124 39.99641 59.99554
1.583334 30.99260 1.916075 40.00774 59.99208
1.650000 31.64061 1.915732 39.99480 59.99511
1.716667 32.28928 1.915812 39.99478 60.00289
1.783333 32.93561 1.916324 40.00383 59.99354
1.850000 33.58320 1.916407 39.99036 59.99540
1.916666 34.22986 1.916058 39.99690 59.99418
1.983334 34.87558 1.916297 39.99082 59.99600
2.050000 35.51979 1.915834 40.00228 59.99814
2.116666 36.16517 1.915586 40.00452 59.98884
2.183334 36.81004 1.915469 40.00098 59.99540
2.250000 37.45329 1.915422 40.00609 59.99532
2.316666 38.09668 1.915486 39.99346 59.99912
2.383334 38.74226 1.915338 39.99868 60.00864
2.450000 39.38490 1.915189 39.99859 59.99170
2.516666 40.03094 1.914951 39.99557 59.98099
2.583333 40.67500 1.915046 39.99448 59.98934
2.650000 41.31955 1.915053 40.00364 59.99620
2.716667 41.96534 1.914840 39.99705 59.99724
2.783333 42.61048 1.914516 40.00030 59.99287
2.850000 43.25660 1.914943 40.00412 59.99840
2.916667 43.90389 1.914564 40.00563 59.99798
2.983334 44.55373 1.914715 39.99234 59.98984
3.050000 45.20164 1.914430 40.00614 59.99184
3.116666 45.84988 1.914386 40.00170 60.00202
3.183334 46.50064 1.914306 40.00666 59.99670
3.250000 47.15210 1.914435 39.99955 60.00088
3.316666 47.80295 1.914065 39.99613 60.00330
3.383334 48.45634 1.914142 40.00260 60.00488
3.450000 49.10954 1.914019 40.00170 60.00634
3.516667 49.76300 1.913856 40.00832 60.00746
3.583333 50.41597 1.913572 39.99005 60.01415
3.650000 51.07358 1.914042 39.99075 60.00335
3.716667 51.72844 1.913622 40.00394 60.00054
3.783333 52.38506 1.913556 39.99600 60.00463
3.850000 53.04290 1.913498 40.00446 59.99703
3.916667 53.70029 1.913807 39.99578 59.98550
3.983333 54.35950 1.913281 40.00048 59.98069
4.050000 55.01771 1.912447 40.00144 59.99889
4.116667 55.67870 1.912726 39.99864 60.00460
4.183334 56.33774 1.912687 40.01002 59.99652
4.250000 56.99824 1.912373 40.00113 60.00292
4.316666 57.65863 1.912361 40.00030 59.99610
4.383333 58.31982 1.912092 40.00384 59.99851
4.450000 58.98296 1.912145 39.99105 60.00285
4.516667 59.64660 1.912144 40.00175 59.99906
4.583334 60.30980 1.912020 40.01750 59.98188
4.650000 60.97355 1.911619 40.01328 59.98826
4.716667 61.63554 1.911435 40.01147 59.99741
4.783333 62.29730 1.911260 40.01261 60.00137
4.850000 62.96151 1.911004 39.98613 60.00691
4.916666 63.62550 1.910880 39.99995 60.00672
4.983333 64.29210 1.911142 39.99755 59.99768
5.050000 64.95688 1.911016 40.00005 60.00378
5.116667 65.62068 1.910317 40.00966 60.00355
5.183334 66.28530 1.909924 39.99104 59.99817
5.250000 66.94932 1.909786 40.00540 59.99459
5.316666 67.61578 1.909728 40.00531 59.99646
5.383332 68.28124 1.909425 40.01578 60.00822
5.450000 68.94819 1.909438 40.00086 60.00108
5.516668 69.61389 1.909116 40.00183 59.99477
5.583334 70.27819 1.908734 40.00344 59.99454
5.650000 70.94312 1.908132 39.99974 60.00361
5.716668 71.61060 1.908092 40.01197 60.01110
5.783332 72.27955 1.908241 39.99547 60.01452
5.850000 72.94701 1.907750 40.02293 59.98170
5.916666 73.61481 1.907140 39.99508 59.99942
5.983332 74.28318 1.906803 39.98119 60.00750
6.050000 74.95024 1.906156 39.98906 60.00622
6.116668 75.61915 1.905889 39.99795 60.00750
6.183334 76.28912 1.906183 39.99514 60.00348
6.250000 76.95813 1.905291 39.98862 60.00522
6.316666 77.62670 1.904955 39.99470 60.00870
6.383332 78.29452 1.904507 39.99928 59.99594
6.450000 78.96248 1.903942 39.99710 60.00468
6.516668 79.62955 1.903431 39.98458 60.00356
6.583334 80.29834 1.903344 39.98758 59.99972
6.650000 80.96582 1.902467 40.00506 60.00506
6.716666 81.63253 1.901896 40.00343 60.00846
6.783334 82.30010 1.901511 39.98294 59.99480
6.850000 82.96766 1.900606 39.99866 59.99841
6.916666 83.63422 1.899948 40.00796 59.99880
6.983332 84.30219 1.899676 39.99042 60.00280
7.050000 84.97031 1.899156 40.00522 59.99218
7.116668 85.63631 1.898100 39.99770 60.00566
7.183334 86.30316 1.897391 40.01072 59.99506
7.250000 86.97071 1.896551 40.00574 59.99033
7.316666 87.63639 1.895676 39.99561 60.00537
7.383332 88.30274 1.894434 39.98914 60.00704
7.450000 88.96825 1.893565 39.99844 60.00702
7.516668 89.63515 1.893019 40.00307 59.99834
7.583334 90.30226 1.891911 39.99894 59.99892
7.650000 90.97075 1.891067 39.99237 60.00122
7.716666 91.63437 1.889539 40.00871 60.01050
7.783334 92.30038 1.888246 40.00015 60.00112
7.850000 92.96660 1.887314 39.99789 59.99144
7.916666 93.63672 1.886306 40.00379 60.00522
7.983332 94.30536 1.885125 39.98984 60.00332
8.050000 94.96988 1.883028 39.99775 60.00112
8.116668 95.63324 1.881304 39.99092 59.99230
8.183334 96.30066 1.880387 40.00309 59.99972
8.250000 96.97285 1.879441 39.99933 60.00544
8.316666 97.64018 1.877489 39.99382 60.00424
8.383332 98.30899 1.875829 40.00595 60.00460
8.450000 98.97251 1.873544 39.99310 60.00224
8.516666 99.63768 1.871642 40.00189 59.99459
8.583332 100.3041 1.869936 40.00552 59.99982
8.650000 100.9713 1.867998 39.99538 59.98761
8.716666 101.6378 1.865761 40.00171 59.98736
8.783334 102.3052 1.863809 39.99443 60.01121
8.850000 102.9726 1.861705 40.00769 59.98970
8.916668 103.6380 1.858986 39.99530 60.01014
8.983334 104.3035 1.856750 40.00071 60.00146
9.050000 104.9701 1.854208 39.99953 60.01024
9.116668 105.6351 1.851470 39.99948 60.01124
9.183334 106.3001 1.848950 39.99344 60.00014
9.250000 106.9680 1.846424 40.00216 59.99070
9.316666 107.6353 1.843721 39.99072 60.00084
9.383332 108.2989 1.840326 39.99912 60.00112
9.450000 108.9658 1.837567 39.99204 60.00717
9.516666 109.6295 1.834115 39.98250 59.99877
9.583332 110.2978 1.831479 39.98786 59.99737
9.650000 110.9661 1.828108 40.00162 60.00212
9.716666 111.6336 1.825282 39.98822 59.99854
9.783334 112.2998 1.821411 39.99666 60.00066
9.850000 112.9685 1.818640 40.01828 60.00486
9.916668 113.6314 1.813730 39.99521 59.98620
9.983334 114.2948 1.810151 40.01160 59.98426
10.05000 114.9616 1.806851 40.01659 60.00074
10.11667 115.6333 1.803446 40.01462 59.99930
10.18333 116.3002 1.799101 40.00922 60.01144
10.25000 116.9659 1.794891 40.01570 60.00658
10.31667 117.6332 1.790596 39.99833 60.01361
10.38333 118.2982 1.786265 40.00084 59.99848
10.45000 118.9638 1.781972 39.99956 59.99541
10.51666 119.6291 1.777848 40.00232 59.98557
10.58333 120.2938 1.773174 39.99561 59.98832
10.65000 120.9615 1.769129 40.00860 60.01466
10.71666 121.6285 1.764834 39.99999 59.99934
10.78334 122.2987 1.761162 40.01245 59.98650
10.85000 122.9612 1.756021 40.01132 60.00117
10.91667 123.6329 1.752878 40.00308 59.99639
10.98334 124.2948 1.747923 39.99736 60.00264
11.05000 124.9628 1.744641 40.00214 59.99720
11.11667 125.6337 1.741617 40.00478 59.99691
11.18334 126.2989 1.737204 40.01746 60.00560
11.25000 126.9606 1.733185 39.99365 59.98886
11.31666 127.6308 1.730919 40.00456 59.99316
11.38333 128.2914 1.726436 40.00549 60.00590
11.45000 128.9604 1.724396 40.00561 59.99912
11.51666 129.6341 1.722696 40.00868 60.00566
11.58333 130.2990 1.719002 39.99040 60.01116
11.65000 130.9651 1.716984 40.00094 60.00360
11.71666 131.6310 1.714655 39.99980 59.99125
11.78334 132.3000 1.713375 40.00105 60.00117
11.85000 132.9692 1.711512 39.99710 59.99253
11.91667 133.6304 1.709125 40.01237 59.98996
11.98334 134.2961 1.707908 39.99762 59.99429
12.05000 134.9588 1.705899 40.00300 59.98700
12.11667 135.6298 1.705646 40.00067 59.98968
12.18334 136.2978 1.704455 39.99434 59.99945
12.25000 136.9616 1.703353 39.99627 60.00286
12.31666 137.6352 1.703528 40.00810 60.01218
12.38333 138.2992 1.702087 39.99206 60.00020
12.45000 138.9666 1.701889 40.00215 59.99316
12.51666 139.6318 1.701040 39.98597 59.98296
12.58333 140.2954 1.700418 40.00005 59.98282
12.65000 140.9646 1.700745 40.01694 60.00390
12.71666 141.6362 1.700714 40.00378 60.00545
12.78334 142.3026 1.699847 39.99710 60.00729
12.85000 142.9675 1.699418 39.99967 59.99737
12.91667 143.6305 1.698623 39.99738 59.98734
12.98334 144.2938 1.698223 40.00425 59.99239
13.05000 144.9629 1.698695 39.98809 59.99365
13.11667 145.6298 1.698422 40.00784 59.99800
13.18333 146.3008 1.698604 40.00770 60.00302
13.25000 146.9657 1.698056 40.00252 59.99876
13.31667 147.6317 1.697906 40.02060 60.00051
13.38333 148.2940 1.697002 40.00652 60.00326
13.45000 148.9626 1.697558 40.00482 60.00821
13.51666 149.6324 1.697634 39.99447 60.00111
13.58333 150.3008 1.697525 39.99929 59.99002
13.65000 150.9632 1.696833 39.99961 60.00615
13.71666 151.6269 1.696489 39.99985 59.99930
13.78334 152.2870 1.695727 39.99805 60.01048
13.85000 152.9614 1.697401 40.00600 59.99321
13.91667 153.6305 1.696732 40.00220 59.98846
13.98334 154.2930 1.695817 39.99524 60.01360
14.05000 154.9586 1.695928 40.00457 59.98410
14.11667 155.6268 1.696232 39.99166 59.99346
14.18333 156.2917 1.695908 39.99235 59.99962
14.25000 156.9520 1.694944 39.99605 59.99106
14.31667 157.6278 1.696755 39.99973 59.99836
14.38333 158.2986 1.696398 39.98744 60.00764
14.45000 158.9573 1.694759 39.99158 60.00462
14.51666 159.6174 1.694472 39.99544 60.01099
14.58333 160.2814 1.694536 40.01076 60.00374
14.65000 160.9534 1.695551 40.01978 60.00476
14.71666 161.6238 1.695296 40.02190 59.99122
14.78334 162.2932 1.695332 39.99850 60.00650
14.85000 162.9575 1.694873 40.00140 60.01578
14.91667 163.6184 1.694197 40.00133 59.98760
14.98334 164.2826 1.694163 40.00262 60.00500
15.05000 164.9517 1.694809 40.00500 59.99628
15.11667 165.6134 1.693740 39.99598 60.01084
15.18333 166.2843 1.694687 40.00105 60.01006
15.25000 166.9566 1.695207 40.01008 59.99744
15.31667 167.6212 1.694018 40.02429 60.01552
15.38333 168.2784 1.693034 39.99572 60.00262
15.45000 168.9418 1.693381 40.00242 60.01056
15.51666 169.6084 1.693212 40.00513 60.01215
15.58333 170.2771 1.693884 40.00064 59.99963
15.65000 170.9488 1.693999 39.99533 59.99130
15.71666 171.6124 1.693049 39.99418 60.00080
15.78334 172.2719 1.692185 40.01234 59.99895
15.85000 172.9428 1.693402 39.99411 60.00246
15.91667 173.6120 1.693276 40.01384 59.99928
15.98334 174.2851 1.693927 40.01141 60.00491
16.05000 174.9494 1.693081 40.00594 59.99419
16.11667 175.6051 1.691698 39.99672 60.00675
16.18333 176.2708 1.692126 40.00189 59.99862
16.25000 176.9416 1.693016 40.01102 59.98892
16.31667 177.6083 1.692562 39.99213 59.99682
16.38333 178.2716 1.691961 40.00287 60.00064
16.45000 178.9412 1.692673 40.01182 59.99644
16.51666 179.6100 1.692462 39.99793 59.99944
16.58334 180.2732 1.691841 40.00359 59.98364
16.65000 180.9360 1.691701 40.00488 60.00406
16.71667 181.6024 1.691839 40.00189 59.99015
16.78333 182.2721 1.692131 39.99752 59.99524
16.85000 182.9357 1.691428 40.00394 60.01155
16.91666 183.6010 1.691582 39.99898 60.00050
16.98334 184.2715 1.692042 40.00925 59.99535
17.05000 184.9398 1.691994 39.99990 60.00250
17.11667 185.6045 1.691389 40.00720 60.00037
17.18333 186.2697 1.691279 40.01883 60.00214
17.25000 186.9326 1.690891 39.99956 60.00586
17.31667 187.5981 1.690964 40.00810 59.98943
17.38333 188.2659 1.691055 40.01575 59.98861
17.45000 188.9327 1.690924 40.01912 59.99916
17.51666 189.5987 1.690865 40.00197 60.00032
17.58334 190.2630 1.690549 40.00941 59.98776
17.65000 190.9329 1.690920 40.00813 59.99741
17.71667 191.5996 1.690635 40.00576 59.99600
17.78333 192.2659 1.690534 40.00351 59.99793
17.85000 192.9332 1.690777 40.01616 59.99612
17.91666 193.6023 1.690791 39.98852 60.00844
17.98334 194.2652 1.690209 39.99697 59.99884
18.05000 194.9296 1.690117 40.00020 60.00010
18.11667 195.5989 1.690579 39.99674 60.00758
18.18333 196.2646 1.690247 40.00941 60.00951
18.25000 196.9290 1.689934 39.99907 59.99226
18.31667 197.5976 1.690215 40.00242 59.99031
18.38333 198.2614 1.689581 39.98776 60.00174
18.45000 198.9199 1.688894 39.99112 59.98296
18.51666 199.5866 1.689406 40.00107 59.99994
18.58334 200.2582 1.689946 40.00208 59.99707
18.65000 200.9243 1.689510 40.00663 60.00455
18.71667 201.5921 1.689428 39.99242 59.98934
18.78333 202.2589 1.689430 39.99646 59.99397
18.85000 202.9257 1.689415 39.99869 60.00826
18.91666 203.5933 1.689462 40.00068 60.00190
18.98334 204.2585 1.689118 40.00028 60.00513
19.05000 204.9266 1.689213 40.00476 59.99609
19.11667 205.5949 1.689526 40.00184 59.98192
19.18333 206.2591 1.688952 40.01035 60.00500
19.25000 206.9201 1.688519 40.01224 59.98457
19.31667 207.5844 1.688497 40.01434 60.00020
19.38333 208.2470 1.688107 40.00291 60.02116
19.45000 208.9164 1.688640 40.00274 60.01240
19.51666 209.5857 1.688736 39.98839 60.01864
19.58334 210.2560 1.688993 39.98747 60.01144
19.65000 210.9225 1.688686 39.98208 60.01400
19.71667 211.5844 1.688069 40.01978 59.98928
19.78333 212.2440 1.687509 40.00425 60.00412
19.85000 212.9127 1.687978 40.01401 59.99952
19.91666 213.5853 1.688623 39.99276 59.99735
19.98334 214.2520 1.688214 39.99946 59.99084
20.05000 214.9176 1.687822 40.01675 59.98516
20.11667 215.5856 1.687952 40.00112 60.00318
20.18333 216.2439 1.686909 39.99559 60.00414
20.25000 216.9192 1.688401 39.99718 60.01308
20.31667 217.5852 1.687427 39.99971 60.00215
20.38333 218.2480 1.687036 39.99556 60.01194
20.45000 218.9120 1.687234 40.00244 60.00101
20.51666 219.5816 1.687674 40.00918 59.99366
20.58334 220.2451 1.686886 40.00898 59.99797
20.65000 220.9104 1.686972 40.00448 59.99458
20.71667 221.5775 1.687057 39.99772 59.99444
20.78333 222.2489 1.687402 40.00259 59.99765
20.85000 222.9142 1.686819 40.00028 59.99861
20.91666 223.5797 1.686831 39.98645 59.99013
20.98334 224.2454 1.686728 40.00959 59.99172
21.05000 224.9109 1.686484 39.99683 59.99024
21.11667 225.5799 1.686926 40.00189 60.00165
21.18333 226.2468 1.686531 39.99166 60.00594
21.25000 226.9137 1.686435 40.01019 60.00141
21.31667 227.5801 1.686455 40.00262 60.01012
21.38333 228.2434 1.686036 39.98572 59.99343
21.45000 228.9082 1.685910 39.99847 59.98492
21.51666 229.5740 1.685866 39.99578 60.00136
21.58334 230.2415 1.685971 40.01360 60.01696
21.65000 230.9085 1.685828 39.99562 59.99898
21.71667 231.5750 1.685718 40.00056 60.00601
21.78333 232.2409 1.685572 40.00190 59.99690
21.85000 232.9054 1.685323 40.02385 60.00790
21.91666 233.5742 1.685611 40.01958 60.00789
21.98334 234.2412 1.685416 40.01380 59.98364
22.05000 234.9053 1.685062 39.99462 60.01100
22.11667 235.5702 1.684889 40.01019 60.00814
22.18333 236.2402 1.685404 40.00824 60.00526
22.25000 236.9064 1.685078 39.99411 59.99805
22.31667 237.5705 1.684842 40.00298 60.00266
22.38333 238.2372 1.684681 40.00066 60.00511
22.45000 238.9056 1.684810 39.99330 60.00591
22.51666 239.5682 1.684337 40.00372 60.00312
22.58334 240.2352 1.684398 39.99832 59.99254
22.65000 240.8977 1.683884 40.01991 59.99257
22.71667 241.5625 1.683733 39.99774 60.00142
22.78333 242.2308 1.684000 40.01092 59.99864
22.85000 242.8993 1.683869 39.99910 60.00861
22.91666 243.5669 1.683879 39.99319 59.98786
22.98334 244.2325 1.683545 40.00092 60.01130
23.05000 244.8994 1.683758 39.98933 59.99526
23.11667 245.5700 1.684054 39.99600 60.00230
23.18333 246.2314 1.683065 40.00002 60.00140
23.25000 246.8978 1.683264 40.00628 60.00392
23.31667 247.5607 1.683040 40.01758 60.00265
23.38333 248.2316 1.683410 40.00600 59.99749
23.45000 248.8961 1.682936 39.99442 59.99802
23.51666 249.5562 1.682194 39.99429 59.99715
23.58334 250.2257 1.682826 39.97976 59.99358
23.65000 250.8966 1.682959 40.02005 60.00903
23.71667 251.5642 1.682703 39.98022 60.00043
23.78333 252.2306 1.682475 39.98890 60.01642
23.85000 252.8988 1.682380 39.99353 59.97870
23.91666 253.5602 1.681764 40.03279 60.01851
23.98334 254.2288 1.681970 39.97931 59.99149
24.05000 254.8985 1.682057 40.02114 60.00911
24.11667 255.5670 1.681869 39.99635 60.00601
24.18333 256.2322 1.681684 40.00422 60.00028
24.25000 256.8977 1.681339 39.98990 60.00332
24.31667 257.5656 1.681256 40.00692 60.01590
24.38333 258.2315 1.681168 40.00078 60.00120
24.45000 258.8963 1.680734 40.00645 59.99685
24.51666 259.5621 1.680678 39.99443 59.99590
24.58334 260.2301 1.680692 40.00088 59.99192
24.65000 260.8980 1.680623 39.99638 59.99688
24.71667 261.5662 1.680532 39.99894 60.00354
24.78333 262.2314 1.680105 39.99554 59.99960
24.85000 262.9016 1.680328 39.99535 60.00789
24.91666 263.5639 1.679596 39.99861 60.00400
24.98334 264.2280 1.679311 40.00298 60.00361
25.05000 264.8935 1.679306 39.99183 60.00151
25.11667 265.5606 1.679174 39.99984 59.99693
25.18333 266.2291 1.679201 40.01072 59.99826
25.25000 266.9000 1.679283 40.00133 60.00104
25.31667 267.5659 1.678826 39.99128 59.98680
25.38333 268.2289 1.678338 40.01854 59.99459
25.45000 268.8963 1.678547 40.00227 60.00068
25.51666 269.5656 1.678484 39.99503 60.00449
25.58334 270.2311 1.678012 39.98958 59.99975
25.65000 270.8942 1.677568 40.00640 59.98528
25.71667 271.5562 1.677165 39.99786 59.99663
25.78333 272.2196 1.676876 39.99890 60.00850
25.85000 272.8841 1.676549 40.01160 60.00787
25.91666 273.5536 1.676671 40.00130 59.99220
25.98334 274.2248 1.677037 39.99836 59.99543
26.05000 274.8946 1.676665 39.98928 59.97974
26.11666 275.5543 1.675612 40.00459 60.00846
26.18333 276.2246 1.675955 40.00159 60.00280
26.25000 276.8918 1.676034 39.99010 60.00636
26.31667 277.5580 1.675489 39.99882 60.00110
26.38334 278.2249 1.675491 40.00464 60.00242
26.45000 278.8904 1.675034 40.00586 59.98355
26.51666 279.5556 1.674878 39.99594 60.00049
26.58334 280.2195 1.674483 40.01463 59.98852
26.65000 280.8881 1.674515 39.99643 59.99216
26.71667 281.5508 1.674005 40.01574 60.01046
26.78333 282.2128 1.673306 40.01506 60.00054
26.85000 282.8817 1.673501 39.99616 60.00074
26.91666 283.5498 1.673294 39.99890 60.00149
26.98334 284.2180 1.673107 40.00295 59.99324
27.05000 284.8853 1.672968 40.00278 59.99778
27.11666 285.5480 1.672250 39.99746 59.99836
27.18333 286.2114 1.671808 39.99970 60.00100
27.25000 286.8811 1.672250 40.00042 59.99022
27.31667 287.5510 1.672231 39.99439 59.99541
27.38334 288.2140 1.671256 39.99984 59.99496
27.45000 288.8746 1.670484 40.01255 60.00094
27.51666 289.5470 1.671308 40.00608 60.01074
27.58334 290.2142 1.670714 39.99620 59.99490
27.65000 290.8792 1.670279 40.00285 59.99374
27.71667 291.5416 1.669579 40.00054 60.00225
27.78333 292.2068 1.669305 39.98418 60.00342
27.85000 292.8745 1.669384 39.99989 60.00101
27.91666 293.5488 1.669618 40.00630 59.99399
27.98334 294.2124 1.668672 39.99732 60.00250
28.05000 294.8794 1.668678 40.00008 59.99947
28.11666 295.5436 1.668060 39.99766 60.00538
28.18333 296.2080 1.667576 40.00018 60.00321
28.25000 296.8750 1.667438 39.99653 60.00889
28.31667 297.5459 1.667352 40.00340 60.00031
28.38334 298.2115 1.666730 39.99650 60.00792
28.45000 298.8789 1.666565 39.99999 60.00318
28.51666 299.5455 1.666170 39.99963 60.00342
28.58334 300.2060 1.665231 40.01403 60.00014
28.65000 300.8763 1.665522 40.00090 59.99794
28.71667 301.5454 1.665319 40.00058 60.00942
28.78333 302.2162 1.665246 39.99078 60.00066
28.85000 302.8828 1.664722 39.99448 60.00503
28.91666 303.5479 1.664344 40.00090 59.99879
28.98334 304.2134 1.663896 40.00921 60.01182
29.05000 304.8771 1.663325 40.01623 60.00945
29.11666 305.5418 1.662822 40.00033 60.01474
29.18333 306.2064 1.662462 40.00418 59.99479
29.25000 306.8766 1.662314 39.99848 59.99712
29.31667 307.5404 1.661381 40.00556 59.99458
29.38334 308.2120 1.661795 40.00731 59.99414
29.45000 308.8829 1.661575 40.00705 59.99150
29.51666 309.5539 1.661480 39.99930 60.00190
29.58334 310.2173 1.660536 40.00511 59.99600
29.65000 310.8822 1.660201 39.99952 60.00370
29.71667 311.5450 1.659738 40.00612 60.00599
29.78333 312.2110 1.659539 39.99630 59.99450
29.85000 312.8775 1.659151 40.01474 59.99816
29.91666 313.5430 1.658623 40.00292 59.99289
29.98334 314.2063 1.658178 40.00803 59.99346
30.05000 314.8673 1.657183 39.99450 59.99599
30.11666 315.5356 1.657312 40.00597 59.99456
30.18333 316.2060 1.657206 39.99158 60.00393
30.25000 316.8744 1.656712 40.00889 59.99104
30.31667 317.5462 1.656918 40.00650 59.99174
30.38334 318.2125 1.656148 39.99437 59.99265
30.45000 318.8855 1.656465 39.99074 60.00255
30.51666 319.5514 1.655754 40.01846 59.99766
30.58334 320.2078 1.654382 39.99844 59.99916
30.65000 320.8633 1.653582 39.99756 60.00937
30.71667 321.5330 1.653838 39.99305 59.99605
30.78333 322.2045 1.654060 39.99214 60.00762
30.85000 322.8690 1.652955 39.99181 60.00328
30.91666 323.5361 1.652678 39.99534 59.98974
30.98334 324.2066 1.652673 40.00889 59.99104
31.05000 324.8728 1.652003 40.00654 59.99240
31.11666 325.5372 1.651488 39.99798 60.00226
31.18333 326.2012 1.650912 40.01375 59.98606
31.25000 326.8694 1.650570 40.00000 59.99566
31.31667 327.5410 1.650674 40.02145 60.00307
31.38334 328.2070 1.650035 40.02462 59.99570
31.45000 328.8737 1.649543 40.00860 59.98376
31.51666 329.5387 1.648984 40.01245 60.00234
31.58334 330.2062 1.648764 40.01440 59.99830
31.65000 330.8746 1.648485 39.99450 60.00567
31.71667 331.5414 1.647994 40.01416 60.01000
31.78333 332.2024 1.647229 40.01245 59.99691
31.85000 332.8688 1.646973 40.01815 60.00188
31.91666 333.5362 1.646545 40.01309 59.98500
31.98334 334.2064 1.646389 39.99787 59.99231
32.05000 334.8780 1.646329 40.00195 60.00582
32.11666 335.5437 1.645480 39.99944 59.99609
32.18334 336.2046 1.644576 40.00888 60.00770
32.25000 336.8730 1.644508 40.00787 60.00105
32.31666 337.5435 1.644364 40.00120 59.99384
32.38334 338.2115 1.643779 39.99704 59.99902
32.45000 338.8745 1.643076 40.00652 59.99521
32.51666 339.5394 1.642771 40.00462 60.00164
32.58333 340.2132 1.643110 40.00120 60.00015
32.65000 340.8770 1.641951 40.00391 59.98904
32.71667 341.5426 1.641671 40.01338 60.00415
32.78333 342.2065 1.640995 40.01114 59.99602
32.85000 342.8754 1.640994 39.99091 59.99960
32.91667 343.5429 1.640358 39.99983 59.99545
32.98334 344.2047 1.639353 40.00318 60.00299
33.05000 344.8702 1.638999 39.99887 60.00337
33.11666 345.5458 1.639744 40.00033 60.00184
33.18334 346.2148 1.638842 40.00196 60.00292
33.25000 346.8692 1.637173 40.00340 60.00074
33.31666 347.5332 1.637025 39.99532 59.99528
33.38334 348.2083 1.637613 40.01440 60.00661
33.45000 348.8790 1.636854 39.99067 60.00258
33.51666 349.5540 1.637214 40.00557 60.00224
33.58333 350.2189 1.636380 39.99950 59.99864
33.65000 350.8730 1.634670 40.00608 59.99938
33.71667 351.5391 1.634854 40.00159 60.00262
33.78333 352.2075 1.634826 40.00510 60.00470
33.85000 352.8746 1.634170 40.01184 60.00527
33.91667 353.5409 1.633532 39.99013 59.99660
33.98334 354.2058 1.633051 40.00558 59.99814
34.05000 354.8717 1.632422 40.00420 59.99991
34.11666 355.5400 1.632164 39.99836 59.98132
34.18334 356.2113 1.632155 39.99149 59.99506
34.25000 356.8782 1.631323 40.01138 59.99980
34.31666 357.5412 1.630704 39.99443 60.01151
34.38334 358.2079 1.630352 40.00322 60.01206
34.45000 358.8746 1.629554 40.02058 59.99674
34.51666 359.5421 1.629425 40.03032 59.99810
34.58333 360.2132 1.629456 40.01120 59.99119
34.65000 360.8802 1.628591 39.98021 60.00732
34.71667 361.5444 1.627874 40.00042 59.99634
34.78333 362.2138 1.628036 39.98840 59.99843
34.85000 362.8791 1.627106 39.99252 59.99674
34.91667 363.5434 1.626465 39.99424 60.00182
34.98334 364.2122 1.626276 39.99846 59.99008
35.05000 364.8765 1.625525 40.00192 60.00674
35.11666 365.5459 1.625000 39.99024 59.99555
35.18334 366.2117 1.624228 40.00003 59.99444
35.25000 366.8816 1.624308 40.00103 59.99890
35.31666 367.5537 1.624044 40.00780 60.00184
35.38334 368.2148 1.622886 40.00322 59.99220
35.45000 368.8752 1.622116 39.99934 59.99473
35.51666 369.5464 1.622495 40.00300 60.01305
35.58333 370.2150 1.621658 39.99944 60.00478
35.65000 370.8810 1.621214 40.00122 59.99416
35.71667 371.5506 1.620935 40.00018 59.99380
35.78333 372.2110 1.619757 40.00281 59.98735
35.85000 372.8776 1.619511 40.00964 60.00535
35.91667 373.5425 1.618671 40.01417 60.00290
35.98334 374.2153 1.618650 40.02072 59.99348
36.05000 374.8809 1.617638 40.00325 60.00428
36.11666 375.5503 1.617404 39.99826 59.99818
36.18334 376.2208 1.616899 39.99625 59.99989
36.25000 376.8864 1.615925 40.00559 60.01062
36.31666 377.5506 1.615268 39.99347 60.00154
36.38334 378.2186 1.615339 40.00058 60.00144
36.45000 378.8877 1.614686 39.99933 59.98750
36.51666 379.5508 1.613680 39.99106 59.99308
36.58333 380.2163 1.613072 40.00390 59.99106
36.65000 380.8842 1.612682 39.99055 59.99450
36.71667 381.5510 1.611932 39.99850 59.99135
36.78333 382.2170 1.611329 39.98718 60.00956
36.85000 382.8828 1.610466 39.99250 59.99294
36.91667 383.5506 1.609860 39.99236 59.99738
36.98334 384.2216 1.609471 40.00130 59.99244
37.05000 384.8869 1.608433 40.00094 59.98908
37.11666 385.5538 1.607954 39.98752 59.98762
37.18334 386.2172 1.606927 40.00359 60.00144
37.25000 386.8867 1.606577 40.00400 60.00332
37.31666 387.5544 1.605719 40.00455 60.00562
37.38334 388.2219 1.605119 39.99372 59.98839
37.45000 388.8868 1.604107 40.00144 60.00072
37.51666 389.5522 1.603420 39.98439 60.00310
37.58333 390.2200 1.602792 40.00500 60.00842
37.65000 390.8862 1.601765 39.98631 59.97744
37.71667 391.5533 1.601078 39.99982 60.00062
37.78333 392.2162 1.599766 39.99457 60.00516
37.85000 392.8882 1.599596 39.99988 59.99158
37.91667 393.5563 1.598751 40.01204 60.00418
37.98334 394.2200 1.597636 40.01572 59.98694
38.05000 394.8890 1.597081 39.99480 59.99701
38.11666 395.5536 1.595909 40.00116 59.99340
38.18334 396.2110 1.594048 40.00636 59.99218
38.25000 396.8837 1.594245 39.98480 59.99989
38.31666 397.5522 1.592698 39.99602 59.99407
38.38334 398.2144 1.591259 40.00228 60.01157
38.45000 398.8889 1.591109 40.00744 60.00630
38.51666 399.5600 1.589979 40.00362 59.99743
38.58333 400.2280 1.588743 40.00080 59.99361
38.65000 400.9014 1.588286 40.02275 60.00500
38.71667 401.5619 1.586375 40.01256 59.99996
38.78333 402.2290 1.585446 39.99412 60.00630
38.85000 402.8941 1.584109 39.99363 59.98813
38.91667 403.5642 1.583318 39.99321 59.99986
38.98334 404.2365 1.582354 39.98722 60.00200
39.05000 404.9000 1.580676 40.00628 59.98388
39.11666 405.5660 1.579439 39.99125 60.01282
39.18334 406.2286 1.577611 40.01440 59.99613
39.25000 406.8892 1.575767 40.00574 60.00335
39.31666 407.5660 1.575755 39.98888 60.00505
39.38334 408.2303 1.573407 40.00310 59.97882
39.45000 408.9032 1.572784 40.01202 60.00438
39.51666 409.5675 1.570688 39.99558 59.99578
39.58333 410.2276 1.568989 39.99076 60.00708
39.65000 410.8940 1.567602 39.99963 60.00512
39.71667 411.5615 1.565921 40.00136 60.00516
39.78333 412.2260 1.563924 40.00852 59.98644
39.85000 412.8920 1.561986 40.02326 60.00220
39.91667 413.5598 1.560405 39.99982 59.99844
39.98334 414.2322 1.558958 40.00848 60.01289
40.05000 414.8971 1.556562 40.00300 60.01713
40.11666 415.5628 1.554761 39.99853 60.00895
40.18334 416.2393 1.553764 39.98936 60.00411
40.25000 416.9026 1.551045 39.98776 60.01150
40.31666 417.5635 1.548439 39.99817 60.00842
40.38334 418.2238 1.545936 40.01530 59.99360
40.45000 418.8937 1.544121 39.98730 60.00660
40.51666 419.5586 1.541181 40.00288 60.00864
40.58333 420.2266 1.538835 40.00402 60.00362
40.65000 420.8939 1.536142 40.00995 60.00212
40.71667 421.5596 1.533258 40.00880 59.99712
40.78333 422.2278 1.530724 40.00070 60.00168
40.85000 422.9002 1.528274 40.00015 60.00660
40.91667 423.5646 1.524841 39.99422 60.00352
40.98334 424.2244 1.521336 39.99866 60.00271
41.05000 424.8897 1.518075 40.00665 59.99780
41.11666 425.5598 1.515039 40.00667 59.99344
41.18334 426.2297 1.511956 39.99795 59.99646
41.25000 426.9008 1.508485 40.00235 59.99180
41.31666 427.5664 1.504775 40.01981 60.01087
41.38334 428.2300 1.500824 40.00557 59.99397
41.45000 428.9032 1.497536 40.00452 59.99534
41.51666 429.5731 1.493994 39.99882 60.00870
41.58333 430.2388 1.490150 40.00154 59.99800
41.65000 430.8956 1.485022 40.00735 60.01239
41.71667 431.5574 1.480539 39.99396 60.00688
41.78333 432.2308 1.476954 39.99691 60.00348
41.85000 432.9040 1.472666 40.01132 60.00215
41.91667 433.5744 1.468111 39.99700 59.99716
41.98334 434.2426 1.463823 39.99984 60.00924
42.05000 434.9082 1.459626 39.98818 60.00292
42.11666 435.5722 1.454652 40.00623 59.98972
42.18334 436.2390 1.450062 39.99353 60.01526
42.25000 436.9068 1.445193 40.00980 59.99041
42.31666 437.5741 1.440097 40.00094 60.00087
42.38334 438.2411 1.435370 40.00465 60.00220
42.45000 438.9054 1.430082 39.99382 60.00075
42.51666 439.5738 1.424928 40.01440 60.00507
42.58333 440.2491 1.420274 40.00375 60.00826
42.65000 440.9183 1.415026 40.02230 60.01161
42.71667 441.5784 1.408705 39.99528 60.01011
42.78333 442.2400 1.402979 40.00609 59.98837
42.85000 442.9061 1.397307 39.99642 59.99478
42.91667 443.5728 1.391155 39.99228 60.00700
42.98334 444.2406 1.384877 39.99843 59.99600
43.05000 444.9118 1.378846 40.01763 59.98394
43.11666 445.5822 1.372438 39.98642 60.01135
43.18334 446.2489 1.365704 40.01068 60.01189
43.25000 446.9158 1.358918 39.98860 60.01212
43.31666 447.5790 1.351707 40.00482 60.00310
43.38334 448.2498 1.345332 40.00602 60.00504
43.45000 448.9102 1.337134 40.00117 60.00344
43.51666 449.5828 1.330575 39.97794 59.99763
43.58333 450.2454 1.322264 40.00364 59.99668
43.65000 450.9136 1.315024 39.97970 60.00120
43.71667 451.5752 1.306968 40.01007 59.99965
43.78333 452.2396 1.299040 40.01252 59.99656
43.85000 452.9109 1.291725 40.01495 59.99954
43.91667 453.5760 1.283574 40.01686 59.98930
43.98334 454.2426 1.275724 39.98645 60.00874
44.05000 454.9133 1.268319 40.00431 59.97838
44.11666 455.5701 1.259261 40.00438 59.99268
44.18334 456.2272 1.251143 40.01146 59.99578
44.25000 456.9021 1.243300 40.00824 60.00505
44.31666 457.5665 1.233955 40.00950 60.00599
44.38334 458.2287 1.224850 40.00483 60.00451
44.45000 458.9041 1.217415 39.98564 60.00188
44.51666 459.5798 1.209034 40.01917 59.99882
44.58333 460.2549 1.200606 39.98748 59.98932
44.65000 460.9225 1.191535 40.00556 59.99878
44.71667 461.5822 1.181798 39.99742 59.99350
44.78333 462.2398 1.171085 39.99060 60.00126
44.85000 462.9164 1.162701 39.99709 60.00688
44.91667 463.5840 1.152466 39.99557 59.99692
44.98334 464.2493 1.141874 40.01286 60.00281
45.05000 464.9140 1.132033 39.99798 59.99739
45.11666 465.5922 1.121772 40.00321 60.00590
45.18334 466.2622 1.110663 40.00880 60.00741
45.25000 466.9200 1.098840 40.00694 59.99640
45.31666 467.5887 1.089036 40.00528 59.99818
45.38334 468.2506 1.077608 40.00174 59.98880
45.45000 468.9167 1.066113 40.01077 60.00250
45.51666 469.5865 1.054862 39.99410 59.99186
45.58333 470.2488 1.043023 40.01361 59.99649
45.65000 470.9067 1.031000 40.00686 60.01197
45.71667 471.5796 1.019682 39.99104 59.99361
45.78333 472.2469 1.008039 40.00404 60.00180
45.85000 472.9094 0.9964376 39.99727 59.99216
45.91667 473.5708 0.9852924 39.99989 59.99924
45.98334 474.2343 0.9746982 40.00517 59.99366
46.05000 474.8945 0.9634460 40.00929 59.99835
46.11666 475.5578 0.9528848 39.99756 59.99646
46.18334 476.2222 0.9423488 39.99803 59.99810
46.25000 476.8890 0.9323548 40.00080 60.00772
46.31666 477.5538 0.9221645 39.99903 59.99418
46.38334 478.2154 0.9120434 39.99890 60.00920
46.45000 478.8794 0.9020220 40.00286 59.99535
46.51666 479.5439 0.8921897 39.99980 60.00278
46.58333 480.2054 0.8813755 40.00230 59.99137
46.65000 480.8728 0.8718781 40.01213 60.00278
46.71667 481.5462 0.8627174 39.99578 59.99819
46.78333 482.2211 0.8541955 40.01106 59.99004
46.85000 482.8916 0.8456900 39.99381 59.99653
46.91667 483.5552 0.8372684 39.99770 59.98611
46.98334 484.2175 0.8289242 39.99031 60.00930
47.05000 484.8866 0.8216381 39.99414 59.98993
47.11666 485.5604 0.8150391 39.99685 60.00219
47.18334 486.2320 0.8082801 39.99420 60.01707
47.25000 486.9032 0.8019675 40.00874 60.00295
47.31666 487.5714 0.7958160 39.98140 59.99992
47.38334 488.2354 0.7896656 39.98650 60.00161
47.45000 488.9018 0.7842376 40.01998 59.99615
47.51666 489.5692 0.7792947 39.99974 59.99809
47.58333 490.2408 0.7750732 39.99780 59.99276
47.65000 490.9135 0.7713151 39.99704 59.99460
47.71667 491.5846 0.7676501 40.01291 59.99766
47.78333 492.2488 0.7639516 40.00856 60.00366
47.85000 492.9170 0.7610511 40.00713 59.99636
47.91667 493.5790 0.7575370 39.99437 59.98645
47.98334 494.2480 0.7551376 40.01328 59.98768
48.05000 494.9160 0.7527442 40.00267 60.01190
48.11666 495.5860 0.7510275 39.99704 59.99110
48.18334 496.2550 0.7491919 40.01560 59.98952
48.25000 496.9232 0.7477102 40.01602 60.00994
48.31666 497.5867 0.7460658 40.00428 59.99195
48.38334 498.2602 0.7453485 40.00059 60.00200
48.45000 498.9288 0.7440305 39.98259 59.99752
48.51666 499.5952 0.7427682 39.98594 59.98690
48.58333 500.2629 0.7419051 40.00754 59.98526
48.65000 500.9363 0.7414680 40.02255 59.99882
48.71667 501.6086 0.7408884 40.03065 59.98586
48.78333 502.2741 0.7398457 40.01282 60.00041
48.85000 502.9322 0.7384409 39.99840 59.99919
48.91667 503.6026 0.7387520 39.99328 59.99871
48.98334 504.2704 0.7377270 39.99727 59.99472
49.05000 504.9382 0.7373004 39.99578 60.00961
49.11666 505.6078 0.7369851 39.98678 59.99818
49.18334 506.2732 0.7362488 40.01419 59.99635
49.25000 506.9440 0.7363507 40.01121 60.00457
49.31666 507.6106 0.7357313 40.00642 59.98736
49.38334 508.2748 0.7355225 40.00604 60.00437
49.45000 508.9430 0.7353765 39.99375 60.00876
49.51666 509.6104 0.7349726 39.99574 60.00918
49.58333 510.2780 0.7348219 39.99834 59.99965
49.65000 510.9437 0.7345139 39.99717 59.98829
49.71667 511.6137 0.7345103 39.99660 60.00890
49.78333 512.2804 0.7341047 39.99472 59.99384
49.85000 512.9432 0.7337906 39.99904 59.99220
49.91667 513.6117 0.7340345 40.00513 60.00522
49.98334 514.2799 0.7338144 40.01062 60.00756
50.05000 514.9494 0.7340626 40.00989 60.00869
50.11666 515.6131 0.7335184 40.00037 60.00288
50.18334 516.2802 0.7335303 39.99917 59.99080
50.25000 516.9487 0.7334753 39.99829 59.99742
50.31666 517.6146 0.7332704 40.00161 60.00466
50.38334 518.2828 0.7331982 39.99700 59.99727
50.45000 518.9478 0.7326503 40.00972 60.00059
50.51666 519.6184 0.7329424 40.01027 59.99444
50.58333 520.2854 0.7329907 40.00607 60.00116
50.65000 520.9550 0.7332012 40.00203 60.00457
50.71667 521.6241 0.7332330 39.99248 59.98764
50.78333 522.2847 0.7325890 39.99894 60.00214
50.85000 522.9472 0.7322876 39.99748 60.00538
50.91667 523.6162 0.7324118 40.00275 60.00230
50.98334 524.2838 0.7323566 39.99348 59.98850
51.05000 524.9505 0.7320435 40.00414 60.00630
51.11666 525.6262 0.7329160 40.00830 60.00961
51.18334 526.2890 0.7322158 40.00302 60.00154
51.25000 526.9530 0.7319736 40.00752 59.99900
51.31666 527.6246 0.7325890 40.01116 59.99532
51.38334 528.2888 0.7321387 39.99300 59.98554
51.45000 528.9534 0.7317681 40.00604 60.01406
51.51667 529.6196 0.7318707 39.99136 59.98961
51.58333 530.2873 0.7317806 39.99150 60.00729
51.65000 530.9572 0.7319034 39.99014 60.00434
51.71667 531.6270 0.7321600 40.01058 60.00300
51.78333 532.2900 0.7315350 40.00514 59.99804
51.85000 532.9570 0.7315655 39.99680 59.99002
51.91667 533.6236 0.7314156 40.00844 59.98614
51.98333 534.2925 0.7316434 39.99200 59.98959
52.05000 534.9620 0.7318382 39.99406 59.98635
52.11666 535.6280 0.7315191 40.01184 59.99395
52.18334 536.2957 0.7318830 39.99433 60.01059
52.25000 536.9616 0.7316985 39.99344 59.99887
52.31666 537.6264 0.7312959 39.99942 60.00670
52.38334 538.2918 0.7312963 39.98536 60.00337
52.45000 538.9576 0.7309449 40.00052 59.98830
52.51668 539.6276 0.7312486 39.99461 59.99635
52.58332 540.2966 0.7311624 40.00464 60.00068
52.65000 540.9632 0.7308946 40.01834 59.99282
52.71668 541.6304 0.7310288 40.02112 59.99060
52.78332 542.2976 0.7312170 40.00872 59.99468
52.85000 542.9621 0.7309305 39.99922 60.00933
52.91668 543.6312 0.7309838 40.01572 60.02060
52.98332 544.2992 0.7310368 39.99066 59.98826
53.05000 544.9678 0.7310634 40.01142 59.98918
53.11666 545.6350 0.7311056 40.00586 59.99397
53.18334 546.2970 0.7305159 40.00828 60.01289
53.25000 546.9630 0.7304550 39.99834 59.99545
53.31666 547.6343 0.7306631 40.01079 60.00284
53.38334 548.3037 0.7307159 40.01294 60.00210
53.45000 548.9700 0.7307239 40.01356 60.01108
53.51668 549.6359 0.7307732 40.00052 59.99560
53.58332 550.3028 0.7306480 39.99565 59.98868
53.65000 550.9678 0.7303534 40.01046 59.98707
53.71668 551.6308 0.7301936 40.00783 59.99816
53.78332 552.3016 0.7305032 39.99228 59.99882
53.85000 552.9720 0.7306016 39.99460 59.99168
53.91668 553.6426 0.7311657 39.98744 59.98918
53.98332 554.3054 0.7302142 40.00113 60.01407
54.05000 554.9736 0.7301532 40.00188 59.99295
54.11666 555.6456 0.7300844 40.00372 59.98628
54.18334 556.3166 0.7300495 39.98723 60.00654
54.25000 556.9863 0.7300772 39.99371 60.00634
54.31666 557.6521 0.7298497 40.00331 59.98430
54.38334 558.3190 0.7298494 39.99226 59.99250
54.45000 558.9902 0.7303376 39.99495 60.00005
54.51668 559.6563 0.7300760 39.98418 59.99252
54.58332 560.3264 0.7304602 40.02392 59.98884
54.65000 560.9900 0.7300271 40.01220 59.98796
54.71668 561.6530 0.7298614 39.99975 59.99855
54.78332 562.3188 0.7296668 40.01261 60.00224
54.85000 562.9835 0.7293809 39.99974 59.99640
54.91668 563.6515 0.7294160 39.99638 59.99953
54.98332 564.3220 0.7297891 40.00122 60.00476
55.05000 564.9907 0.7300072 40.00946 59.99451
55.11666 565.6535 0.7296078 40.00860 60.00571
55.18334 566.3174 0.7295422 39.99866 59.99031
55.25000 566.9901 0.7302149 40.01254 60.00480
55.31666 567.6572 0.7300544 40.01754 60.00469
55.38334 568.3222 0.7295513 40.00620 60.00476
55.45000 568.9816 0.7287796 40.00589 59.99508
55.51668 569.6503 0.7290634 40.01492 60.00440
55.58332 570.3236 0.7297776 40.00104 60.00202
55.65000 570.9904 0.7292240 39.99244 59.99600
55.71668 571.6587 0.7297485 39.99322 59.99960
55.78332 572.3172 0.7285426 39.99009 60.00239
55.85000 572.9872 0.7292419 40.00570 60.00210
55.91668 573.6663 0.7305200 39.99606 60.00418
55.98332 574.3276 0.7294597 39.99426 60.00508
56.05000 574.9854 0.7288842 39.99182 59.99903
56.11666 575.6516 0.7287940 39.98962 59.99747
56.18334 576.3237 0.7291032 39.99722 60.00686
56.25000 576.9898 0.7286868 40.01110 60.00780
56.31666 577.6574 0.7289669 40.00538 59.99086
56.38334 578.3230 0.7286671 39.99480 59.98806
56.45000 578.9941 0.7291726 40.00421 59.99293
56.51668 579.6684 0.7299270 40.00074 59.99652
56.58332 580.3252 0.7284918 40.00780 59.99118
56.65000 580.9879 0.7286431 40.01722 60.00274
56.71668 581.6543 0.7281824 40.01206 59.99131
56.78332 582.3257 0.7282822 39.98868 60.01078
56.85000 582.9994 0.7286120 40.00031 59.99401
56.91668 583.6824 0.7303749 40.00108 60.00865
56.98332 584.3332 0.7285564 39.98750 59.99645
57.05000 584.9965 0.7287189 39.99473 59.99902
57.11666 585.6642 0.7284125 40.01160 60.00352
57.18334 586.3307 0.7283196 39.99982 59.99182
57.25000 586.9966 0.7279558 39.99864 59.99868
57.31666 587.6660 0.7280824 40.00557 59.99540
57.38334 588.3368 0.7282344 40.00186 59.99912
57.45000 589.0030 0.7279778 39.99334 59.98702
57.51668 589.6688 0.7278587 40.00182 60.00072
57.58332 590.3366 0.7280829 39.99704 60.00772
57.65000 591.0050 0.7281012 39.98504 60.00008
57.71668 591.6753 0.7282694 39.99980 60.00304
57.78332 592.3420 0.7282550 40.01068 59.99834
57.85000 593.0030 0.7276878 40.00118 59.99487
57.91668 593.6738 0.7282959 39.99560 59.97813
57.98332 594.3406 0.7278738 40.00129 60.00282
58.05000 595.0082 0.7278279 40.01125 59.99646
58.08332 595.3426 0.7278280 39.98560 60.00300