File: TGA/ZIF8cellulose rods sample3.txt
CLOSED
Version	1.0
Language	English
Run	1
RunSerial	823
Instrument	TGA Q500 V6.7 Build 203
Module	TGA
InstSerial	0500-0499
Operator	at615
File	C:\TA\Data\TGA\ak794\anders\ZIF8cellulose rods sample3.001
FurnaceType	Standard
Sample	ZIF8 cellulose rods in air s3
Size	6.58800	mg
ProcName
Method
Comment
Xcomment	Pan: Platinum
Xcomment	Gas1: Air
Xcomment	Gas2: Air
Xcomment	Balance Gas: Air 40.0 ml/min
Xcomment	Sample Gas: Air 60.0 ml/min
Text	Cellulose rods and zif8 degradation in air. Sample 3
Kcell	1.00000
TempCal	3	pts	20.00	20.00,364.00	356.00,776.00	770.00
InstCalDate	Weight Date 2013-03-01 10:10:44
Controls	Gas 2  Event Off  Sampling 2.0
Nsig	5
Sig1	Time (min)
Sig2	Temperature (°C)
Sig3	Weight (mg)
Sig4	Balance Purge Flow (mL/min)
Sig5	Sample Purge Flow (mL/min)
AirCoolTime	20.0 min
AutoAnalysis	Off
MacroFile
Date	2013-03-11
Time	18:35:16
OrgMethod	1: Ramp 10.00 °C/min to 600.00 °C
OrgFile	C:\Users\AIM_Group\Desktop\post doc cambridge\Students files\Internships\Anders\anders tga\anders\ZIF8cellulose rods sample3.001
7.33333E-4 17.91302 6.588430 40.00728 60.00686
0.05000000 17.96540 6.587989 39.97847 59.99885
0.1166666 18.10902 6.587568 40.00415 59.99586
0.1833334 18.34525 6.587910 40.00744 59.99770
0.2500000 18.65753 6.587971 40.01031 60.01888
0.3166666 19.03227 6.587772 39.99004 59.99226
0.3833333 19.45400 6.588018 40.00104 59.99311
0.4500000 19.91752 6.587369 40.01184 60.00806
0.5166666 20.41283 6.587060 40.00194 59.99875
0.5833332 20.93810 6.586708 40.00838 60.00239
0.6500000 21.48703 6.586499 39.99740 60.00826
0.7166666 22.05529 6.586122 40.00552 60.00025
0.7833334 22.63985 6.585274 39.99376 59.99550
0.8500000 23.24122 6.584849 40.00765 59.99446
0.9166668 23.85282 6.583869 40.00750 60.00302
0.9833334 24.47241 6.583497 40.00041 59.99491
1.050000 25.10180 6.582842 39.99568 59.99470
1.116667 25.73685 6.582212 40.00758 60.00120
1.183333 26.37588 6.582397 39.98917 59.98610
1.250000 27.01832 6.580372 40.00726 59.99936
1.316667 27.66258 6.580318 39.99783 60.00235
1.383333 28.30936 6.579594 40.00089 60.00144
1.450000 28.95502 6.579487 39.99101 59.98596
1.516666 29.60273 6.578150 39.99919 60.00715
1.583334 30.25000 6.576784 40.00009 60.00671
1.650000 30.89894 6.575816 40.00177 60.00100
1.716667 31.54563 6.574962 39.99825 59.99141
1.783333 32.19264 6.575259 39.99942 60.00575
1.850000 32.83782 6.574438 39.99436 59.99712
1.916666 33.48328 6.573440 40.00133 60.00050
1.983334 34.12872 6.572701 39.99793 59.99486
2.050000 34.77186 6.571734 40.00039 60.01035
2.116666 35.41528 6.571314 40.00203 59.99943
2.183334 36.05772 6.570657 39.99414 59.99346
2.250000 36.70242 6.569480 40.00854 60.00572
2.316666 37.34530 6.568857 40.00930 60.00747
2.383334 37.98841 6.568422 39.99282 59.99436
2.450000 38.63056 6.567578 40.00332 60.01075
2.516666 39.27517 6.566862 39.99885 59.99708
2.583333 39.92012 6.566443 40.00062 59.99907
2.650000 40.56437 6.565790 40.00214 59.99695
2.716667 41.20938 6.564751 40.01062 60.00616
2.783333 41.85361 6.563858 40.00254 60.00156
2.850000 42.50228 6.563549 40.00187 60.00149
2.916667 43.14770 6.562888 40.00719 60.00686
2.983334 43.79652 6.561899 40.00102 60.00185
3.050000 44.44468 6.561581 39.99384 59.99972
3.116666 45.09534 6.560974 40.01200 59.98994
3.183334 45.74565 6.560304 39.99744 59.99351
3.250000 46.39523 6.559592 39.99705 59.99906
3.316666 47.04666 6.559016 40.00337 59.99863
3.383334 47.69888 6.558284 40.00500 59.99356
3.450000 48.35338 6.557757 40.00249 60.00050
3.516667 49.00664 6.556926 40.00790 60.00205
3.583333 49.66064 6.556436 39.99296 59.98526
3.650000 50.31610 6.555803 39.99654 59.99018
3.716667 50.97336 6.555307 39.99917 60.00700
3.783333 51.63292 6.554884 39.99685 60.01057
3.850000 52.29208 6.554186 39.99544 60.00220
3.916667 52.95014 6.553640 39.99597 59.99982
3.983333 53.60942 6.553000 40.00089 60.00692
4.050000 54.26985 6.552559 40.00583 59.99451
4.116667 54.93368 6.552212 40.00288 59.99287
4.183334 55.59453 6.551314 40.00186 59.99135
4.250000 56.25566 6.551140 39.99579 59.99714
4.316666 56.91800 6.550720 40.00183 59.99963
4.383333 57.57896 6.549908 39.99615 59.99276
4.450000 58.24229 6.549592 40.00798 59.99810
4.516667 58.90585 6.549238 39.99806 59.99174
4.583334 59.56798 6.548655 40.00850 60.00936
4.650000 60.23088 6.548004 40.01135 60.00688
4.716667 60.89486 6.547635 39.99605 60.00064
4.783333 61.56076 6.547496 40.00326 59.99796
4.850000 62.22350 6.546840 39.98953 59.98597
4.916666 62.88698 6.546319 39.98994 59.99420
4.983333 63.55160 6.545706 40.00808 60.01018
5.050000 64.21645 6.545391 40.01060 60.00462
5.116667 64.88120 6.544868 39.97708 59.98432
5.183334 65.54851 6.545037 40.00284 59.99324
5.250000 66.21245 6.544150 40.00538 60.01120
5.316666 66.87820 6.543712 40.00196 59.99750
5.383332 67.54482 6.543943 40.00004 60.00868
5.450000 68.20900 6.542818 39.99636 60.00766
5.516668 68.87402 6.542246 39.99408 59.98293
5.583334 69.53804 6.541660 39.99005 59.99657
5.650000 70.20698 6.541861 40.01098 60.01563
5.716668 70.87376 6.541220 40.01030 59.99639
5.783332 71.54132 6.541306 40.00446 59.99976
5.850000 72.20757 6.540582 40.00820 59.99786
5.916666 72.87498 6.540214 39.99178 59.99555
5.983332 73.54199 6.539550 40.00704 60.00857
6.050000 74.20900 6.539234 40.01142 60.00780
6.116668 74.87616 6.538933 39.97954 59.98796
6.183334 75.54368 6.538674 39.99760 60.01326
6.250000 76.20955 6.537937 40.00465 59.99660
6.316666 76.87515 6.537042 39.99188 59.99140
6.383332 77.54426 6.537290 40.01430 60.01528
6.450000 78.21157 6.536800 40.00969 59.99938
6.516668 78.87966 6.536671 40.00332 60.00450
6.583334 79.54634 6.535844 39.99772 59.99757
6.650000 80.21374 6.535406 39.99717 60.00359
6.716666 80.88022 6.535064 40.00650 60.00035
6.783334 81.54714 6.534512 39.98268 60.00394
6.850000 82.21262 6.533550 40.00030 59.99731
6.916666 82.87824 6.533066 40.00342 59.99742
6.983332 83.54551 6.532722 40.00763 60.00666
7.050000 84.21637 6.532761 40.00786 59.99398
7.116668 84.88201 6.531513 40.00488 60.00544
7.183334 85.55082 6.531082 40.00590 60.00434
7.250000 86.21628 6.530274 39.98970 59.99665
7.316666 86.88081 6.529711 40.01365 60.00875
7.383332 87.55097 6.529462 40.00919 60.00634
7.450000 88.21952 6.528903 40.00150 60.00070
7.516668 88.88580 6.527847 39.99234 60.00524
7.583334 89.55157 6.527056 39.99534 59.99852
7.650000 90.21974 6.526495 40.00560 60.00165
7.716666 90.88651 6.525479 39.99999 60.00837
7.783334 91.55356 6.524850 40.00490 60.00452
7.850000 92.22285 6.524362 40.00329 59.99627
7.916666 92.89042 6.523574 40.00454 60.00890
7.983332 93.55722 6.522419 40.00262 59.99247
8.050000 94.22388 6.521440 40.00912 60.01166
8.116668 94.89025 6.520508 40.01007 59.99452
8.183334 95.55793 6.519588 39.99690 59.99922
8.250000 96.22696 6.518699 39.99274 59.99449
8.316666 96.89321 6.517488 40.00862 59.99787
8.383332 97.56076 6.516809 40.00225 60.00365
8.450000 98.22816 6.515753 40.00967 60.01032
8.516666 98.89349 6.514426 40.00537 59.99556
8.583332 99.55842 6.513038 40.00388 60.01112
8.650000 100.2244 6.511732 39.99275 59.99111
8.716666 100.8899 6.510184 40.00186 59.99389
8.783334 101.5576 6.509371 40.00137 60.00847
8.850000 102.2253 6.508005 39.99094 59.99082
8.916668 102.8904 6.506407 39.98979 59.99818
8.983334 103.5575 6.504996 39.99970 59.99052
9.050000 104.2236 6.503368 40.00538 59.99818
9.116668 104.8919 6.501868 39.99224 59.99389
9.183334 105.5569 6.499932 39.99950 59.99293
9.250000 106.2232 6.498130 39.99389 59.98555
9.316666 106.8908 6.496547 39.99761 59.99503
9.383332 107.5565 6.494590 40.00516 60.00596
9.450000 108.2230 6.492766 40.00633 59.99970
9.516666 108.8878 6.490219 40.00305 59.99409
9.583332 109.5536 6.488352 39.99265 59.99412
9.650000 110.2229 6.486484 39.99041 59.99474
9.716666 110.8904 6.484156 39.99820 59.99582
9.783334 111.5566 6.481955 39.99910 59.99889
9.850000 112.2234 6.479504 39.99922 60.00694
9.916668 112.8890 6.476704 39.99578 59.99770
9.983334 113.5557 6.474207 39.99489 59.98904
10.05000 114.2239 6.471912 39.98992 60.00322
10.11667 114.8914 6.469124 40.00045 60.00064
10.18333 115.5591 6.466510 39.98704 59.99070
10.25000 116.2241 6.463276 40.01361 60.00068
10.31667 116.8891 6.460234 40.00236 60.00234
10.38333 117.5569 6.457328 40.00631 60.00951
10.45000 118.2229 6.454111 39.99644 59.99524
10.51666 118.8917 6.451464 39.99506 60.00730
10.58333 119.5576 6.447850 39.98664 59.99330
10.65000 120.2235 6.444441 40.00776 60.00455
10.71666 120.8919 6.441426 40.01580 60.01275
10.78334 121.5602 6.437963 39.99900 59.99855
10.85000 122.2260 6.434287 39.98156 59.99344
10.91667 122.8857 6.429512 40.00152 60.00637
10.98334 123.5560 6.426850 39.98346 60.01443
11.05000 124.2201 6.422269 39.99506 59.98120
11.11667 124.8872 6.418709 40.00072 59.99660
11.18334 125.5524 6.414344 40.00203 60.01389
11.25000 126.2212 6.410479 40.00819 60.00839
11.31666 126.8876 6.406142 39.99622 60.01284
11.38333 127.5527 6.401802 39.99202 59.99688
11.45000 128.2269 6.398530 40.01048 59.98522
11.51666 128.8948 6.393757 40.02004 59.99588
11.58333 129.5577 6.388286 39.98416 59.99011
11.65000 130.2212 6.383484 40.00922 60.01281
11.71666 130.8863 6.378546 40.00128 59.99792
11.78334 131.5516 6.374040 39.98407 59.98370
11.85000 132.2169 6.368658 40.00020 59.99791
11.91667 132.8840 6.363994 40.00446 59.99092
11.98334 133.5512 6.358801 40.00874 59.98524
12.05000 134.2190 6.353783 39.98803 59.99047
12.11667 134.8868 6.348492 40.01431 60.00976
12.18334 135.5513 6.342938 40.00616 59.99830
12.25000 136.2193 6.337593 40.01622 59.99572
12.31666 136.8862 6.332007 40.00963 60.00220
12.38333 137.5500 6.326047 40.00647 59.99291
12.45000 138.2184 6.320455 40.00556 60.00898
12.51666 138.8878 6.315035 39.99125 60.00700
12.58333 139.5530 6.308874 40.00066 59.99395
12.65000 140.2216 6.303232 39.98578 59.99885
12.71666 140.8862 6.296793 40.00867 59.99793
12.78334 141.5500 6.290524 40.01004 59.99872
12.85000 142.2162 6.284566 39.99875 59.99634
12.91667 142.8860 6.278941 40.01100 59.99801
12.98334 143.5530 6.272584 39.99387 60.00696
13.05000 144.2164 6.265548 39.99048 60.01172
13.11667 144.8776 6.258942 39.99900 60.00700
13.18333 145.5477 6.253586 39.99618 60.01054
13.25000 146.2138 6.247040 40.00514 60.00864
13.31667 146.8805 6.240464 40.00816 60.00066
13.38333 147.5487 6.234358 39.99732 60.00426
13.45000 148.2164 6.227944 39.99235 59.99278
13.51666 148.8832 6.221466 40.00531 60.00216
13.58333 149.5466 6.214484 40.00246 60.01133
13.65000 150.2168 6.208701 39.99661 60.00274
13.71666 150.8842 6.202309 40.01083 60.00641
13.78334 151.5494 6.195720 39.99022 60.00992
13.85000 152.2149 6.189236 39.99868 60.00020
13.91667 152.8814 6.183014 39.99616 59.99478
13.98334 153.5476 6.176623 39.99512 60.00081
14.05000 154.2142 6.170498 40.00046 59.99230
14.11667 154.8785 6.164040 39.98662 60.00176
14.18333 155.5432 6.157771 39.99528 59.99304
14.25000 156.2113 6.151915 39.99560 59.99676
14.31667 156.8781 6.145756 40.00383 59.99282
14.38333 157.5476 6.140156 40.00769 59.99965
14.45000 158.2095 6.133365 39.99620 59.98330
14.51666 158.8717 6.126946 40.00378 60.00229
14.58333 159.5398 6.121612 39.99313 60.00381
14.65000 160.2095 6.116060 40.00105 59.99477
14.71666 160.8748 6.109805 39.99468 59.97918
14.78334 161.5413 6.103884 39.99765 59.99178
14.85000 162.2061 6.097934 39.99406 59.99560
14.91667 162.8714 6.092026 40.01056 59.99450
14.98334 163.5417 6.086811 39.99392 60.00696
15.05000 164.2108 6.080997 40.00552 60.00729
15.11667 164.8752 6.074522 40.00106 59.98925
15.18333 165.5369 6.068045 40.00116 59.99428
15.25000 166.2030 6.062489 40.00115 60.00229
15.31667 166.8683 6.056202 40.00634 60.00288
15.38333 167.5359 6.050293 40.01043 60.00546
15.45000 168.1989 6.043298 40.01681 59.98837
15.51666 168.8662 6.037195 39.99452 59.99918
15.58333 169.5336 6.030903 39.99180 60.00502
15.65000 170.2034 6.024735 40.00574 59.99540
15.71666 170.8681 6.017451 39.99316 59.98838
15.78334 171.5353 6.010708 39.99498 59.99328
15.85000 172.1979 6.003580 39.99426 59.99942
15.91667 172.8638 5.996416 39.99139 60.00262
15.98334 173.5282 5.989023 40.01030 59.99026
16.05000 174.1937 5.981848 39.99456 59.98950
16.11667 174.8647 5.975041 39.99387 60.00585
16.18333 175.5333 5.967610 39.99437 59.99640
16.25000 176.1991 5.959906 39.99100 60.01347
16.31667 176.8648 5.952224 39.98004 60.00971
16.38333 177.5283 5.944171 40.00161 60.01400
16.45000 178.1927 5.936626 40.01692 59.99426
16.51666 178.8620 5.929615 39.98522 60.01266
16.58334 179.5301 5.922037 40.01342 59.99874
16.65000 180.1925 5.914031 40.01663 59.98648
16.71667 180.8597 5.907026 40.00714 59.97693
16.78333 181.5312 5.900350 39.99522 59.99480
16.85000 182.1927 5.892382 39.98297 59.99774
16.91666 182.8602 5.885786 39.99334 60.01170
16.98334 183.5272 5.879049 40.00732 59.99990
17.05000 184.1923 5.872236 40.00286 59.99379
17.11667 184.8579 5.865512 40.01470 59.98251
17.18333 185.5259 5.859389 40.00610 60.00020
17.25000 186.1940 5.853114 40.00814 59.99666
17.31667 186.8582 5.846506 39.99763 60.00762
17.38333 187.5248 5.840504 39.99680 60.00379
17.45000 188.1902 5.834424 39.99916 59.99582
17.51666 188.8561 5.828404 39.99802 60.00182
17.58334 189.5248 5.822705 40.01709 59.98743
17.65000 190.1896 5.816613 40.00824 60.00739
17.71667 190.8554 5.810814 39.99456 60.00370
17.78333 191.5218 5.805234 39.99668 60.00581
17.85000 192.1899 5.799570 40.00060 59.99182
17.91666 192.8548 5.793800 39.98878 60.01965
17.98334 193.5218 5.788276 39.99065 59.99120
18.05000 194.1866 5.782618 40.01105 59.99694
18.11667 194.8510 5.776924 40.00344 60.01872
18.18333 195.5135 5.771156 40.00008 59.99660
18.25000 196.1838 5.766433 40.00162 59.98522
18.31667 196.8545 5.761280 40.00617 60.00368
18.38333 197.5209 5.755626 40.00980 59.99338
18.45000 198.1851 5.750006 40.00100 60.00772
18.51666 198.8509 5.744785 40.00328 59.99451
18.58334 199.5154 5.739345 40.00972 59.99887
18.65000 200.1802 5.734042 39.99683 59.99810
18.71667 200.8461 5.728862 39.99833 60.00270
18.78333 201.5134 5.723705 39.99942 60.00695
18.85000 202.1791 5.718430 39.99458 59.99270
18.91666 202.8448 5.713195 40.00238 59.99703
18.98334 203.5142 5.708385 40.00088 60.00000
19.05000 204.1794 5.702828 40.00746 59.99032
19.11667 204.8438 5.697488 40.00340 60.00556
19.18333 205.5102 5.692322 39.99605 60.00217
19.25000 206.1787 5.687476 39.99300 59.99613
19.31667 206.8449 5.682294 39.99315 60.00102
19.38333 207.5102 5.676905 40.00494 60.00626
19.45000 208.1766 5.671840 40.00117 59.99762
19.51666 208.8434 5.666661 40.00451 59.99556
19.58334 209.5072 5.661118 40.00967 59.99880
19.65000 210.1745 5.655961 39.99000 59.99832
19.71667 210.8403 5.650491 40.00160 59.99441
19.78333 211.5042 5.644882 39.99002 60.00658
19.85000 212.1726 5.639542 40.00206 59.99780
19.91666 212.8404 5.634028 39.99394 60.00463
19.98334 213.5074 5.627944 40.00662 59.99454
20.05000 214.1745 5.621982 39.99304 60.00359
20.11667 214.8440 5.616533 39.98606 60.00549
20.18333 215.5074 5.609765 40.00569 59.99741
20.25000 216.1684 5.602950 39.99556 60.00171
20.31667 216.8346 5.596680 40.00105 60.00646
20.38333 217.5040 5.590090 40.00800 59.99901
20.45000 218.1697 5.582500 39.99322 60.01480
20.51666 218.8381 5.575043 39.98403 60.00056
20.58334 219.5048 5.566665 39.98310 60.01496
20.65000 220.1704 5.557885 40.00490 59.98225
20.71667 220.8361 5.549250 39.97976 60.01220
20.78333 221.5051 5.540568 39.99538 59.99838
20.85000 222.1701 5.531355 39.99336 60.01020
20.91666 222.8348 5.522250 40.01464 59.97618
20.98334 223.5006 5.513016 39.98889 60.01871
21.05000 224.1670 5.504058 39.99603 60.00322
21.11667 224.8349 5.495430 39.98667 60.00715
21.18333 225.5013 5.486972 39.99316 60.00993
21.25000 226.1666 5.478687 40.00946 59.99550
21.31667 226.8312 5.470562 39.99735 60.00100
21.38333 227.4948 5.463246 39.98160 60.00662
21.45000 228.1586 5.456050 39.99387 60.01326
21.51666 228.8258 5.449834 40.02160 60.00807
21.58334 229.4882 5.442932 40.01766 59.97928
21.65000 230.1540 5.437205 40.00472 59.98984
21.71667 230.8182 5.431199 40.00627 59.98049
21.78333 231.4859 5.425930 39.99554 60.01837
21.85000 232.1524 5.420612 40.00141 60.00005
21.91666 232.8169 5.415392 40.00126 59.99912
21.98334 233.4867 5.411096 39.99702 60.00590
22.05000 234.1560 5.406536 39.99328 60.00150
22.11667 234.8187 5.401824 39.99292 59.99498
22.18333 235.4825 5.397450 39.99881 59.98669
22.25000 236.1526 5.393981 40.01078 59.99714
22.31667 236.8218 5.390156 40.01155 60.00140
22.38333 237.4868 5.386370 39.99326 60.01343
22.45000 238.1450 5.381943 39.99583 60.01201
22.51666 238.8080 5.378672 40.00315 60.00636
22.58334 239.4766 5.375840 39.99509 60.00597
22.65000 240.1422 5.372512 39.99263 60.00586
22.71667 240.8146 5.370031 40.00389 60.00662
22.78333 241.4866 5.367524 39.99780 59.99611
22.85000 242.1540 5.364542 39.99334 60.00750
22.91666 242.8163 5.361433 40.00400 60.00344
22.98334 243.4815 5.358980 40.00172 60.00492
23.05000 244.1544 5.357193 39.98613 59.99862
23.11667 244.8219 5.354552 40.00715 59.99112
23.18333 245.4806 5.351508 40.00581 59.99818
23.25000 246.1505 5.350024 40.00109 60.00093
23.31667 246.8118 5.347059 40.01061 59.99894
23.38333 247.4764 5.344856 40.00016 60.00310
23.45000 248.1463 5.343271 39.98478 60.00305
23.51666 248.8112 5.340859 40.00822 59.99766
23.58334 249.4763 5.338484 39.99531 60.00350
23.65000 250.1469 5.337016 40.00140 59.99470
23.71667 250.8158 5.334852 40.00105 59.99258
23.78333 251.4798 5.332488 39.99762 60.00680
23.85000 252.1493 5.330818 40.00555 60.00710
23.91666 252.8130 5.328342 39.99684 60.00544
23.98334 253.4831 5.326862 39.99245 59.99588
24.05000 254.1468 5.324291 39.99840 60.00648
24.11667 254.8118 5.322256 39.99188 60.00605
24.18333 255.4746 5.319868 39.99914 60.00444
24.25000 256.1460 5.318500 40.00131 59.99674
24.31667 256.8086 5.315844 40.00085 60.00376
24.38333 257.4754 5.313916 40.00440 60.00402
24.45000 258.1409 5.311445 39.99739 59.99260
24.51666 258.8086 5.309448 40.00540 60.00134
24.58334 259.4762 5.307368 39.98757 60.00459
24.65000 260.1463 5.305450 40.01080 59.99258
24.71667 260.8134 5.303140 40.00656 59.99609
24.78333 261.4807 5.300918 39.99672 59.99296
24.85000 262.1437 5.298385 39.99435 59.99980
24.91666 262.8091 5.296118 40.00904 59.99424
24.98334 263.4740 5.293750 40.00818 60.00170
25.05000 264.1391 5.291357 39.99846 60.00720
25.11667 264.8074 5.289102 39.99250 59.99785
25.18333 265.4732 5.286811 39.99725 59.99880
25.25000 266.1394 5.284340 39.99462 59.99238
25.31667 266.8071 5.281921 40.00378 59.99486
25.38333 267.4728 5.279212 40.00294 59.99006
25.45000 268.1401 5.276785 40.00358 59.99436
25.51666 268.8072 5.274172 39.99470 59.98926
25.58334 269.4766 5.271900 39.99134 60.00488
25.65000 270.1418 5.268998 40.00126 59.99964
25.71667 270.8030 5.265818 39.99191 60.00220
25.78333 271.4692 5.263340 39.99984 59.99879
25.85000 272.1374 5.260740 39.99263 60.00676
25.91666 272.8053 5.258079 40.00041 59.99494
25.98334 273.4763 5.255537 39.98611 59.99410
26.05000 274.1428 5.252459 39.99844 60.01009
26.11666 274.8071 5.249097 40.00442 59.98530
26.18333 275.4729 5.246590 40.01132 60.00369
26.25000 276.1387 5.243412 39.98748 60.00052
26.31667 276.8013 5.239973 40.00798 59.99182
26.38334 277.4683 5.237146 40.01422 60.00426
26.45000 278.1337 5.233702 40.01958 60.00732
26.51666 278.8044 5.230946 39.99990 59.99838
26.58334 279.4747 5.227831 40.00246 60.01226
26.65000 280.1393 5.224274 39.98987 59.97961
26.71667 280.8074 5.221264 39.99710 60.01588
26.78333 281.4732 5.217642 40.00126 60.01950
26.85000 282.1372 5.214008 40.00037 59.98532
26.91666 282.8016 5.210463 40.02120 60.00299
26.98334 283.4683 5.206955 40.00436 60.00148
27.05000 284.1356 5.203356 40.00560 59.99204
27.11666 284.8062 5.199840 39.99806 59.98480
27.18333 285.4738 5.196084 39.98862 59.99336
27.25000 286.1390 5.192152 40.00737 59.99575
27.31667 286.8070 5.188453 40.00478 60.01052
27.38334 287.4752 5.184554 39.99742 60.00064
27.45000 288.1410 5.180588 40.00973 60.00768
27.51666 288.8063 5.176533 39.99808 60.01055
27.58334 289.4723 5.172553 40.00638 59.99868
27.65000 290.1400 5.168377 39.99665 60.00318
27.71667 290.8104 5.164551 40.00504 60.01358
27.78333 291.4768 5.160206 40.00604 59.99990
27.85000 292.1414 5.155762 39.99160 59.98892
27.91666 292.8056 5.151290 39.98913 59.98903
27.98334 293.4711 5.146858 39.99443 59.99652
28.05000 294.1414 5.142867 40.00160 59.99930
28.11666 294.8062 5.138030 39.99834 60.01408
28.18333 295.4733 5.133584 39.99876 59.99129
28.25000 296.1416 5.129218 39.99736 59.98419
28.31667 296.8080 5.124488 39.99717 60.00784
28.38334 297.4778 5.120092 40.00235 60.00448
28.45000 298.1457 5.115324 40.00964 60.01064
28.51666 298.8106 5.110356 39.99731 59.98555
28.58334 299.4734 5.105314 39.99825 59.99540
28.65000 300.1413 5.100729 39.99864 60.00100
28.71667 300.8044 5.095428 39.99016 59.99532
28.78333 301.4738 5.090744 39.99678 60.00188
28.85000 302.1370 5.085239 39.98859 59.99458
28.91666 302.8037 5.080442 40.00682 60.01223
28.98334 303.4722 5.075558 40.00430 60.00326
29.05000 304.1393 5.070269 39.99281 59.99922
29.11666 304.8098 5.065572 39.99902 59.99340
29.18333 305.4748 5.060277 39.99356 59.99812
29.25000 306.1322 5.053970 39.99890 59.99666
29.31667 306.7959 5.048721 39.99886 60.00482
29.38334 307.4666 5.044154 40.00242 60.00158
29.45000 308.1335 5.038365 39.99218 59.99781
29.51666 308.8010 5.033104 40.00763 60.00748
29.58334 309.4630 5.027165 40.00770 60.00582
29.65000 310.1310 5.021958 39.99880 59.99536
29.71667 310.8007 5.016828 39.99506 59.98635
29.78333 311.4649 5.011132 39.99742 60.00212
29.85000 312.1302 5.005474 39.99310 59.99238
29.91666 312.8002 5.000244 40.00091 59.99954
29.98334 313.4642 4.994410 40.00409 59.99774
30.05000 314.1282 4.988537 39.99660 60.00974
30.11666 314.7944 4.983240 39.99469 59.99078
30.18333 315.4614 4.977743 40.01150 60.00222
30.25000 316.1250 4.971822 39.99111 59.99149
30.31667 316.7909 4.966309 39.99123 59.99645
30.38334 317.4580 4.960776 40.00563 59.99921
30.45000 318.1243 4.955120 40.01639 60.00606
30.51666 318.7896 4.949417 40.00126 59.99986
30.58334 319.4558 4.943966 39.99844 60.00466
30.65000 320.1240 4.938610 39.99384 60.00056
30.71667 320.7880 4.932652 39.99416 59.99328
30.78333 321.4520 4.927227 39.99100 59.99448
30.85000 322.1218 4.922116 39.99426 59.99285
30.91666 322.7882 4.916474 39.99512 59.99620
30.98334 323.4575 4.911610 40.00190 59.99916
31.05000 324.1193 4.905731 40.00329 60.01028
31.11666 324.7842 4.900459 40.01956 60.01378
31.18333 325.4520 4.895656 39.97983 59.98970
31.25000 326.1199 4.890522 39.98476 59.99000
31.31667 326.7917 4.886028 40.00772 60.00806
31.38334 327.4589 4.881140 39.99276 59.99568
31.45000 328.1228 4.875961 39.99509 59.99474
31.51666 328.7836 4.870856 39.99548 59.99570
31.58334 329.4506 4.866667 39.99978 60.00662
31.65000 330.1142 4.861804 40.01510 60.01712
31.71667 330.7881 4.858410 39.98266 60.00004
31.78333 331.4579 4.854111 39.99090 59.99476
31.85000 332.1205 4.849541 39.98040 59.99498
31.91666 332.7898 4.846206 40.00738 60.00175
31.98334 333.4593 4.842812 40.00928 60.01163
32.05000 334.1206 4.838452 39.99920 60.00883
32.11666 334.7851 4.834871 40.00594 60.00755
32.18334 335.4514 4.831802 39.99826 59.99665
32.25000 336.1235 4.829146 39.99705 59.99049
32.31666 336.7968 4.826468 39.99994 60.00676
32.38334 337.4646 4.823382 39.98994 59.98550
32.45000 338.1234 4.819797 39.99984 59.98849
32.51666 338.7809 4.816628 39.99294 59.99384
32.58333 339.4490 4.814798 39.99747 59.99570
32.65000 340.1156 4.812027 39.99008 59.99086
32.71667 340.7862 4.810196 39.99555 59.99629
32.78333 341.4563 4.807970 39.99480 59.98555
32.85000 342.1284 4.806283 40.01006 60.01526
32.91667 342.7937 4.803953 40.00848 59.99859
32.98334 343.4553 4.801531 40.01030 60.00892
33.05000 344.1265 4.800460 40.00748 60.00488
33.11666 344.7924 4.798496 39.99713 59.99190
33.18334 345.4604 4.796953 40.00190 60.00260
33.25000 346.1277 4.795242 39.99992 60.00628
33.31666 346.7933 4.793488 39.99590 59.99470
33.38334 347.4620 4.792328 40.00608 59.99414
33.45000 348.1312 4.791040 39.99722 59.98605
33.51666 348.7920 4.788730 39.99112 60.01022
33.58333 349.4557 4.787459 39.99554 59.99276
33.65000 350.1272 4.786721 39.99828 60.00694
33.71667 350.7990 4.785712 39.99102 59.99522
33.78333 351.4569 4.783309 40.00433 59.99050
33.85000 352.1280 4.783078 40.00246 59.99478
33.91667 352.7965 4.781744 40.00012 60.00406
33.98334 353.4641 4.780582 39.99988 59.99337
34.05000 354.1234 4.778708 39.99737 59.99940
34.11666 354.7918 4.777830 39.98797 59.99230
34.18334 355.4568 4.776340 39.99712 60.00951
34.25000 356.1278 4.775716 40.00096 60.00412
34.31666 356.7961 4.774582 39.99313 60.01146
34.38334 357.4644 4.773340 39.99988 59.99582
34.45000 358.1324 4.772481 39.99416 59.99387
34.51666 358.7898 4.770276 39.99221 60.00351
34.58333 359.4580 4.769697 40.00212 59.99728
34.65000 360.1292 4.769087 40.00412 60.00635
34.71667 360.7966 4.767691 40.00183 59.99589
34.78333 361.4626 4.766418 40.00002 60.00132
34.85000 362.1272 4.765156 39.99899 59.99888
34.91667 362.7949 4.764090 39.99256 59.99830
34.98334 363.4656 4.763370 40.00157 59.99905
35.05000 364.1340 4.762250 39.99291 59.99457
35.11666 364.8065 4.761526 39.99521 59.98367
35.18334 365.4637 4.759472 39.99526 60.00127
35.25000 366.1405 4.759580 39.99768 59.99734
35.31666 366.7950 4.757078 39.98809 59.98744
35.38334 367.4612 4.756261 39.99328 59.99959
35.45000 368.1351 4.755880 40.00287 59.99885
35.51666 368.7940 4.753950 40.00722 60.01193
35.58333 369.4740 4.754355 39.99416 59.99678
35.65000 370.1475 4.753396 39.99666 59.99407
35.71667 370.8010 4.750766 39.99945 59.99720
35.78333 371.4640 4.749744 40.00055 59.99575
35.85000 372.1324 4.748876 40.00143 60.00393
35.91667 372.8040 4.748222 39.99468 59.99732
35.98334 373.4752 4.747466 40.00500 60.01204
36.05000 374.1418 4.745947 39.99888 59.99870
36.11666 374.8093 4.744998 39.99992 60.00984
36.18334 375.4748 4.743791 39.99808 59.98371
36.25000 376.1400 4.742770 39.99905 60.00756
36.31666 376.8016 4.740860 40.00226 60.00079
36.38334 377.4797 4.741346 40.00440 59.99916
36.45000 378.1426 4.739191 40.00878 60.01060
36.51666 378.8159 4.739286 40.01044 60.00295
36.58333 379.4730 4.736836 39.99244 59.99558
36.65000 380.1406 4.736316 39.99317 60.00512
36.71667 380.8091 4.735470 39.99675 60.00006
36.78333 381.4741 4.734279 39.99664 59.99239
36.85000 382.1427 4.733295 39.99777 60.00731
36.91667 382.8062 4.731958 39.99702 59.99942
36.98334 383.4645 4.730032 40.01063 59.99432
37.05000 384.1342 4.729708 39.99058 59.99211
37.11666 384.8016 4.728518 40.00930 60.00652
37.18334 385.4672 4.727332 39.99998 60.00722
37.25000 386.1383 4.726668 40.00012 59.99634
37.31666 386.8091 4.725969 40.00472 60.00456
37.38334 387.4734 4.724553 40.00314 60.00428
37.45000 388.1342 4.723161 39.99734 60.00676
37.51666 388.7953 4.721813 40.01018 59.99982
37.58333 389.4685 4.721496 39.98655 60.00450
37.65000 390.1428 4.720806 39.99903 60.00852
37.71667 390.7995 4.718522 40.00832 60.01157
37.78333 391.4638 4.717619 40.01436 60.01559
37.85000 392.1347 4.717030 40.00455 59.99082
37.91667 392.7992 4.715684 39.99660 60.00476
37.98334 393.4630 4.714511 39.99424 59.99994
38.05000 394.1326 4.713754 40.00460 59.98759
38.11666 394.8004 4.712354 39.99137 60.00264
38.18334 395.4704 4.711664 39.98936 60.00085
38.25000 396.1386 4.710556 39.98834 60.00704
38.31666 396.8050 4.709476 39.99548 59.99910
38.38334 397.4685 4.708134 39.99698 60.00242
38.45000 398.1362 4.707284 39.99805 59.98385
38.51666 398.8015 4.705836 39.99662 59.99645
38.58333 399.4694 4.705094 39.98234 59.98287
38.65000 400.1381 4.704270 40.00168 60.00307
38.71667 400.8054 4.703362 39.99174 60.00137
38.78333 401.4735 4.702470 39.98168 59.98116
38.85000 402.1397 4.701352 40.00020 59.98418
38.91667 402.8044 4.700125 39.99800 59.99761
38.98334 403.4712 4.699174 40.00534 60.00343
39.05000 404.1345 4.697834 40.02164 60.00999
39.11666 404.8000 4.696808 40.00347 59.99682
39.18334 405.4683 4.696040 39.99315 60.00181
39.25000 406.1372 4.695176 39.98956 60.00687
39.31666 406.8004 4.693600 40.00056 60.00768
39.38334 407.4672 4.692587 39.99795 60.00348
39.45000 408.1372 4.692006 39.98536 60.00266
39.51666 408.8086 4.691269 39.98560 60.00938
39.58333 409.4750 4.690201 39.99222 59.98330
39.65000 410.1398 4.689117 40.01725 59.99756
39.71667 410.8045 4.687914 39.99495 59.99968
39.78333 411.4691 4.686929 39.99974 59.99084
39.85000 412.1431 4.686535 39.98380 59.98836
39.91667 412.8072 4.685160 40.01000 60.00902
39.98334 413.4733 4.684196 39.98337 59.98250
40.05000 414.1392 4.683178 40.01304 59.99895
40.11666 414.8034 4.681836 39.99145 60.02101
40.18334 415.4724 4.681205 39.98634 60.01100
40.25000 416.1410 4.680164 39.98130 59.99600
40.31666 416.8119 4.679521 39.99880 60.00418
40.38334 417.4757 4.678124 40.00964 60.01858
40.45000 418.1406 4.677076 40.00900 60.00115
40.51666 418.8104 4.676468 39.99512 59.99551
40.58333 419.4756 4.675123 39.99506 60.00220
40.65000 420.1422 4.674160 40.00967 60.01640
40.71667 420.8153 4.673671 40.01432 60.01138
40.78333 421.4828 4.672719 39.99751 60.01790
40.85000 422.1490 4.671478 39.99850 60.00790
40.91667 422.8128 4.670281 40.00085 59.99118
40.98334 423.4734 4.668842 40.01955 60.02058
41.05000 424.1420 4.668193 40.01660 60.01174
41.11666 424.8124 4.667298 40.01807 60.00700
41.18334 425.4825 4.666638 40.00211 60.01295
41.25000 426.1507 4.665447 40.00863 60.00401
41.31666 426.8146 4.664404 39.99963 59.99798
41.38334 427.4806 4.663238 40.01330 60.00957
41.45000 428.1463 4.662286 40.00756 59.98535
41.51666 428.8117 4.661071 40.01714 59.98688
41.58333 429.4794 4.660248 40.01357 60.00942
41.65000 430.1489 4.659320 40.01355 59.99834
41.71667 430.8156 4.658230 40.01026 59.99989
41.78333 431.4906 4.657950 40.00690 60.01338
41.85000 432.1526 4.656166 39.98783 60.01187
41.91667 432.8154 4.655224 40.01576 60.00015
41.98334 433.4770 4.653804 39.99640 60.00492
42.05000 434.1439 4.653052 40.00225 60.01376
42.11666 434.8176 4.652515 40.00685 59.99782
42.18334 435.4818 4.650714 39.99582 59.99566
42.25000 436.1503 4.649829 40.00705 59.99778
42.31666 436.8160 4.648506 40.00024 60.01630
42.38334 437.4846 4.647778 39.99685 59.99001
42.45000 438.1480 4.646156 39.99065 59.99766
42.51666 438.8194 4.645519 40.00882 59.99592
42.58333 439.4941 4.645053 40.00787 60.00072
42.65000 440.1585 4.643584 40.00554 60.00140
42.71667 440.8254 4.642631 40.00030 60.00055
42.78333 441.4878 4.640902 40.00473 59.99878
42.85000 442.1528 4.639656 39.99640 60.00320
42.91667 442.8242 4.639011 39.99743 60.00990
42.98334 443.4918 4.637808 40.00110 59.99238
43.05000 444.1570 4.636346 39.99226 59.99113
43.11666 444.8196 4.634787 39.97967 59.99500
43.18334 445.4886 4.633994 39.99662 59.99041
43.25000 446.1610 4.632998 39.99588 60.00871
43.31666 446.8268 4.631442 40.00996 59.99942
43.38334 447.4929 4.629947 40.00799 59.99744
43.45000 448.1613 4.629020 39.99362 59.99961
43.51666 448.8326 4.628317 40.01265 59.99756
43.58333 449.4944 4.626394 39.99728 60.00020
43.65000 450.1584 4.624914 40.00038 60.00630
43.71667 450.8259 4.623900 40.00059 60.01596
43.78333 451.4956 4.622609 39.98613 60.00984
43.85000 452.1612 4.620988 39.99750 59.99950
43.91667 452.8297 4.619697 40.01528 59.99696
43.98334 453.4988 4.618519 39.99224 59.98870
44.05000 454.1710 4.617640 39.99128 59.98778
44.11666 454.8348 4.615914 40.00373 59.99062
44.18334 455.4990 4.614450 40.00481 60.00720
44.25000 456.1644 4.612972 40.01289 59.99871
44.31666 456.8317 4.611308 40.00534 60.01342
44.38334 457.4964 4.609738 39.99000 59.99102
44.45000 458.1616 4.607929 40.00517 59.99740
44.51666 458.8284 4.606456 39.99710 59.98906
44.58333 459.4946 4.604718 39.99793 60.00481
44.65000 460.1666 4.603816 39.98809 60.01402
44.71667 460.8340 4.601978 40.00154 59.99818
44.78333 461.4996 4.600116 40.01170 60.01347
44.85000 462.1724 4.599188 39.98736 60.01300
44.91667 462.8344 4.596850 39.99424 60.01711
44.98334 463.5000 4.595112 39.98508 59.99258
45.05000 464.1754 4.594152 40.00524 59.99126
45.11666 464.8384 4.591870 40.00468 59.98930
45.18334 465.5019 4.589633 40.01006 60.00220
45.25000 466.1697 4.588008 40.01728 59.99390
45.31666 466.8362 4.585787 39.99559 60.00672
45.38334 467.5030 4.583818 40.01275 60.00686
45.45000 468.1719 4.581770 40.00310 60.00782
45.51666 468.8440 4.580116 39.99874 60.00178
45.58333 469.5162 4.578403 40.00645 60.00684
45.65000 470.1837 4.576244 40.00437 59.98862
45.71667 470.8444 4.573590 40.00045 59.99893
45.78333 471.5085 4.571456 39.99711 59.98289
45.85000 472.1742 4.569190 39.99057 60.00346
45.91667 472.8475 4.567554 40.01006 60.00656
45.98334 473.5156 4.564754 40.00322 59.99780
46.05000 474.1837 4.561871 40.01221 59.99564
46.11666 474.8536 4.559010 40.01220 60.00130
46.18334 475.5284 4.556974 39.98538 60.01272
46.25000 476.1940 4.554030 40.00532 59.99863
46.31666 476.8598 4.550853 39.98847 59.98752
46.38334 477.5352 4.548794 40.00087 59.99106
46.45000 478.2038 4.545594 40.00815 59.99142
46.51666 478.8763 4.543160 40.00290 59.99840
46.58333 479.5429 4.539922 40.00539 59.98896
46.65000 480.2044 4.536050 39.99287 59.99550
46.71667 480.8702 4.532680 40.01129 60.00191
46.78333 481.5425 4.529740 39.99416 60.00240
46.85000 482.2092 4.526124 39.99774 59.99891
46.91667 482.8760 4.522152 39.99036 59.97996
46.98334 483.5459 4.518992 40.00928 60.00432
47.05000 484.2134 4.514942 40.01570 59.99117
47.11666 484.8778 4.510644 40.00062 59.99649
47.18334 485.5431 4.506303 39.98922 59.99752
47.25000 486.2135 4.502556 39.98917 60.00022
47.31666 486.8757 4.497586 40.00853 60.01087
47.38334 487.5428 4.493027 40.00090 60.00300
47.45000 488.2111 4.488523 39.98691 59.99418
47.51666 488.8768 4.483322 39.99680 59.98438
47.58333 489.5446 4.478197 40.00350 59.99106
47.65000 490.2102 4.472709 39.99475 60.00866
47.71667 490.8822 4.467719 40.00287 60.01176
47.78333 491.5441 4.461459 39.99934 59.99982
47.85000 492.2086 4.455545 39.99178 59.99149
47.91667 492.8776 4.449868 39.99584 59.99768
47.98334 493.5390 4.443020 40.00662 60.00700
48.05000 494.2016 4.436402 39.99360 59.99282
48.11666 494.8734 4.430191 39.99007 59.99098
48.18334 495.5434 4.423500 39.99664 59.98995
48.25000 496.2096 4.416483 39.99329 59.99969
48.31666 496.8666 4.408498 40.01129 59.99836
48.38334 497.5386 4.401891 39.99619 59.99851
48.45000 498.2050 4.394348 39.99925 59.99202
48.51666 498.8694 4.386336 40.01278 59.99568
48.58333 499.5354 4.378685 40.00007 60.01155
48.65000 500.1908 4.369272 39.99724 59.99074
48.71667 500.8672 4.362530 40.01051 60.00722
48.78333 501.5394 4.354549 39.98767 59.99475
48.85000 502.1967 4.345113 39.98938 60.00816
48.91667 502.8492 4.335208 39.98697 60.00646
48.98334 503.5141 4.326754 40.00814 60.01474
49.05000 504.1820 4.317997 40.01239 60.00488
49.11666 504.8629 4.310612 40.00416 60.00743
49.18334 505.5306 4.301526 39.99725 59.99638
49.25000 506.1894 4.292334 40.00780 60.00580
49.31666 506.8554 4.283847 39.99934 60.00371
49.38334 507.5231 4.275269 39.98721 59.99625
49.45000 508.1903 4.266758 39.99668 59.99450
49.51666 508.8534 4.257761 40.00359 60.00110
49.58333 509.5160 4.248710 40.00350 59.98352
49.65000 510.1813 4.240019 39.99890 60.01580
49.71667 510.8550 4.231965 40.00126 59.99470
49.78333 511.5244 4.223890 40.00273 60.00218
49.85000 512.1956 4.216006 39.99199 60.01325
49.91667 512.8588 4.207710 39.99614 59.98814
49.98334 513.5104 4.197968 40.01023 60.00015
50.05000 514.1728 4.189883 39.99100 60.00226
50.11666 514.8522 4.183094 40.00209 60.00616
50.18334 515.5191 4.174574 40.00628 59.99946
50.25000 516.1828 4.166635 39.99706 60.01903
50.31666 516.8515 4.159504 40.00806 59.99963
50.38334 517.5165 4.151762 40.00062 59.99436
50.45000 518.1896 4.145110 39.99136 59.99141
50.51666 518.8576 4.137929 40.01930 60.00161
50.58333 519.5226 4.130724 39.98738 59.98974
50.65000 520.1944 4.124785 39.98624 60.00156
50.71667 520.8530 4.116892 40.00360 59.99465
50.78333 521.5259 4.111492 40.00988 59.99321
50.85000 522.2002 4.105930 40.00044 59.98371
50.91667 522.8622 4.099156 39.98888 60.00102
50.98334 523.5216 4.092624 40.00354 59.99560
51.05000 524.1810 4.086210 40.00287 59.99856
51.11666 524.8502 4.080668 40.00565 59.99926
51.18334 525.5276 4.076028 40.00275 59.99780
51.25000 526.1997 4.071106 39.98977 60.00871
51.31666 526.8616 4.065228 40.00425 60.00632
51.38334 527.5215 4.059955 40.00719 59.99528
51.45000 528.1975 4.056612 39.98766 59.98968
51.51667 528.8644 4.051714 39.99432 59.99780
51.58333 529.5302 4.047246 40.00626 60.00508
51.65000 530.1943 4.042664 40.00284 60.01087
51.71667 530.8590 4.038428 40.00755 59.99791
51.78333 531.5273 4.034483 39.99652 59.98644
51.85000 532.1988 4.030933 40.00320 59.99895
51.91667 532.8710 4.027614 39.99650 60.00018
51.98333 533.5386 4.024145 39.99184 59.99785
52.05000 534.2006 4.020432 40.00437 60.00513
52.11666 534.8695 4.017410 40.00455 59.99468
52.18334 535.5364 4.014178 40.00981 59.99938
52.25000 536.2078 4.011536 39.99558 60.00720
52.31666 536.8820 4.009450 39.99032 60.01080
52.38334 537.5515 4.007000 39.99242 59.99215
52.45000 538.2042 4.002863 40.00813 59.99950
52.51668 538.8672 4.000300 40.01252 59.98943
52.58332 539.5390 3.997997 39.99375 59.99686
52.65000 540.2100 3.995666 40.01672 59.98642
52.71668 540.8790 3.993360 40.00160 59.98889
52.78332 541.5455 3.991048 40.00070 60.01550
52.85000 542.2129 3.988892 40.00292 60.00840
52.91668 542.8843 3.987450 39.99857 60.00649
52.98332 543.5498 3.985066 39.99652 60.00551
53.05000 544.2145 3.982938 39.99615 60.01152
53.11666 544.8799 3.980861 39.99448 59.99355
53.18334 545.5472 3.978801 40.01260 59.99160
53.25000 546.2197 3.977530 40.00538 60.00674
53.31666 546.8866 3.975617 40.00734 59.99924
53.38334 547.5533 3.974013 39.99635 60.00121
53.45000 548.2188 3.972396 40.00596 60.01070
53.51668 548.8875 3.970938 40.00718 59.99464
53.58332 549.5538 3.969300 40.00040 60.00363
53.65000 550.2195 3.967468 40.00390 60.00382
53.71668 550.8926 3.966438 39.99798 60.00110
53.78332 551.5618 3.964954 40.00958 60.00493
53.85000 552.2271 3.963528 40.01259 59.99236
53.91668 552.8958 3.962572 40.00054 60.00307
53.98332 553.5616 3.961520 39.98813 59.99600
54.05000 554.2240 3.959967 39.99240 59.99244
54.11666 554.8915 3.958855 39.99466 60.00354
54.18334 555.5606 3.957767 39.99876 59.99648
54.25000 556.2305 3.956967 39.99842 60.00453
54.31666 556.8940 3.955638 39.99225 59.99962
54.38334 557.5612 3.954996 39.99486 59.98430
54.45000 558.2275 3.953842 39.99160 60.00335
54.51668 558.8922 3.952520 40.00065 60.00098
54.58332 559.5610 3.951852 39.99622 60.00324
54.65000 560.2335 3.951476 39.99620 59.99283
54.71668 560.9016 3.950790 39.99750 60.00313
54.78332 561.5622 3.949526 39.98961 59.99547
54.85000 562.2288 3.948710 40.00260 59.99060
54.91668 562.8976 3.947830 39.99938 59.98694
54.98332 563.5676 3.947286 40.00552 59.99288
55.05000 564.2348 3.946622 40.00186 60.00164
55.11666 564.9058 3.946352 40.01407 59.99539
55.18334 565.5710 3.945176 40.00998 60.00176
55.25000 566.2389 3.944688 40.00574 59.99965
55.31666 566.9078 3.944048 39.99063 60.00566
55.38334 567.5742 3.943285 39.99185 59.99736
55.45000 568.2502 3.943760 40.00747 60.00175
55.51668 568.9152 3.942798 40.00306 59.99729
55.58332 569.5774 3.942019 39.99539 59.99300
55.65000 570.2410 3.941402 39.99938 60.00340
55.71668 570.9087 3.940820 40.00641 60.00264
55.78332 571.5774 3.940305 40.00864 59.99639
55.85000 572.2486 3.940330 39.99143 60.00171
55.91668 572.9121 3.939625 40.00506 60.00370
55.98332 573.5769 3.939191 40.00611 59.99843
56.05000 574.2476 3.939426 40.01533 59.99611
56.11666 574.9105 3.938664 40.00461 60.01068
56.18334 575.5696 3.937788 40.00115 59.99824
56.25000 576.2454 3.938694 40.00562 59.99474
56.31666 576.9057 3.937256 39.99882 60.00371
56.38334 577.5719 3.936558 40.00876 60.01010
56.45000 578.2465 3.936998 40.00310 59.98642
56.51668 578.9160 3.936767 39.99938 60.00646
56.58332 579.5813 3.936356 40.00126 60.00498
56.65000 580.2453 3.936075 39.99878 59.99731
56.71668 580.9129 3.935981 39.99522 60.00006
56.78332 581.5791 3.935430 39.99937 60.00370
56.85000 582.2492 3.935374 40.00276 59.99982
56.91668 582.9190 3.935578 39.99986 59.99510
56.98332 583.5860 3.935330 40.00354 60.01221
57.05000 584.2476 3.934597 39.99609 60.00278
57.11666 584.9120 3.934572 40.00454 60.00526
57.18334 585.5832 3.934361 40.00381 60.00176
57.25000 586.2516 3.934308 40.01207 60.00280
57.31666 586.9188 3.934201 40.00205 59.99684
57.38334 587.5818 3.933656 39.99160 59.99524
57.45000 588.2550 3.933875 39.99931 59.99910
57.51668 588.9199 3.933554 39.99758 59.99512
57.58332 589.5863 3.933348 40.00375 59.99910
57.65000 590.2550 3.933502 40.00978 60.00315
57.71668 590.9268 3.934058 40.00388 60.00235
57.78332 591.5861 3.932887 39.99750 59.99576
57.85000 592.2520 3.932760 40.00032 59.99343
57.91668 592.9194 3.932606 40.00240 60.00220
57.98332 593.5891 3.932792 40.00336 59.99346
58.05000 594.2560 3.932891 39.99730 59.99690
58.11666 594.9224 3.932705 39.99976 60.00000
58.18334 595.5891 3.932370 40.00764 59.99464