File: TGA/ZIF8cellulosesponge sample 1.txt
CLOSED
Version	1.0
Language	English
Run	1
RunSerial	821
Instrument	TGA Q500 V6.7 Build 203
Module	TGA
InstSerial	0500-0499
Operator	at615
File	C:\TA\Data\TGA\ak794\anders\ZIF8cellulosesponge1.001
FurnaceType	Standard
Sample	ZIF8 cellulose sponge in air 1
Size	5.56500	mg
ProcName
Method
Comment
Xcomment	Pan: Platinum
Xcomment	Gas1: Air
Xcomment	Gas2: Air
Xcomment	Balance Gas: Air 40.0 ml/min
Xcomment	Sample Gas: Air 60.0 ml/min
Text	Cellulose sponge and zif8 degradation in air
Kcell	1.00000
TempCal	3	pts	20.00	20.00,364.00	356.00,776.00	770.00
InstCalDate	Weight Date 2013-03-01 10:10:44
Controls	Gas 2  Event Off  Sampling 2.0
Nsig	5
Sig1	Time (min)
Sig2	Temperature (°C)
Sig3	Weight (mg)
Sig4	Balance Purge Flow (mL/min)
Sig5	Sample Purge Flow (mL/min)
AirCoolTime	20.0 min
AutoAnalysis	Off
MacroFile
Date	2013-03-11
Time	13:44:24
OrgMethod	1: Ramp 10.00 °C/min to 600.00 °C
OrgFile	C:\Users\AIM_Group\Desktop\post doc cambridge\Students files\Internships\Anders\anders tga\anders\ZIF8cellulosesponge sample 1.001
.001116667 17.77372 5.565514 40.00012 60.00007
0.05000000 17.80943 5.564350 39.99631 59.99060
0.1166666 17.94139 5.564332 40.00913 59.99318
0.1833334 18.17238 5.563886 39.98192 60.01526
0.2500000 18.48250 5.562230 39.99761 60.00830
0.3166666 18.85794 5.561711 40.00238 60.00250
0.3833333 19.28150 5.560813 39.98317 59.99638
0.4500000 19.74898 5.559549 39.97790 60.01428
0.5166666 20.24968 5.557930 39.99712 59.99256
0.5833332 20.77583 5.557201 39.98164 60.01944
0.6500000 21.32893 5.555896 40.00752 59.99500
0.7166666 21.90124 5.554429 40.00765 59.98238
0.7833334 22.49024 5.553132 39.98710 59.99946
0.8500000 23.09453 5.551607 39.99658 59.99945
0.9166668 23.70913 5.550338 39.99102 60.01016
0.9833334 24.33256 5.549443 40.00294 60.01146
1.050000 24.96567 5.546976 39.99810 59.99800
1.116667 25.60343 5.545135 40.00120 59.99708
1.183333 26.24602 5.544495 40.01191 59.99403
1.250000 26.88994 5.543004 40.01150 59.98406
1.316667 27.53656 5.541298 39.99997 60.00239
1.383333 28.18516 5.540095 40.00162 59.99150
1.450000 28.83330 5.538472 40.00776 60.00092
1.516666 29.48340 5.536485 39.99025 60.00922
1.583334 30.13295 5.535164 39.99460 60.00219
1.650000 30.78115 5.533544 40.00237 60.00230
1.716667 31.42896 5.532774 40.00112 60.00594
1.783333 32.07725 5.531526 40.00235 60.00176
1.850000 32.72429 5.529781 40.00668 59.99074
1.916666 33.37052 5.528402 40.00364 60.00766
1.983334 34.01523 5.526850 40.01200 59.99098
2.050000 34.66000 5.525300 39.99791 60.00857
2.116666 35.30414 5.523936 39.99848 60.00490
2.183334 35.94872 5.523444 40.00552 59.99814
2.250000 36.59296 5.522248 39.99799 60.00377
2.316666 37.23584 5.521143 39.99872 59.99340
2.383334 37.87900 5.519911 40.01864 60.00921
2.450000 38.52340 5.518925 39.99411 60.00838
2.516666 39.16700 5.517921 40.00269 60.00376
2.583333 39.81291 5.516708 39.99655 59.98414
2.650000 40.45702 5.516059 40.00464 59.99039
2.716667 41.10354 5.515046 40.00302 60.00416
2.783333 41.74934 5.514111 39.99103 59.98870
2.850000 42.39584 5.513369 40.01063 59.99001
2.916667 43.04227 5.512737 40.00216 60.00289
2.983334 43.69052 5.511778 40.01361 59.98956
3.050000 44.33859 5.510680 40.00500 59.99853
3.116666 44.98838 5.509930 40.01002 59.99634
3.183334 45.63835 5.509290 39.98355 60.00952
3.250000 46.28994 5.508824 40.00208 59.98848
3.316666 46.94169 5.508522 39.98588 60.00343
3.383334 47.59439 5.507766 40.02041 59.98894
3.450000 48.24666 5.507074 39.99924 60.00891
3.516667 48.89981 5.506250 40.00730 59.99560
3.583333 49.55628 5.505503 40.00325 60.00242
3.650000 50.21028 5.504800 40.00914 59.98438
3.716667 50.86660 5.504350 40.00319 59.98723
3.783333 51.52272 5.503693 39.99846 60.00644
3.850000 52.17954 5.503175 40.00447 60.01584
3.916667 52.83829 5.502884 40.00560 60.00121
3.983333 53.49970 5.503374 40.00306 60.00814
4.050000 54.15729 5.502074 39.98960 60.00149
4.116667 54.81761 5.501694 40.00116 60.00540
4.183334 55.47683 5.501331 40.01058 59.99154
4.250000 56.13820 5.500662 39.99232 60.00701
4.316666 56.79720 5.500063 39.98606 59.98688
4.383333 57.45826 5.499794 39.99581 59.99600
4.450000 58.12193 5.499458 39.99794 60.00416
4.516667 58.78371 5.498730 39.99768 59.99962
4.583334 59.44668 5.498738 40.00387 60.00298
4.650000 60.11028 5.498004 40.01250 59.99090
4.716667 60.77574 5.498180 40.00223 59.98524
4.783333 61.43882 5.497521 39.99161 60.01228
4.850000 62.10262 5.497182 40.00642 59.99324
4.916666 62.76687 5.496557 39.99309 59.99563
4.983333 63.43086 5.496050 39.99998 60.00085
5.050000 64.09626 5.496318 39.99334 59.99580
5.116667 64.76285 5.495722 40.00053 59.99922
5.183334 65.42628 5.495045 40.00680 60.00651
5.250000 66.09245 5.494859 39.99498 59.99970
5.316666 66.75658 5.494143 39.99756 60.01498
5.383332 67.42296 5.494234 40.00350 60.00533
5.450000 68.08954 5.493900 40.00022 60.00016
5.516668 68.75396 5.493038 40.00206 60.00603
5.583334 69.42224 5.493345 40.00408 60.00842
5.650000 70.09003 5.493046 39.99980 59.99470
5.716668 70.75528 5.491894 39.99242 59.99314
5.783332 71.42068 5.491765 40.00862 60.00630
5.850000 72.08921 5.491428 39.99667 60.01822
5.916666 72.75537 5.490856 40.00048 60.00579
5.983332 73.42490 5.491390 40.00124 59.99887
6.050000 74.09050 5.490144 40.00466 59.99922
6.116668 74.75740 5.489998 40.00634 59.99834
6.183334 75.42194 5.488819 39.99736 59.99966
6.250000 76.08690 5.488128 40.00300 60.00710
6.316666 76.75601 5.488256 40.00072 59.98924
6.383332 77.42221 5.487451 39.99610 59.99989
6.450000 78.08936 5.487280 39.99584 59.99824
6.516668 78.75735 5.486688 40.00190 60.00225
6.583334 79.42494 5.486118 39.99823 60.01006
6.650000 80.09270 5.485908 39.98404 59.99560
6.716666 80.76126 5.485489 40.00946 59.98484
6.783334 81.42786 5.484585 40.01567 59.98776
6.850000 82.09566 5.484000 40.02146 60.00800
6.916666 82.76100 5.482919 40.00852 60.00706
6.983332 83.42613 5.482144 40.01989 60.01702
7.050000 84.09449 5.481984 39.98610 60.01562
7.116668 84.76246 5.481482 39.99756 59.99406
7.183334 85.43026 5.480722 40.00108 59.99742
7.250000 86.09559 5.479717 40.01322 59.99748
7.316666 86.76089 5.478389 39.99260 59.99433
7.383332 87.42772 5.477900 40.00302 59.98976
7.450000 88.09590 5.477213 40.00587 59.99306
7.516668 88.76444 5.476720 40.01976 59.99820
7.583334 89.43178 5.475610 40.00835 60.00097
7.650000 90.09812 5.474553 40.00024 59.99531
7.716666 90.76551 5.473426 39.99441 60.00168
7.783334 91.43194 5.472472 40.00625 59.99982
7.850000 92.09930 5.471787 40.00406 59.99492
7.916666 92.76641 5.470606 40.00294 59.99832
7.983332 93.43414 5.469670 40.00662 59.99407
8.050000 94.10192 5.468545 39.99221 60.00234
8.116668 94.77047 5.467585 40.00548 60.00449
8.183334 95.43548 5.466000 39.99082 59.98888
8.250000 96.10342 5.464864 39.99863 59.98446
8.316666 96.77006 5.463778 39.99115 59.99654
8.383332 97.43562 5.461656 40.00325 59.98650
8.450000 98.10172 5.460579 39.99833 60.00299
8.516666 98.77003 5.459363 39.99036 59.99318
8.583332 99.43725 5.457879 39.99544 60.00493
8.650000 100.1045 5.456524 39.99421 59.99328
8.716666 100.7733 5.455376 40.00506 60.01118
8.783334 101.4389 5.453043 40.00494 60.00393
8.850000 102.1029 5.451191 39.99472 60.01060
8.916668 102.7700 5.449551 39.99342 59.99516
8.983334 103.4360 5.447930 40.00108 60.00176
9.050000 104.1023 5.446192 40.00737 59.99468
9.116668 104.7697 5.443829 39.99678 60.00500
9.183334 105.4385 5.442200 40.00730 60.00151
9.250000 106.1072 5.440527 40.00620 59.99671
9.316666 106.7727 5.437926 40.00358 60.00356
9.383332 107.4355 5.435293 39.99635 59.99717
9.450000 108.1014 5.433310 39.99740 59.99160
9.516666 108.7710 5.431624 40.00820 60.00835
9.583332 109.4380 5.429132 39.99716 60.00996
9.650000 110.1026 5.426168 39.99734 59.99326
9.716666 110.7692 5.423876 40.00008 59.99661
9.783334 111.4346 5.421432 40.00295 60.00562
9.850000 112.0977 5.418028 40.00711 60.00468
9.916668 112.7685 5.416192 39.99698 60.00639
9.983334 113.4393 5.413531 40.00327 59.99982
10.05000 114.1062 5.410474 40.00669 60.01004
10.11667 114.7734 5.407612 40.00857 60.00300
10.18333 115.4389 5.404268 39.99964 60.00239
10.25000 116.1064 5.401470 39.98887 60.00244
10.31667 116.7731 5.398250 39.99709 59.99340
10.38333 117.4393 5.394894 39.98830 59.99662
10.45000 118.1075 5.391660 39.99284 59.99363
10.51666 118.7728 5.387898 40.00080 60.01162
10.58333 119.4415 5.384749 40.00903 60.00110
10.65000 120.1050 5.380630 39.98967 59.99399
10.71666 120.7736 5.377461 39.99426 60.00830
10.78334 121.4402 5.373472 40.00738 60.01143
10.85000 122.1056 5.369545 39.98755 59.99810
10.91667 122.7724 5.365682 39.98618 60.00132
10.98334 123.4369 5.361572 39.99689 59.99361
11.05000 124.1033 5.357434 39.99993 59.98800
11.11667 124.7688 5.353230 39.98713 59.98728
11.18334 125.4346 5.348898 40.01480 60.01264
11.25000 126.1000 5.344629 39.98884 59.99594
11.31666 126.7700 5.340496 40.00030 59.99769
11.38333 127.4354 5.335559 39.99512 60.00019
11.45000 128.1029 5.331477 40.00395 60.00040
11.51666 128.7708 5.326600 39.99170 59.98670
11.58333 129.4400 5.322308 39.99724 60.01714
11.65000 130.1081 5.317555 40.00204 60.00079
11.71666 130.7724 5.311907 39.99626 59.99405
11.78334 131.4333 5.306679 40.00806 60.00744
11.85000 132.0989 5.301804 40.00832 59.99492
11.91667 132.7663 5.296900 39.97800 59.96684
11.98334 133.4313 5.291476 39.98540 59.98962
12.05000 134.0975 5.285948 39.98458 59.98926
12.11667 134.7686 5.281440 40.00370 59.99541
12.18334 135.4363 5.275395 40.00316 59.99693
12.25000 136.0964 5.269310 39.99788 59.99816
12.31666 136.7619 5.264262 40.00583 59.98814
12.38333 137.4274 5.258407 40.00236 59.98948
12.45000 138.1001 5.253950 39.99408 59.99688
12.51666 138.7712 5.248072 40.00334 60.00666
12.58333 139.4372 5.241991 39.99664 60.01807
12.65000 140.1012 5.236026 39.99881 59.98970
12.71666 140.7661 5.229776 39.99572 59.99810
12.78334 141.4271 5.223836 39.99145 60.00025
12.85000 142.0925 5.218052 39.99469 59.98930
12.91667 142.7604 5.212303 40.01903 60.00250
12.98334 143.4239 5.205774 39.99644 59.99989
13.05000 144.0984 5.201322 40.00188 60.01391
13.11667 144.7689 5.195076 40.01480 60.00499
13.18333 145.4352 5.188683 40.00234 60.01198
13.25000 146.0988 5.182383 39.98737 59.99377
13.31667 146.7627 5.176243 40.00110 60.01060
13.38333 147.4275 5.170210 40.00582 60.00362
13.45000 148.0946 5.164314 39.99398 59.99226
13.51666 148.7605 5.158586 39.99972 59.99982
13.58333 149.4263 5.152314 40.00408 59.99711
13.65000 150.0922 5.146346 40.00061 59.99176
13.71666 150.7555 5.140066 39.98700 60.00707
13.78334 151.4252 5.134809 40.00247 59.99438
13.85000 152.0943 5.129032 40.01169 60.00369
13.91667 152.7605 5.122920 39.98962 60.00076
13.98334 153.4274 5.117123 39.99716 59.99560
14.05000 154.0901 5.110814 40.00036 60.01118
14.11667 154.7539 5.105102 39.99262 60.00222
14.18333 155.4224 5.100011 39.99612 59.99762
14.25000 156.0927 5.094989 40.00186 59.99912
14.31667 156.7580 5.088691 40.00615 60.00550
14.38333 157.4198 5.082806 39.99336 59.99264
14.45000 158.0878 5.078082 39.99422 60.00337
14.51666 158.7530 5.072372 39.99308 59.99954
14.58333 159.4216 5.067410 39.99175 60.01270
14.65000 160.0899 5.062332 40.00615 60.00850
14.71666 160.7583 5.057346 39.99713 59.99676
14.78334 161.4240 5.052240 40.00840 60.00190
14.85000 162.0883 5.046922 39.99889 59.99260
14.91667 162.7542 5.042042 39.99561 60.00780
14.98334 163.4202 5.037366 40.00177 60.00247
15.05000 164.0850 5.032553 39.99364 59.99920
15.11667 164.7534 5.028316 40.00287 60.00720
15.18333 165.4220 5.023808 39.99559 60.00510
15.25000 166.0853 5.019019 39.99803 59.99966
15.31667 166.7460 5.013932 39.98529 59.99412
15.38333 167.4127 5.010704 39.99648 60.00007
15.45000 168.0846 5.007011 40.00925 60.00294
15.51666 168.7472 5.001903 39.99920 59.99442
15.58333 169.4106 4.997848 39.99906 60.00006
15.65000 170.0766 4.993972 39.99654 59.99571
15.71666 170.7437 4.990410 39.99628 59.98972
15.78334 171.4131 4.986834 39.99066 59.99336
15.85000 172.0807 4.983047 39.99650 60.01605
15.91667 172.7453 4.979381 39.98904 60.00037
15.98334 173.4119 4.975926 39.98996 59.99516
16.05000 174.0774 4.972344 39.99468 59.99664
16.11667 174.7441 4.969062 39.99130 59.99318
16.18333 175.4089 4.965524 39.99948 60.00082
16.25000 176.0763 4.962384 40.00296 60.01614
16.31667 176.7428 4.959164 40.00366 60.00729
16.38333 177.4149 4.956476 40.00688 59.99390
16.45000 178.0827 4.953232 39.99605 59.99491
16.51666 178.7470 4.949748 39.98991 59.98746
16.58334 179.4086 4.946030 40.00074 59.99739
16.65000 180.0730 4.942869 40.00148 60.00007
16.71667 180.7426 4.940683 40.01130 60.00596
16.78333 181.4087 4.936970 40.00114 60.00354
16.85000 182.0768 4.934264 39.98596 60.00000
16.91666 182.7435 4.930900 39.99472 59.99870
16.98334 183.4090 4.927618 39.99580 60.00986
17.05000 184.0754 4.924574 39.99638 60.00800
17.11667 184.7406 4.921242 39.98862 59.99742
17.18333 185.4051 4.917969 39.98946 60.00059
17.25000 186.0744 4.915218 39.99058 60.01304
17.31667 186.7399 4.911436 40.00440 60.00750
17.38333 187.4045 4.908172 39.99798 59.99945
17.45000 188.0723 4.905163 40.00760 60.00734
17.51666 188.7370 4.901538 40.01033 60.00380
17.58334 189.4101 4.899058 39.99500 60.00244
17.65000 190.0751 4.895003 40.00222 59.98800
17.71667 190.7383 4.891434 40.00294 60.01436
17.78333 191.4013 4.887674 40.00168 60.00615
17.85000 192.0696 4.884726 39.99732 59.98994
17.91666 192.7390 4.881482 40.00192 59.98100
17.98334 193.4010 4.877180 40.00392 60.00582
18.05000 194.0727 4.874508 40.00286 60.01704
18.11667 194.7380 4.870507 39.99168 59.99590
18.18333 195.4006 4.866640 39.99259 59.99604
18.25000 196.0723 4.863562 39.98550 60.00766
18.31667 196.7379 4.859634 40.00564 60.00137
18.38333 197.4054 4.855984 40.00244 60.00352
18.45000 198.0675 4.851776 40.01169 60.00420
18.51666 198.7263 4.847248 39.99404 59.98548
18.58334 199.3894 4.843669 39.98727 59.99941
18.65000 200.0532 4.839534 40.00347 59.99692
18.71667 200.7264 4.836694 40.00309 60.00455
18.78333 201.4049 4.833488 40.00035 60.00124
18.85000 202.0596 4.827520 39.97640 60.01016
18.91666 202.7305 4.824566 39.98216 60.00848
18.98334 203.3960 4.820356 39.98172 60.00204
19.05000 204.0634 4.816468 39.99731 60.00272
19.11667 204.7320 4.812656 40.00222 60.00320
19.18333 205.3934 4.807402 40.01839 60.01406
19.25000 206.0589 4.803414 39.98472 60.01509
19.31667 206.7260 4.799541 40.01260 59.98862
19.38333 207.4013 4.796222 40.00153 59.99337
19.45000 208.0649 4.790924 39.99039 59.99209
19.51666 208.7295 4.786548 40.01914 60.00665
19.58334 209.3904 4.781585 39.97864 60.00401
19.65000 210.0586 4.777770 39.99692 60.00844
19.71667 210.7252 4.773358 40.00122 59.99246
19.78333 211.3966 4.769348 39.98238 59.98887
19.85000 212.0630 4.764463 40.00924 59.98576
19.91666 212.7320 4.760308 40.01178 59.98292
19.98334 213.3979 4.755430 39.99861 59.99000
20.05000 214.0596 4.750290 39.98950 59.98711
20.11667 214.7250 4.746109 40.02398 59.99762
20.18333 215.3946 4.742098 40.01242 59.98921
20.25000 216.0666 4.737831 39.98456 60.00419
20.31667 216.7314 4.732729 39.99100 59.99476
20.38333 217.4006 4.728558 40.01019 59.99913
20.45000 218.0672 4.723922 39.99805 60.00062
20.51666 218.7334 4.719346 40.00219 59.99880
20.58334 219.3984 4.714818 39.99422 60.00070
20.65000 220.0613 4.710022 39.99917 59.99382
20.71667 220.7260 4.705675 40.00302 60.00068
20.78333 221.3916 4.701278 39.98735 60.00614
20.85000 222.0590 4.696705 40.00615 60.00043
20.91666 222.7236 4.692286 40.00534 60.00308
20.98334 223.3897 4.688024 40.01035 59.98664
21.05000 224.0562 4.683747 40.00614 59.99321
21.11667 224.7246 4.679748 40.00662 60.00971
21.18333 225.3921 4.675470 39.99852 59.99809
21.25000 226.0601 4.671297 39.98301 59.99185
21.31667 226.7246 4.667044 39.98906 60.00528
21.38333 227.3949 4.663706 39.99736 60.00852
21.45000 228.0596 4.659110 40.00074 60.01476
21.51666 228.7205 4.654654 39.99441 59.99879
21.58334 229.3873 4.651058 40.00261 60.00533
21.65000 230.0539 4.647299 40.00875 59.99996
21.71667 230.7190 4.643444 40.00918 59.98840
21.78333 231.3868 4.639746 39.99780 59.99932
21.85000 232.0524 4.635750 40.00368 59.99630
21.91666 232.7132 4.631620 39.99444 60.01301
21.98334 233.3820 4.628280 40.00226 59.99691
22.05000 234.0494 4.624768 39.99020 59.99248
22.11667 234.7134 4.620636 39.99623 60.00463
22.18333 235.3770 4.617097 40.00353 59.99814
22.25000 236.0476 4.614226 40.05958 59.99532
22.31667 236.7136 4.610388 39.99844 60.00840
22.38333 237.3838 4.607057 39.99609 60.00206
22.45000 238.0490 4.603459 40.00236 59.98666
22.51666 238.7107 4.599426 39.99832 60.00259
22.58334 239.3749 4.595967 40.00736 59.99094
22.65000 240.0430 4.592776 40.00104 59.99620
22.71667 240.7068 4.589030 39.99329 59.99724
22.78333 241.3749 4.585663 39.99791 59.99758
22.85000 242.0431 4.582380 39.99964 60.00830
22.91666 242.7098 4.578646 40.00194 59.99485
22.98334 243.3736 4.574820 40.00506 60.01455
23.05000 244.0404 4.571312 40.00306 59.98977
23.11667 244.7068 4.567534 40.00586 59.99245
23.18333 245.3725 4.563681 40.00430 59.99378
23.25000 246.0397 4.559890 39.99058 60.00450
23.31667 246.7057 4.555708 39.99930 60.00484
23.38333 247.3684 4.551119 40.00240 59.99418
23.45000 248.0350 4.546937 40.00723 60.00175
23.51666 248.7026 4.542657 39.99347 60.00789
23.58334 249.3684 4.537690 39.99856 59.99622
23.65000 250.0342 4.532748 39.99345 60.00268
23.71667 250.6989 4.527550 40.00606 60.00255
23.78333 251.3671 4.522407 40.00454 60.00567
23.85000 252.0348 4.516914 40.01394 59.99878
23.91666 252.7010 4.510942 40.00589 60.01078
23.98334 253.3662 4.504776 39.99456 60.00124
24.05000 254.0334 4.498440 39.99348 60.00240
24.11667 254.6974 4.491533 40.00280 59.99976
24.18333 255.3625 4.484306 40.00022 59.99580
24.25000 256.0317 4.477492 39.99717 60.00642
24.31667 256.7002 4.469948 39.99676 60.01049
24.38333 257.3650 4.461667 39.99969 59.99900
24.45000 258.0302 4.453416 39.99600 60.00110
24.51666 258.6990 4.444843 40.00471 60.00413
24.58334 259.3658 4.435904 39.99867 59.99261
24.65000 260.0308 4.426298 40.00440 59.99426
24.71667 260.6946 4.416391 39.99832 59.98821
24.78333 261.3599 4.406506 40.00274 59.99792
24.85000 262.0250 4.395965 39.99844 59.99520
24.91666 262.6942 4.385312 40.00119 60.00742
24.98334 263.3633 4.374300 40.01412 60.00472
25.05000 264.0292 4.362634 39.99609 60.00042
25.11667 264.6971 4.350918 39.99148 59.99486
25.18333 265.3630 4.338754 39.99837 59.99792
25.25000 266.0266 4.325854 39.99732 59.99905
25.31667 266.6941 4.313398 40.00854 60.00064
25.38333 267.3620 4.300526 39.99782 59.99963
25.45000 268.0283 4.287124 40.00816 59.99629
25.51666 268.6947 4.273664 40.00825 59.98918
25.58334 269.3626 4.260068 40.00574 59.99771
25.65000 270.0321 4.246374 40.00752 60.01184
25.71667 270.7008 4.232554 40.00732 60.00518
25.78333 271.3637 4.217816 39.99672 59.99560
25.85000 272.0225 4.203009 40.00430 60.00491
25.91666 272.6957 4.189870 39.99388 59.99496
25.98334 273.3732 4.176277 39.99705 60.00310
26.05000 274.0364 4.160945 39.99634 60.01087
26.11666 274.6958 4.145918 39.99481 59.99255
26.18333 275.3556 4.131200 39.99802 60.00220
26.25000 276.0234 4.117615 39.99620 60.00588
26.31667 276.7042 4.105191 40.00140 59.99696
26.38334 277.3721 4.090272 39.99128 59.98437
26.45000 278.0420 4.076816 39.98901 60.01011
26.51666 278.7155 4.063751 40.00528 60.00603
26.58334 279.3758 4.049716 40.00034 59.98806
26.65000 280.0373 4.036464 39.99965 59.99566
26.71667 280.7011 4.024052 39.99377 59.99043
26.78333 281.3762 4.013081 40.00402 59.98424
26.85000 282.0441 4.000730 39.99992 59.99720
26.91666 282.7060 3.988868 39.99574 59.98484
26.98334 283.3696 3.978086 40.01580 60.00309
27.05000 284.0416 3.968793 40.00350 59.99508
27.11666 284.7122 3.959366 39.99712 59.99343
27.18333 285.3786 3.950244 40.00733 59.99870
27.25000 286.0490 3.942212 39.99644 59.99376
27.31667 286.7180 3.934254 39.99987 60.00266
27.38334 287.3787 3.926158 40.01176 59.99613
27.45000 288.0522 3.919856 40.00032 59.99870
27.51666 288.7222 3.912995 40.00556 60.00752
27.58334 289.3832 3.905563 39.99872 59.99400
27.65000 290.0460 3.898980 39.99075 60.00744
27.71667 290.7091 3.892410 40.00502 60.00226
27.78333 291.3789 3.886544 40.00616 59.98650
27.85000 292.0532 3.880887 40.01494 59.99120
27.91666 292.7062 3.873407 40.02213 59.99432
27.98334 293.3720 3.867509 39.99122 60.00088
28.05000 294.0325 3.860881 40.01623 59.99788
28.11666 294.6986 3.854954 39.99155 60.01120
28.18333 295.3661 3.848694 39.99948 60.00294
28.25000 296.0344 3.842357 39.99479 59.99761
28.31667 296.6920 3.834944 39.99133 60.00127
28.38334 297.3561 3.828314 39.99725 60.00992
28.45000 298.0222 3.821850 39.99617 60.00398
28.51666 298.6905 3.814883 39.99466 60.00640
28.58334 299.3594 3.807935 40.01194 59.97207
28.65000 300.0237 3.800174 40.02240 59.99612
28.71667 300.6892 3.792728 40.00308 59.98056
28.78333 301.3550 3.785028 39.99104 60.00218
28.85000 302.0200 3.776936 40.01186 59.99708
28.91666 302.6820 3.768563 40.01284 59.99441
28.98334 303.3486 3.760286 39.99446 60.00768
29.05000 304.0162 3.751568 40.01230 59.98642
29.11666 304.6838 3.742774 40.01108 59.99613
29.18333 305.3490 3.733361 40.00089 60.00761
29.25000 306.0228 3.724753 40.01051 60.00039
29.31667 306.6930 3.714889 39.98835 60.01493
29.38334 307.3520 3.703942 40.00360 60.01152
29.45000 308.0131 3.693486 39.98880 60.01089
29.51666 308.6800 3.682964 40.00075 59.99854
29.58334 309.3490 3.672383 40.00050 60.00434
29.65000 310.0225 3.661523 40.00950 59.98137
29.71667 310.6919 3.649953 39.99908 60.00756
29.78333 311.3529 3.637258 40.00947 59.99938
29.85000 312.0190 3.625000 39.98908 60.00082
29.91666 312.6815 3.611750 39.99465 60.00759
29.98334 313.3435 3.598206 40.01110 59.98838
30.05000 314.0150 3.585110 39.99451 59.99558
30.11666 314.6824 3.571040 40.00286 60.00213
30.18333 315.3518 3.556574 39.98100 60.01936
30.25000 316.0205 3.541557 40.01036 59.99912
30.31667 316.6932 3.526594 40.00576 60.00528
30.38334 317.3560 3.510004 39.99983 60.00634
30.45000 318.0196 3.493298 40.01832 59.98919
30.51666 318.6902 3.476729 40.00134 60.00072
30.58334 319.3596 3.459369 39.99634 60.00535
30.65000 320.0225 3.440455 39.99300 60.00623
30.71667 320.6862 3.421396 40.00406 60.01380
30.78333 321.3497 3.401774 39.99691 59.99894
30.85000 322.0182 3.381807 39.99657 59.99946
30.91666 322.6869 3.361030 40.00905 59.99302
30.98334 323.3579 3.339453 39.98545 60.00777
31.05000 324.0218 3.316262 39.99783 60.01010
31.11666 324.6872 3.292888 40.01194 59.99716
31.18333 325.3628 3.269735 39.99938 59.99770
31.25000 326.0376 3.244827 39.99687 59.98389
31.31667 326.6988 3.217444 39.99478 60.01005
31.38334 327.3616 3.190096 40.01433 59.99512
31.45000 328.0200 3.161138 40.01244 59.99730
31.51666 328.6869 3.131852 40.00812 60.00652
31.58334 329.3500 3.100513 39.99082 60.00244
31.65000 330.0216 3.068884 39.99367 60.00508
31.71667 330.6938 3.035668 39.99552 59.99332
31.78333 331.3617 3.000672 40.00384 59.98324
31.85000 332.0300 2.964563 39.99318 60.01023
31.91666 332.6939 2.926770 40.00144 60.00657
31.98334 333.3551 2.887628 40.00139 59.99684
32.05000 334.0265 2.848550 39.99738 59.99824
32.11666 334.6958 2.807860 40.00588 60.00957
32.18334 335.3529 2.765224 40.01080 59.99011
32.25000 336.0187 2.723830 39.99785 59.99312
32.31666 336.6819 2.681687 39.98355 60.00274
32.38334 337.3455 2.640342 40.00735 59.98223
32.45000 338.0227 2.601199 40.00537 59.98545
32.51666 338.6914 2.561978 40.00262 59.99162
32.58333 339.3578 2.525258 40.00852 59.99735
32.65000 340.0132 2.489782 39.99472 60.00045
32.71667 340.6733 2.458185 39.99747 59.99874
32.78333 341.3350 2.429006 40.00083 60.00375
32.85000 341.9945 2.402100 40.00280 60.00035
32.91667 342.6632 2.378828 40.01141 59.99571
32.98334 343.3280 2.356828 39.99663 59.99319
33.05000 343.9998 2.337990 39.99167 59.98808
33.11666 344.6578 2.319322 39.99544 59.99129
33.18334 345.3162 2.303142 39.99922 59.99500
33.25000 345.9758 2.288350 40.00212 59.98860
33.31666 346.6333 2.274695 40.00722 59.99707
33.38334 347.2965 2.262792 39.99286 60.00201
33.45000 347.9663 2.252192 40.00178 60.00012
33.51666 348.6319 2.241730 40.00448 59.99706
33.58333 349.3035 2.232799 40.00602 59.99440
33.65000 349.9694 2.223532 40.00020 60.00418
33.71667 350.6364 2.215283 40.00235 59.99648
33.78333 351.3032 2.207444 40.00292 60.00031
33.85000 351.9746 2.200615 40.00632 60.00348
33.91667 352.6415 2.193389 40.00756 59.98250
33.98334 353.3103 2.186918 40.00420 59.99088
34.05000 353.9762 2.180442 39.99237 59.99076
34.11666 354.6424 2.174272 40.00125 60.00316
34.18334 355.3140 2.168714 39.98522 60.00710
34.25000 355.9800 2.162660 40.00500 60.00070
34.31666 356.6446 2.156882 40.00692 59.99444
34.38334 357.3181 2.152138 40.00384 59.98984
34.45000 357.9888 2.147013 39.99240 59.99695
34.51666 358.6569 2.141596 40.00033 59.99691
34.58333 359.3248 2.136790 39.99280 60.01756
34.65000 359.9926 2.132196 39.99456 60.00926
34.71667 360.6640 2.127760 39.99468 59.99543
34.78333 361.3261 2.122402 40.00161 60.00538
34.85000 361.9913 2.117792 40.00018 59.99740
34.91667 362.6660 2.114196 39.99286 60.00070
34.98334 363.3375 2.109841 40.00024 60.00208
35.05000 364.0059 2.105261 39.99372 60.00465
35.11666 364.6719 2.101169 39.98876 60.01244
35.18334 365.3470 2.097790 40.01463 59.99317
35.25000 366.0048 2.092712 39.99730 59.99714
35.31666 366.6679 2.088767 40.00328 59.99524
35.38334 367.3460 2.086087 40.00050 59.99982
35.45000 368.0112 2.081731 39.99695 60.00076
35.51666 368.6778 2.077934 39.99918 60.00445
35.58333 369.3436 2.074028 39.98692 59.98853
35.65000 370.0135 2.070842 40.00718 59.99350
35.71667 370.6756 2.066711 39.99274 60.00915
35.78333 371.3455 2.063584 39.98856 60.00764
35.85000 372.0152 2.060366 39.99000 59.99858
35.91667 372.6828 2.056589 40.00450 60.00168
35.98334 373.3438 2.052647 40.00425 60.00258
36.05000 374.0079 2.049307 39.99060 59.99316
36.11666 374.6822 2.046750 39.99916 60.00455
36.18334 375.3527 2.043078 39.99674 60.00872
36.25000 376.0181 2.039852 40.00072 60.00160
36.31666 376.6740 2.035425 39.99470 59.98704
36.38334 377.3560 2.034125 39.98997 60.00793
36.45000 378.0241 2.030384 39.99391 60.00097
36.51666 378.6914 2.027148 40.00282 59.99894
36.58333 379.3618 2.024650 39.99731 60.00346
36.65000 380.0224 2.020692 39.99416 59.99666
36.71667 380.6851 2.017742 39.99275 59.99332
36.78333 381.3492 2.014649 40.00974 59.99613
36.85000 382.0204 2.012201 39.99588 60.00132
36.91667 382.6900 2.009622 40.00674 59.99510
36.98334 383.3554 2.005982 39.99990 59.99755
37.05000 384.0252 2.003399 40.00967 60.00312
37.11666 384.6918 2.000491 39.99717 59.99250
37.18334 385.3564 1.997573 39.99678 60.01059
37.25000 386.0239 1.994884 40.00262 59.99343
37.31666 386.7020 1.993112 39.99544 60.00056
37.38334 387.3617 1.989330 39.99770 60.00494
37.45000 388.0158 1.985598 40.01900 60.00176
37.51666 388.6892 1.984431 39.99061 60.00899
37.58333 389.3691 1.982583 39.99617 59.99413
37.65000 390.0380 1.979433 39.99555 60.00303
37.71667 390.6954 1.975691 39.99290 59.99868
37.78333 391.3464 1.972048 40.00536 60.00296
37.85000 392.0008 1.968433 40.00131 60.00874
37.91667 392.6955 1.969246 40.00250 59.98062
37.98334 393.3524 1.964088 40.00648 59.99851
38.05000 394.0172 1.961620 39.99748 60.00471
38.11666 394.6884 1.959781 39.99098 60.00385
38.18334 395.3497 1.956199 39.99034 60.01078
38.25000 396.0274 1.954938 40.00368 60.00550
38.31666 396.6960 1.952389 40.00205 59.99918
38.38334 397.3602 1.949142 39.99280 60.01308
38.45000 398.0277 1.947089 39.99872 60.00769
38.51666 398.6926 1.944119 39.99392 60.00124
38.58333 399.3611 1.941727 39.99625 59.99472
38.65000 400.0244 1.939164 40.01264 59.98926
38.71667 400.6913 1.936632 40.00136 60.00558
38.78333 401.3510 1.933398 40.00583 59.99674
38.85000 402.0188 1.931287 40.00223 59.99746
38.91667 402.6969 1.929766 39.99938 60.00959
38.98334 403.3572 1.925918 40.00267 60.00193
39.05000 404.0178 1.923152 39.99702 59.99829
39.11666 404.6910 1.921527 40.00634 60.00800
39.18334 405.3586 1.919033 39.99579 59.99735
39.25000 406.0274 1.916564 39.99934 60.00681
39.31666 406.6937 1.913703 40.00148 60.00806
39.38334 407.3554 1.911023 39.98832 60.00166
39.45000 408.0215 1.908472 40.00120 60.00044
39.51666 408.6926 1.906750 40.00678 60.00525
39.58333 409.3654 1.904543 40.00507 60.00476
39.65000 410.0316 1.901923 39.99977 60.00957
39.71667 410.6880 1.898220 40.00788 59.98668
39.78333 411.3590 1.896780 40.00402 59.99211
39.85000 412.0332 1.894677 39.99506 60.01224
39.91667 412.6942 1.891417 39.99924 60.00118
39.98334 413.3550 1.888496 39.99406 60.00874
40.05000 414.0254 1.886739 39.99845 60.00350
40.11666 414.7036 1.885171 40.00076 59.99816
40.18334 415.3672 1.881715 39.99036 60.01054
40.25000 416.0316 1.879317 40.00928 60.00430
40.31666 416.7002 1.877336 39.99669 60.01745
40.38334 417.3699 1.875070 40.00683 59.99621
40.45000 418.0356 1.872477 40.00180 59.99855
40.51666 418.7016 1.870231 39.99237 60.00288
40.58333 419.3663 1.867554 39.98830 59.99968
40.65000 420.0320 1.865274 39.99964 59.99830
40.71667 420.7000 1.863057 40.00197 59.99896
40.78333 421.3616 1.860078 40.00067 60.00724
40.85000 422.0270 1.857744 39.99537 59.99271
40.91667 422.6954 1.855526 39.99550 60.00028
40.98334 423.3604 1.853466 40.00428 60.00425
41.05000 424.0250 1.850976 39.98994 59.99395
41.11666 424.6900 1.848224 39.98848 60.00432
41.18334 425.3675 1.846867 39.99231 60.01130
41.25000 426.0380 1.844017 40.00546 60.00781
41.31666 426.7008 1.841185 40.00269 59.99379
41.38334 427.3686 1.839198 39.99228 60.00937
41.45000 428.0373 1.836994 40.00566 59.99800
41.51666 428.6975 1.833942 40.00330 59.99605
41.58333 429.3742 1.833004 40.01384 59.99924
41.65000 430.0463 1.830567 40.00594 59.99434
41.71667 430.7063 1.827425 39.99664 59.99495
41.78333 431.3676 1.825010 39.99513 60.00390
41.85000 432.0392 1.823277 40.00882 59.99837
41.91667 432.7068 1.821053 39.99622 59.98648
41.98334 433.3752 1.818806 40.00658 59.99986
42.05000 434.0450 1.816854 39.99148 59.99020
42.11666 434.7078 1.814100 39.99716 60.00063
42.18334 435.3716 1.811806 40.00726 59.99905
42.25000 436.0375 1.809462 40.00685 60.00026
42.31666 436.7071 1.807442 39.99689 60.00574
42.38334 437.3704 1.804544 40.01355 59.99421
42.45000 438.0378 1.802508 40.00041 60.00048
42.51666 438.7142 1.801058 40.00064 60.01279
42.58333 439.3787 1.798332 40.00190 59.98309
42.65000 440.0487 1.796751 40.00105 60.01270
42.71667 440.7094 1.793784 40.00473 59.99380
42.78333 441.3697 1.791294 39.99835 60.00026
42.85000 442.0398 1.789699 40.00490 59.98567
42.91667 442.7090 1.787458 40.01116 60.00412
42.98334 443.3753 1.785049 40.00097 59.99128
43.05000 444.0410 1.782831 40.01160 60.00071
43.11666 444.7074 1.780934 39.99519 60.01524
43.18334 445.3732 1.778496 40.00480 59.99370
43.25000 446.0452 1.777040 39.99933 60.01774
43.31666 446.7184 1.775458 40.00013 60.00772
43.38334 447.3820 1.772906 39.99404 60.00860
43.45000 448.0394 1.770122 40.00026 59.99600
43.51666 448.7066 1.768542 39.98778 60.01000
43.58333 449.3740 1.766061 40.00416 60.00222
43.65000 450.0414 1.764044 40.01076 59.99722
43.71667 450.7109 1.762117 40.00098 59.99761
43.78333 451.3766 1.759862 39.99875 59.99966
43.85000 452.0445 1.758118 40.00874 59.99190
43.91667 452.7130 1.756056 39.99872 60.00298
43.98334 453.3817 1.754410 39.99818 59.99939
44.05000 454.0521 1.752733 40.00066 59.99649
44.11666 454.7146 1.750294 40.01413 59.99853
44.18334 455.3786 1.747911 40.00685 59.98496
44.25000 456.0422 1.745962 40.00458 59.99255
44.31666 456.7062 1.743895 40.00112 59.99771
44.38334 457.3778 1.742337 40.00634 59.98818
44.45000 458.0548 1.741204 40.00137 60.00899
44.51666 458.7188 1.738727 39.99993 60.00476
44.58333 459.3820 1.736757 39.99973 59.99980
44.65000 460.0478 1.735148 39.98599 60.00778
44.71667 460.7114 1.732876 39.99990 60.00928
44.78333 461.3789 1.731086 40.00410 59.99344
44.85000 462.0483 1.729484 40.00746 60.00183
44.91667 462.7188 1.727920 40.00556 59.99706
44.98334 463.3866 1.726035 40.00296 59.99133
45.05000 464.0514 1.724128 40.00604 60.00832
45.11666 464.7192 1.722538 40.00030 60.00713
45.18334 465.3884 1.721146 39.99566 59.99644
45.25000 466.0533 1.719091 40.00539 59.99870
45.31666 466.7156 1.717070 39.99086 60.00181
45.38334 467.3836 1.715773 39.99228 59.99812
45.45000 468.0538 1.714353 39.99534 59.99370
45.51666 468.7228 1.712878 40.00890 59.99537
45.58333 469.3984 1.712236 39.99869 59.98752
45.65000 470.0552 1.709215 39.99454 59.99444
45.71667 470.7154 1.707799 40.00519 60.01410
45.78333 471.3772 1.705888 39.99515 60.00316
45.85000 472.0578 1.706159 39.99209 59.99370
45.91667 472.7310 1.704482 39.99507 59.99258
45.98334 473.3900 1.702237 40.00701 59.99763
46.05000 474.0545 1.700894 39.99188 60.01184
46.11666 474.7246 1.700169 39.98934 59.98928
46.18334 475.3978 1.699302 39.99447 59.99928
46.25000 476.0624 1.697469 39.99887 60.00516
46.31666 476.7204 1.695429 39.98990 60.00108
46.38334 477.3830 1.693969 40.00520 59.99280
46.45000 478.0585 1.693470 39.99714 60.01343
46.51666 478.7290 1.692137 40.00691 59.99141
46.58333 479.3982 1.691110 40.00341 60.00157
46.65000 480.0620 1.689528 39.99454 60.01192
46.71667 480.7238 1.687855 39.99674 59.99913
46.78333 481.3906 1.686964 39.99904 60.00388
46.85000 482.0630 1.686278 39.99145 59.99284
46.91667 482.7433 1.686349 40.00446 59.99882
46.98334 483.4010 1.683742 40.00291 59.99557
47.05000 484.0647 1.682933 40.00346 60.00709
47.11666 484.7222 1.680961 39.99028 59.99869
47.18334 485.3988 1.681212 40.00196 59.99691
47.25000 486.0705 1.680004 40.00122 60.00220
47.31666 486.7389 1.679061 40.00760 60.01395
47.38334 487.3990 1.677251 39.99951 60.01209
47.45000 488.0658 1.676688 40.00872 59.99836
47.51666 488.7342 1.675795 40.00109 59.98891
47.58333 489.3986 1.674188 39.99703 59.99837
47.65000 490.0640 1.673286 40.00159 59.99359
47.71667 490.7326 1.672438 40.01038 59.99246
47.78333 491.4023 1.671665 40.00070 60.00211
47.85000 492.0687 1.670689 40.00674 60.00639
47.91667 492.7496 1.671110 39.99155 59.98836
47.98334 493.4131 1.669698 39.99216 60.00200
48.05000 494.0720 1.668435 40.01070 59.99670
48.11666 494.7370 1.667773 39.99413 60.00598
48.18334 495.4011 1.666452 39.99580 60.00254
48.25000 496.0708 1.665915 40.00756 60.01565
48.31666 496.7328 1.664151 40.00111 60.00190
48.38334 497.4057 1.664008 40.00828 59.98541
48.45000 498.0698 1.662440 39.99209 60.00938
48.51666 498.7340 1.661496 40.00122 59.99527
48.58333 499.4156 1.662528 40.00150 59.98808
48.65000 500.0846 1.661483 40.00137 59.99297
48.71667 500.7579 1.661730 39.99197 59.99470
48.78333 501.4244 1.661251 40.00508 59.99284
48.85000 502.0766 1.659051 40.00186 59.99796
48.91667 502.7302 1.657412 39.98726 60.00162
48.98334 503.4049 1.657816 40.00410 59.99732
49.05000 504.0734 1.656474 39.99618 59.98970
49.11666 504.7350 1.654872 39.99688 59.99834
49.18334 505.4126 1.655708 40.00291 59.99627
49.25000 506.0906 1.655624 40.00694 59.99109
49.31666 506.7541 1.654440 39.99998 60.00368
49.38334 507.4130 1.653310 40.00606 59.98890
49.45000 508.0722 1.652333 39.99214 60.00037
49.51666 508.7468 1.652652 39.99994 59.99348
49.58333 509.4204 1.652359 39.99770 60.00310
49.65000 510.0762 1.650106 40.00650 60.00367
49.71667 510.7516 1.650990 40.00114 59.99712
49.78333 511.4196 1.650086 40.00160 59.98938
49.85000 512.0789 1.648594 40.00122 60.00157
49.91667 512.7488 1.648805 40.00012 59.99906
49.98334 513.4209 1.648460 40.00964 60.01138
50.05000 514.0809 1.646762 39.98419 60.00400
50.11666 514.7506 1.646832 39.99226 59.99629
50.18334 515.4308 1.647858 40.01152 59.99026
50.25000 516.0972 1.646988 40.01539 59.99057
50.31666 516.7539 1.645412 39.98265 60.00980
50.38334 517.4094 1.643702 40.01991 60.00044
50.45000 518.0864 1.644762 40.00156 59.99794
50.51666 518.7700 1.645681 39.98870 59.99820
50.58333 519.4344 1.643994 39.99081 60.00288
50.65000 520.0767 1.641018 39.98195 60.00364
50.71667 520.7450 1.641729 39.98360 60.00928
50.78333 521.4212 1.641818 39.98150 60.01874
50.85000 522.0958 1.641834 40.01433 59.97716
50.91667 522.7630 1.641258 39.99435 59.99602
50.98334 523.4290 1.640909 40.01016 60.00137
51.05000 524.0943 1.640661 40.00170 59.98464
51.11666 524.7524 1.639185 39.98419 60.02158
51.18334 525.4196 1.639296 39.99750 60.00683
51.25000 526.0882 1.638709 39.98424 59.99605
51.31666 526.7642 1.639042 40.00552 60.00324
51.38334 527.4302 1.638228 40.01553 59.99980
51.45000 528.0940 1.637711 40.00456 59.99738
51.51667 528.7570 1.637005 39.98897 59.99668
51.58333 529.4285 1.637276 40.00311 60.00156
51.65000 530.0974 1.636707 40.00274 60.00848
51.71667 530.7639 1.636424 40.01345 59.99310
51.78333 531.4234 1.635355 39.99572 60.00914
51.85000 532.0902 1.635042 39.99450 59.99511
51.91667 532.7642 1.635134 39.99350 60.01304
51.98333 533.4301 1.634453 40.01248 60.00229
52.05000 534.1036 1.635143 40.00112 59.99403
52.11666 534.7644 1.633850 40.01834 59.99646
52.18334 535.4266 1.633516 39.98722 59.98480
52.25000 536.0948 1.633147 40.00408 59.99964
52.31666 536.7596 1.632444 40.00700 59.97958
52.38334 537.4299 1.632573 40.00296 59.99078
52.45000 538.1021 1.632569 39.99008 59.99847
52.51668 538.7661 1.631946 39.99791 60.00156
52.58332 539.4360 1.631922 39.99008 60.00888
52.65000 540.1050 1.631565 39.99921 60.00390
52.71668 540.7647 1.630575 39.99557 59.99700
52.78332 541.4286 1.630037 40.01191 60.00320
52.85000 542.0992 1.630270 40.00204 59.99098
52.91668 542.7710 1.630120 40.00486 60.00286
52.98332 543.4371 1.629696 39.98848 60.00243
53.05000 544.1069 1.629703 39.99259 59.99176
53.11666 544.7699 1.629142 40.00192 59.99488
53.18334 545.4304 1.628192 39.99790 59.99502
53.25000 546.0955 1.627790 40.00078 59.99621
53.31666 546.7693 1.628143 39.99757 60.00952
53.38334 547.4438 1.628251 40.00470 60.00742
53.45000 548.1084 1.627490 40.00566 59.99592
53.51668 548.7844 1.628969 40.00719 60.00876
53.58332 549.4469 1.628051 40.00428 60.00008
53.65000 550.1090 1.627322 39.99847 60.00085
53.71668 550.7627 1.625791 40.00305 59.98906
53.78332 551.4324 1.626006 40.00881 59.98914
53.85000 552.1050 1.625618 39.99248 60.00088
53.91668 552.7780 1.625909 40.00074 59.99482
53.98332 553.4458 1.625508 40.00912 60.01734
54.05000 554.1166 1.625404 40.00912 59.98868
54.11666 554.7844 1.625519 40.00485 59.99931
54.18334 555.4540 1.625768 40.00099 60.00722
54.25000 556.1168 1.625184 40.00626 59.99778
54.31666 556.7776 1.624365 39.99482 60.00274
54.38334 557.4385 1.623418 40.00589 60.00576
54.45000 558.1064 1.622845 40.00556 59.99637
54.51668 558.7896 1.624686 40.00510 60.00199
54.58332 559.4570 1.623629 39.99782 59.99511
54.65000 560.1215 1.623636 40.00517 59.99391
54.71668 560.7788 1.622588 40.00588 59.99840
54.78332 561.4488 1.623083 40.00218 60.00608
54.85000 562.1184 1.622954 40.00273 60.01102
54.91668 562.7895 1.623099 40.00566 59.99018
54.98332 563.4453 1.621382 40.00385 59.99294
55.05000 564.1129 1.621819 39.99890 59.99358
55.11666 564.7821 1.621519 39.99637 60.00560
55.18334 565.4535 1.621488 39.99762 59.99366
55.25000 566.1257 1.621986 39.99585 59.99942
55.31666 566.7902 1.621404 40.00010 59.99804
55.38334 567.4494 1.620563 39.99939 60.00139
55.45000 568.1145 1.620244 40.00107 59.99057
55.51668 568.7848 1.620362 40.00431 60.00742
55.58332 569.4578 1.620614 40.00615 59.99182
55.65000 570.1268 1.620479 39.99372 59.98415
55.71668 570.7926 1.620156 40.00809 59.99562
55.78332 571.4594 1.620280 40.00568 60.00392
55.85000 572.1214 1.619559 39.99830 59.99174
55.91668 572.7891 1.619626 39.99811 59.99552
55.98332 573.4537 1.618916 39.99683 60.00482
56.05000 574.1240 1.619026 39.99055 60.00020
56.11666 574.7981 1.619569 40.01294 60.00157
56.18334 575.4610 1.618838 39.99652 59.99430
56.25000 576.1278 1.618711 39.99655 59.99402
56.31666 576.7922 1.618210 40.00061 59.98957
56.38334 577.4566 1.617722 40.00668 59.99222
56.45000 578.1314 1.618398 39.99917 59.99965
56.51668 578.8050 1.618546 39.99393 60.01063
56.58332 579.4584 1.616947 40.00378 60.00450
56.65000 580.1256 1.617191 39.99844 59.99595
56.71668 580.8018 1.618261 40.00042 60.00130
56.78332 581.4700 1.617816 39.99817 59.99574
56.85000 582.1320 1.617107 39.98536 60.00210
56.91668 582.7969 1.617088 39.99476 60.01270
56.98332 583.4630 1.616512 39.99791 59.99019
57.05000 584.1277 1.615944 40.00604 59.99702
57.11666 584.8055 1.617165 39.99275 59.98606
57.18334 585.4754 1.616620 39.99347 59.99849
57.25000 586.1336 1.615845 40.00960 60.00183
57.31666 586.8040 1.616562 39.99959 59.99809
57.38334 587.4706 1.616010 40.00026 60.00371
57.45000 588.1374 1.615897 39.98822 59.99170
57.51668 588.8123 1.616510 39.99366 59.99570
57.58332 589.4762 1.615720 40.01029 60.01019
57.65000 590.1400 1.615604 40.00202 59.99188
57.71668 590.7997 1.614456 39.99560 59.99011
57.78332 591.4700 1.614878 39.99892 60.01470
57.85000 592.1416 1.614528 39.99170 59.99274
57.91668 592.8171 1.615428 40.00595 59.99050
57.98332 593.4840 1.615251 40.00359 59.99670
58.05000 594.1410 1.614324 39.98710 60.00845
58.11666 594.8038 1.614012 39.99727 59.99639
58.18334 595.4797 1.614958 39.98574 60.00820