File: TGA/ZIF8cellulose rods sample 4.txt
CLOSED
Version	1.0
Language	English
Run	1
RunSerial	824
Instrument	TGA Q500 V6.7 Build 203
Module	TGA
InstSerial	0500-0499
Operator	at615
File	C:\TA\Data\TGA\ak794\anders\ZIF8cellulose rods sample 4.001
FurnaceType	Standard
Sample	ZIF8 cellulose rods in air s4
Size	4.82900	mg
ProcName
Method
Comment
Xcomment	Pan: Platinum
Xcomment	Gas1: Air
Xcomment	Gas2: Air
Xcomment	Balance Gas: Air 40.0 ml/min
Xcomment	Sample Gas: Air 60.0 ml/min
Text	Cellulose rods and zif8 degradation in air. Sample 4
Kcell	1.00000
TempCal	3	pts	20.00	20.00,364.00	356.00,776.00	770.00
InstCalDate	Weight Date 2013-03-01 10:10:44
Controls	Gas 2  Event Off  Sampling 2.0
Nsig	5
Sig1	Time (min)
Sig2	Temperature (°C)
Sig3	Weight (mg)
Sig4	Balance Purge Flow (mL/min)
Sig5	Sample Purge Flow (mL/min)
AirCoolTime	20.0 min
AutoAnalysis	Off
MacroFile
Date	2013-03-12
Time	09:48:15
OrgMethod	1: Ramp 10.00 °C/min to 600.00 °C
OrgFile	C:\Users\AIM_Group\Desktop\post doc cambridge\Students files\Internships\Anders\anders tga\anders\ZIF8cellulose rods sample 4.001
0.01618334 15.91824 4.828526 40.00746 60.00072
0.05000000 15.96954 4.827945 39.97903 59.99899
0.1166666 16.13331 4.827590 40.01412 60.01006
0.1833334 16.38982 4.827378 39.99028 59.99426
0.2500000 16.72131 4.826984 39.99156 59.98771
0.3166666 17.11548 4.826663 39.99175 60.01042
0.3833333 17.55687 4.826363 39.99242 59.99899
0.4500000 18.03853 4.825862 40.00701 60.00979
0.5166666 18.55032 4.824976 40.00769 60.01872
0.5833332 19.09230 4.824034 39.99806 60.00508
0.6500000 19.65437 4.822935 40.01664 60.00664
0.7166666 20.23703 4.822026 40.00830 59.99426
0.7833334 20.83424 4.821452 40.00266 60.00392
0.8500000 21.44394 4.820876 39.99889 59.99145
0.9166668 22.06318 4.819663 39.99597 60.00981
0.9833334 22.69092 4.818759 40.00942 59.99786
1.050000 23.32732 4.817144 39.98990 59.98945
1.116667 23.96607 4.815828 40.00950 60.00280
1.183333 24.61124 4.814601 39.99839 60.00066
1.250000 25.25798 4.813144 39.99558 60.00485
1.316667 25.90545 4.811798 40.00026 60.00037
1.383333 26.55584 4.810402 39.98882 59.99110
1.450000 27.20588 4.809738 40.00382 59.99488
1.516666 27.85594 4.808472 39.99490 59.98958
1.583334 28.50560 4.806666 39.99930 59.99862
1.650000 29.15540 4.805930 39.99510 60.00028
1.716667 29.80442 4.803700 40.00789 60.00672
1.783333 30.45175 4.802915 40.00024 60.00488
1.850000 31.09863 4.801756 39.99019 60.00764
1.916666 31.74530 4.800650 40.01279 60.00309
1.983334 32.39104 4.798758 40.00272 59.98611
2.050000 33.03614 4.797934 40.00704 60.00257
2.116666 33.68132 4.796308 39.99954 59.98308
2.183334 34.32492 4.794928 40.00522 59.99888
2.250000 34.96942 4.793895 40.00220 60.01171
2.316666 35.61348 4.792498 39.99760 59.99988
2.383334 36.25796 4.791390 39.99933 59.99488
2.450000 36.90300 4.790657 40.00814 60.00243
2.516666 37.54566 4.788680 39.99900 59.99832
2.583333 38.19124 4.787778 40.00006 59.99450
2.650000 38.83779 4.786937 40.00007 60.00126
2.716667 39.48285 4.785339 39.99728 59.99776
2.783333 40.12995 4.784741 39.99408 59.99998
2.850000 40.77658 4.783748 40.01033 59.99304
2.916667 41.42409 4.782274 39.99807 59.99275
2.983334 42.07121 4.781458 40.00116 59.98728
3.050000 42.71922 4.779761 40.00138 59.99004
3.116666 43.36950 4.777584 39.99578 60.00443
3.183334 44.01936 4.776982 40.00492 59.99639
3.250000 44.67004 4.775456 39.99320 60.00479
3.316666 45.32340 4.774796 40.01070 60.00270
3.383334 45.97502 4.773666 40.01076 59.99574
3.450000 46.62918 4.772988 40.00609 60.00205
3.516667 47.28246 4.771752 40.00419 59.99654
3.583333 47.93750 4.770822 39.99023 60.00805
3.650000 48.59224 4.769872 39.99218 60.00726
3.716667 49.24913 4.769092 40.00276 60.00488
3.783333 49.90572 4.768160 39.99135 60.00624
3.850000 50.56306 4.767442 39.99814 60.00480
3.916667 51.21976 4.766422 40.00253 59.99388
3.983333 51.88100 4.765861 39.98590 59.99900
4.050000 52.53998 4.764644 40.01210 59.99932
4.116667 53.19880 4.763746 39.99483 60.00299
4.183334 53.86156 4.763379 40.01050 59.99770
4.250000 54.52300 4.762668 40.00266 59.99592
4.316666 55.18596 4.762036 40.00144 59.98985
4.383333 55.84749 4.761176 39.98947 60.00550
4.450000 56.50810 4.760266 39.99067 60.01990
4.516667 57.17132 4.759606 40.00942 59.99459
4.583334 57.83644 4.759406 39.98000 60.00361
4.650000 58.49842 4.758191 39.99811 59.99758
4.716667 59.16232 4.757846 39.99548 60.00994
4.783333 59.82497 4.757215 39.98436 60.00576
4.850000 60.48940 4.756548 40.01150 59.99140
4.916666 61.15070 4.754950 39.97981 59.99580
4.983333 61.81884 4.755285 40.00682 60.01778
5.050000 62.48376 4.755044 39.99256 59.99211
5.116667 63.14761 4.753762 40.00248 59.99550
5.183334 63.81296 4.753296 40.01208 59.98270
5.250000 64.47890 4.752873 40.00132 59.99798
5.316666 65.14475 4.752222 40.00244 59.99553
5.383332 65.81000 4.751334 39.99781 59.99537
5.450000 66.47590 4.750924 39.99398 59.99913
5.516668 67.14304 4.750670 40.00050 60.00762
5.583334 67.81090 4.750172 39.99841 60.00352
5.650000 68.47714 4.749582 39.99726 59.98684
5.716668 69.14490 4.748874 40.00740 60.01340
5.783332 69.81171 4.748392 39.99532 60.01552
5.850000 70.47779 4.747983 40.01812 59.99137
5.916666 71.14250 4.747054 39.99530 59.99843
5.983332 71.80803 4.746332 40.00744 60.00242
6.050000 72.47421 4.745550 40.00926 60.00186
6.116668 73.14206 4.745198 39.99510 60.01250
6.183334 73.81012 4.744836 39.99059 60.01418
6.250000 74.47765 4.744455 40.00464 59.99205
6.316666 75.14313 4.743197 40.00016 60.00412
6.383332 75.81059 4.742802 39.99512 59.99631
6.450000 76.47866 4.742338 40.00642 60.00094
6.516668 77.14490 4.741370 40.00598 59.99531
6.583334 77.81162 4.740772 40.00803 60.00142
6.650000 78.48071 4.740078 39.99776 59.99614
6.716666 79.14497 4.738860 39.99757 59.99184
6.783334 79.81430 4.738810 40.00910 59.99856
6.850000 80.48222 4.737907 39.99889 60.00118
6.916666 81.14998 4.736950 39.99586 60.00159
6.983332 81.81946 4.736484 40.00363 60.00078
7.050000 82.48824 4.735877 40.00009 60.00830
7.116668 83.15655 4.734920 40.00110 60.00268
7.183334 83.82069 4.733347 40.00034 60.00451
7.250000 84.48457 4.731848 39.99878 59.99982
7.316666 85.15449 4.731574 39.99890 59.99428
7.383332 85.82280 4.730636 39.99418 60.00000
7.450000 86.49038 4.729494 40.00153 59.99195
7.516668 87.15808 4.728354 40.00225 60.00288
7.583334 87.82453 4.727228 39.99761 60.00305
7.650000 88.49112 4.725811 40.00010 60.00637
7.716666 89.15958 4.724924 39.99934 59.99752
7.783334 89.82731 4.723534 40.01091 59.99684
7.850000 90.49171 4.721886 40.00015 60.00395
7.916666 91.15841 4.720837 40.00126 59.99328
7.983332 91.82618 4.719541 40.00326 60.00078
8.050000 92.49181 4.717766 40.00244 60.00504
8.116668 93.15830 4.716463 39.99958 60.00344
8.183334 93.82238 4.714532 40.00944 60.00485
8.250000 94.49085 4.713194 40.01274 60.00626
8.316666 95.15732 4.711319 40.01061 60.00949
8.383332 95.82414 4.709534 39.99170 59.99937
8.450000 96.49272 4.708150 39.98770 60.00864
8.516666 97.15814 4.705951 40.00224 59.98755
8.583332 97.82499 4.703858 40.01408 59.99497
8.650000 98.49212 4.702037 40.00430 59.99717
8.716666 99.15855 4.699768 39.99526 60.00020
8.783334 99.82574 4.697898 39.99988 60.00246
8.850000 100.4926 4.695793 39.98837 59.99913
8.916668 101.1602 4.693516 40.01436 60.01221
8.983334 101.8250 4.691019 39.99006 59.98904
9.050000 102.4927 4.688835 39.98496 60.00237
9.116668 103.1593 4.686194 39.98942 59.99971
9.183334 103.8270 4.683572 40.00867 59.99916
9.250000 104.4924 4.680540 39.99196 60.00892
9.316666 105.1593 4.677783 39.98887 60.00456
9.383332 105.8246 4.675056 40.00454 60.00621
9.450000 106.4932 4.672200 39.99914 60.00937
9.516666 107.1572 4.668754 40.01080 59.98842
9.583332 107.8257 4.665791 40.00156 59.99874
9.650000 108.4928 4.662696 39.99050 60.01098
9.716666 109.1604 4.659207 40.00082 60.00933
9.783334 109.8254 4.655386 39.97615 60.01926
9.850000 110.4903 4.651600 39.97748 60.01518
9.916668 111.1564 4.647813 40.01661 59.99528
9.983334 111.8218 4.644009 39.97956 60.01277
10.05000 112.4889 4.639942 39.99143 60.00276
10.11667 113.1585 4.636171 40.01446 59.98814
10.18333 113.8246 4.631630 40.00260 59.99905
10.25000 114.4934 4.627291 40.00546 59.98154
10.31667 115.1614 4.622566 40.00861 59.99890
10.38333 115.8261 4.617421 39.98692 60.01601
10.45000 116.4916 4.612600 39.99727 60.00496
10.51666 117.1592 4.607700 39.99942 59.98124
10.58333 117.8243 4.602100 39.98526 60.01290
10.65000 118.4907 4.596872 39.99860 59.98668
10.71666 119.1572 4.591374 39.98066 60.01713
10.78334 119.8239 4.585584 40.00240 59.98320
10.85000 120.4906 4.579358 39.99594 60.00005
10.91667 121.1551 4.573225 40.01588 59.98770
10.98334 121.8220 4.567260 40.00228 59.99976
11.05000 122.4884 4.560596 39.98674 60.00482
11.11667 123.1530 4.553778 39.99078 60.00610
11.18334 123.8199 4.547004 40.00217 60.01057
11.25000 124.4862 4.539890 40.00195 60.00618
11.31666 125.1547 4.532825 40.01279 60.00371
11.38333 125.8248 4.525710 39.98968 60.01182
11.45000 126.4947 4.517975 39.99874 59.99989
11.51666 127.1611 4.509589 39.98555 60.00361
11.58333 127.8222 4.500855 39.98728 59.99611
11.65000 128.4843 4.492102 39.98984 59.99051
11.71666 129.1508 4.483604 39.97981 60.00472
11.78334 129.8175 4.474563 39.99626 59.99003
11.85000 130.4887 4.466287 39.99954 59.99598
11.91667 131.1559 4.456602 39.99664 60.00176
11.98334 131.8241 4.446912 40.00327 60.00522
12.05000 132.4915 4.436930 40.00670 60.00056
12.11667 133.1593 4.427030 39.99635 60.00235
12.18334 133.8251 4.416094 40.00286 59.99210
12.25000 134.4922 4.405370 39.99397 60.01116
12.31666 135.1591 4.394127 39.99844 59.99414
12.38333 135.8228 4.382578 39.99955 59.99812
12.45000 136.4903 4.371340 39.98488 60.00834
12.51666 137.1592 4.359818 40.00847 60.00474
12.58333 137.8282 4.347946 39.98821 59.99365
12.65000 138.4951 4.335312 39.99392 59.99871
12.71666 139.1613 4.322590 39.99652 60.00068
12.78334 139.8347 4.310750 40.00009 60.00036
12.85000 140.4990 4.296585 40.00332 59.99930
12.91667 141.1658 4.283290 39.99055 59.99676
12.98334 141.8302 4.269075 39.99312 59.99774
13.05000 142.4924 4.254834 40.00322 60.00412
13.11667 143.1559 4.240511 40.00447 60.00176
13.18333 143.8246 4.226363 39.99790 59.98746
13.25000 144.4912 4.211290 39.99740 59.99451
13.31667 145.1562 4.195990 40.00203 59.99406
13.38333 145.8249 4.180746 40.00090 59.99907
13.45000 146.4915 4.164864 40.00254 60.00422
13.51666 147.1557 4.148450 40.00854 60.00190
13.58333 147.8240 4.132348 40.00864 60.00484
13.65000 148.4904 4.115978 39.99928 59.99880
13.71666 149.1541 4.098719 39.99570 59.98068
13.78334 149.8205 4.081662 39.99726 60.00118
13.85000 150.4858 4.064407 40.00474 60.00049
13.91667 151.1548 4.047030 39.99384 60.00602
13.98334 151.8222 4.029332 40.00096 59.99892
14.05000 152.4862 4.010920 39.99353 59.99280
14.11667 153.1520 3.992764 40.00531 59.99220
14.18333 153.8161 3.974109 39.99602 59.99352
14.25000 154.4838 3.955758 40.00716 59.99432
14.31667 155.1546 3.937358 39.98410 60.00150
14.38333 155.8190 3.917864 39.99555 60.00846
14.45000 156.4824 3.898594 39.98978 59.99584
14.51666 157.1462 3.878853 40.00100 60.00288
14.58333 157.8191 3.860523 40.00320 60.00437
14.65000 158.4821 3.840239 40.00345 60.00558
14.71666 159.1517 3.821144 40.00570 59.98779
14.78334 159.8199 3.801322 39.99708 60.00453
14.85000 160.4823 3.780864 40.00041 59.98801
14.91667 161.1463 3.760897 40.00348 59.99674
14.98334 161.8131 3.741140 40.01042 59.99218
15.05000 162.4804 3.721332 39.99994 59.99359
15.11667 163.1437 3.700939 39.99858 59.99784
15.18333 163.8127 3.681406 40.00944 60.00080
15.25000 164.4790 3.661550 40.00066 59.99305
15.31667 165.1461 3.641870 40.01352 59.98874
15.38333 165.8125 3.622357 40.00592 59.99798
15.45000 166.4825 3.603216 39.99693 59.99614
15.51666 167.1463 3.583208 40.00342 60.00174
15.58333 167.8117 3.564026 39.98887 59.99474
15.65000 168.4799 3.545139 40.00883 60.00711
15.71666 169.1437 3.526044 39.99710 59.98638
15.78334 169.8074 3.507325 39.98908 59.99950
15.85000 170.4704 3.488851 39.99888 59.98559
15.91667 171.1390 3.471117 40.00166 60.01487
15.98334 171.8060 3.453424 39.99356 59.99440
16.05000 172.4725 3.435926 40.00062 59.99074
16.11667 173.1406 3.418921 39.99922 59.99672
16.18333 173.8074 3.402025 40.01042 59.99722
16.25000 174.4728 3.385646 40.01472 59.99826
16.31667 175.1369 3.369304 39.98594 60.00349
16.38333 175.8034 3.353769 39.99110 60.00974
16.45000 176.4672 3.338306 39.98288 60.01135
16.51666 177.1328 3.323355 40.00039 59.99911
16.58334 177.8001 3.308964 39.98561 60.00418
16.65000 178.4662 3.294700 40.00145 59.99163
16.71667 179.1322 3.280669 39.99398 60.01563
16.78333 179.7986 3.267304 40.01050 59.98328
16.85000 180.4608 3.253833 39.99565 59.99358
16.91666 181.1276 3.241128 39.99572 60.00168
16.98334 181.7942 3.228649 39.98650 59.99592
17.05000 182.4634 3.216885 40.00566 59.98750
17.11667 183.1301 3.204963 39.99479 59.98844
17.18333 183.7938 3.193210 39.98404 60.01207
17.25000 184.4611 3.182078 40.01528 59.99742
17.31667 185.1259 3.170786 39.99106 59.99382
17.38333 185.7908 3.159914 39.99502 60.00654
17.45000 186.4520 3.148985 40.00135 59.99158
17.51666 187.1204 3.139093 40.00665 60.00230
17.58334 187.7871 3.128920 40.00768 60.00382
17.65000 188.4549 3.119271 40.00396 59.98882
17.71667 189.1217 3.109328 40.01061 59.99184
17.78333 189.7876 3.099482 39.99619 60.00850
17.85000 190.4531 3.090262 40.00652 59.99370
17.91666 191.1200 3.081146 40.00555 60.00312
17.98334 191.7875 3.072094 39.99896 60.00857
18.05000 192.4503 3.062660 40.00310 59.99850
18.11667 193.1151 3.053853 40.00326 59.99807
18.18333 193.7811 3.044992 40.00212 59.99484
18.25000 194.4444 3.036137 39.99184 59.99805
18.31667 195.1122 3.027850 40.00910 60.00720
18.38333 195.7823 3.019809 40.00088 59.99950
18.45000 196.4486 3.011188 40.01007 60.00402
18.51666 197.1160 3.002910 39.99733 60.00575
18.58334 197.7842 2.995035 40.00368 59.99238
18.65000 198.4504 2.986674 39.99486 60.01516
18.71667 199.1161 2.978562 39.99086 60.00085
18.78333 199.7819 2.970548 39.99656 59.99004
18.85000 200.4483 2.962576 39.99992 59.99504
18.91666 201.1110 2.954147 39.99732 59.99813
18.98334 201.7785 2.946553 39.99812 59.99674
19.05000 202.4447 2.938646 39.99076 59.99942
19.11667 203.1115 2.930978 39.99149 59.99314
19.18333 203.7765 2.923030 39.98589 59.99683
19.25000 204.4412 2.915152 39.99344 59.99618
19.31667 205.1102 2.907944 40.00337 60.00239
19.38333 205.7766 2.899967 39.99578 59.99200
19.45000 206.4444 2.892440 39.99409 59.99692
19.51666 207.1077 2.884480 40.00435 59.99838
19.58334 207.7751 2.877146 39.99277 59.99816
19.65000 208.4450 2.870061 40.01045 60.00528
19.71667 209.1106 2.862434 39.99779 59.99929
19.78333 209.7756 2.854807 39.99158 59.99595
19.85000 210.4412 2.847384 40.00415 59.99594
19.91666 211.1066 2.839724 40.00503 60.00560
19.98334 211.7714 2.832002 40.00004 59.99291
20.05000 212.4389 2.824596 39.99011 59.99338
20.11667 213.1034 2.816786 39.99560 60.00736
20.18333 213.7725 2.809341 40.00744 59.99861
20.25000 214.4415 2.801554 39.99585 59.99838
20.31667 215.1075 2.793205 40.01282 60.00550
20.38333 215.7708 2.784560 40.00201 59.99244
20.45000 216.4374 2.776147 39.98748 59.98675
20.51666 217.1065 2.767523 40.01224 60.01158
20.58334 217.7710 2.757880 39.98700 59.97586
20.65000 218.4355 2.747038 39.99047 60.00358
20.71667 219.1035 2.734641 40.01553 60.01670
20.78333 219.7777 2.721068 39.98781 59.98057
20.85000 220.4431 2.706174 39.99294 59.98486
20.91666 221.1124 2.691197 40.00296 60.00351
20.98334 221.7804 2.674173 39.99500 60.00493
21.05000 222.4485 2.652688 39.98528 60.00744
21.11667 223.1220 2.622568 40.00377 60.00302
21.18333 223.8002 2.592206 40.01648 60.00729
21.25000 224.4710 2.569214 40.00029 60.00966
21.31667 225.1305 2.551185 40.00806 59.98960
21.38333 225.7855 2.536652 39.98096 59.98489
21.45000 226.4376 2.524115 39.98956 59.99135
21.51666 227.0895 2.512970 40.02302 60.01604
21.58334 227.7491 2.503331 39.99553 60.00455
21.65000 228.4121 2.494534 39.99706 60.00970
21.71667 229.0740 2.486035 39.99174 59.98618
21.78333 229.7424 2.478624 39.99776 60.00322
21.85000 230.4093 2.471278 39.99620 60.00332
21.91666 231.0763 2.464472 40.00060 59.99993
21.98334 231.7390 2.457755 39.99966 59.99572
22.05000 232.4090 2.452200 40.00787 60.01087
22.11667 233.0788 2.446987 39.99285 59.97960
22.18333 233.7479 2.441817 40.00292 59.99939
22.25000 234.4094 2.436177 40.00250 60.00843
22.31667 235.0766 2.432020 39.99786 60.01096
22.38333 235.7504 2.428352 39.99353 60.00000
22.45000 236.4137 2.423580 39.98930 60.00426
22.51666 237.0844 2.420148 39.99972 59.99816
22.58334 237.7502 2.416153 39.98518 59.99028
22.65000 238.4147 2.412347 39.99890 59.99849
22.71667 239.0782 2.408768 40.00175 60.00274
22.78333 239.7430 2.405458 40.00026 60.00012
22.85000 240.4120 2.402566 39.99856 60.01046
22.91666 241.0830 2.399990 40.00381 59.99700
22.98334 241.7485 2.396508 39.99380 59.99890
23.05000 242.4155 2.393457 39.99959 60.00248
23.11667 243.0805 2.390485 39.99258 59.99563
23.18333 243.7506 2.388186 39.99548 60.00080
23.25000 244.4194 2.385476 40.00148 60.00044
23.31667 245.0856 2.382470 39.99974 59.99965
23.38333 245.7541 2.380020 40.00322 60.00646
23.45000 246.4205 2.377203 40.00107 59.99465
23.51666 247.0867 2.374255 40.00308 60.00886
23.58334 247.7472 2.371105 39.98680 59.99789
23.65000 248.4150 2.368717 39.99734 59.99576
23.71667 249.0850 2.366425 39.99883 60.01151
23.78333 249.7530 2.363739 39.99919 60.00461
23.85000 250.4126 2.360054 39.99441 59.99565
23.91666 251.0773 2.357410 39.99754 59.99076
23.98334 251.7452 2.354929 40.00375 59.99218
24.05000 252.4115 2.351950 40.00938 59.99530
24.11667 253.0860 2.349766 40.00136 59.99260
24.18333 253.7442 2.345640 40.00161 60.00435
24.25000 254.4102 2.342916 39.99410 60.00195
24.31667 255.0881 2.341442 40.00935 59.99911
24.38333 255.7537 2.337750 40.01195 60.00559
24.45000 256.4194 2.334703 39.99732 60.00601
24.51666 257.0818 2.331344 40.00034 59.99387
24.58334 257.7445 2.328116 40.00196 59.99729
24.65000 258.4088 2.324852 39.99328 59.99930
24.71667 259.0782 2.322190 40.00950 60.01332
24.78333 259.7466 2.319019 40.00361 60.00377
24.85000 260.4149 2.315879 40.00488 60.00937
24.91666 261.0829 2.312576 40.00049 60.00709
24.98334 261.7458 2.308800 39.99136 60.00166
25.05000 262.4106 2.305444 40.00430 60.00563
25.11667 263.0760 2.301968 39.99991 60.01207
25.18333 263.7425 2.298528 39.98355 59.99490
25.25000 264.4128 2.295532 39.98436 59.98992
25.31667 265.0858 2.292522 39.99690 59.99946
25.38333 265.7500 2.288322 40.01251 60.01796
25.45000 266.4140 2.284634 40.00728 59.99356
25.51666 267.0804 2.280830 40.00084 60.00560
25.58334 267.7441 2.276938 39.99708 60.00498
25.65000 268.4112 2.273396 40.00502 60.01026
25.71667 269.0776 2.269562 39.99610 59.99320
25.78333 269.7456 2.265599 40.00694 60.01108
25.85000 270.4118 2.261775 40.01041 60.00042
25.91666 271.0784 2.257578 39.99050 59.98855
25.98334 271.7432 2.253310 39.98988 59.99081
26.05000 272.4135 2.249806 39.99883 60.00026
26.11666 273.0804 2.245466 40.01228 59.99711
26.18333 273.7447 2.240967 40.00131 60.00331
26.25000 274.4115 2.236762 40.00815 60.00618
26.31667 275.0726 2.231874 39.99086 60.01461
26.38334 275.7450 2.228345 39.99822 59.98856
26.45000 276.4103 2.223345 39.99614 60.00312
26.51666 277.0741 2.218722 39.98240 59.99534
26.58334 277.7403 2.214106 40.01008 60.01055
26.65000 278.4074 2.209556 40.00444 60.00717
26.71667 279.0726 2.204685 39.99142 59.99505
26.78333 279.7390 2.199775 40.00031 59.99146
26.85000 280.4065 2.194891 39.99766 59.99632
26.91666 281.0722 2.189804 39.98945 60.01134
26.98334 281.7377 2.184570 40.00685 59.99898
27.05000 282.4062 2.179597 40.00340 60.00972
27.11666 283.0715 2.174412 39.99286 59.99708
27.18333 283.7377 2.168997 40.00142 60.00278
27.25000 284.4064 2.163970 39.99224 59.98859
27.31667 285.0728 2.158199 40.00100 59.99169
27.38334 285.7443 2.153068 40.00070 60.00771
27.45000 286.4112 2.147426 39.99448 59.98921
27.51666 287.0686 2.140690 39.99732 59.99816
27.58334 287.7368 2.135450 40.00526 59.99594
27.65000 288.4050 2.129778 39.99805 59.99785
27.71667 289.0706 2.123582 39.99046 59.99480
27.78333 289.7363 2.117354 39.99026 60.00635
27.85000 290.4047 2.111481 39.99618 60.00484
27.91666 291.0768 2.105654 40.00937 59.99906
27.98334 291.7394 2.098579 39.99025 59.99683
28.05000 292.4053 2.092158 40.00183 60.00147
28.11666 293.0682 2.085459 40.00040 60.00061
28.18333 293.7306 2.078470 39.99680 59.99934
28.25000 294.3995 2.072112 39.98680 59.99746
28.31667 295.0697 2.065604 39.99702 59.99972
28.38334 295.7356 2.058345 39.98713 59.98891
28.45000 296.4030 2.051355 40.00113 60.00132
28.51666 297.0732 2.044523 40.00037 60.00513
28.58334 297.7436 2.037716 40.00326 59.99238
28.65000 298.4111 2.030213 40.00422 60.00000
28.71667 299.0712 2.022403 39.99648 59.98328
28.78333 299.7364 2.014979 40.00052 59.99843
28.85000 300.4014 2.007575 39.99424 59.99556
28.91666 301.0653 1.999760 40.00686 60.01153
28.98334 301.7364 1.992696 39.99700 59.98662
29.05000 302.4078 1.985324 40.00084 60.00870
29.11666 303.0742 1.977406 39.99148 60.00331
29.18333 303.7359 1.969287 40.00109 59.99356
29.25000 304.3998 1.961024 40.00858 59.98190
29.31667 305.0677 1.953588 39.99458 60.01458
29.38334 305.7315 1.945420 40.00389 59.98946
29.45000 306.4019 1.937879 40.00700 59.98328
29.51666 307.0652 1.929256 40.02208 59.98762
29.58334 307.7310 1.921272 39.98470 60.00979
29.65000 308.3956 1.913051 40.00195 59.98760
29.71667 309.0594 1.904754 40.00147 60.00256
29.78333 309.7267 1.896767 40.00174 60.00200
29.85000 310.3953 1.888918 40.01494 59.99644
29.91666 311.0618 1.880656 39.99704 60.00006
29.98334 311.7270 1.872171 39.99547 60.00588
30.05000 312.3924 1.863861 39.99770 59.99910
30.11666 313.0580 1.855651 39.99560 59.99582
30.18333 313.7256 1.847541 39.99014 60.00213
30.25000 314.3926 1.839401 40.00296 60.01038
30.31667 315.0610 1.831509 39.99802 59.99091
30.38334 315.7282 1.823311 39.99900 59.99954
30.45000 316.3910 1.814830 40.00046 60.00758
30.51666 317.0512 1.806413 40.01044 60.00318
30.58334 317.7238 1.799134 39.99219 60.00010
30.65000 318.3900 1.791036 40.00900 60.00268
30.71667 319.0604 1.783307 39.99022 60.00340
30.78333 319.7238 1.775170 40.00537 59.99687
30.85000 320.3860 1.767256 40.00734 60.00709
30.91666 321.0529 1.759630 39.99639 60.00280
30.98334 321.7210 1.751778 39.99469 60.00000
31.05000 322.3915 1.744430 39.98691 60.00210
31.11666 323.0579 1.736928 39.99567 60.00305
31.18333 323.7236 1.729761 40.00587 59.99853
31.25000 324.3794 1.721594 39.99852 59.99838
31.31667 325.0544 1.715865 39.99958 60.00408
31.38334 325.7232 1.709138 40.00247 60.00568
31.45000 326.3867 1.701937 40.00952 60.00086
31.51666 327.0532 1.695856 39.99870 59.99224
31.58334 327.7262 1.690240 39.99217 59.99594
31.65000 328.3943 1.684197 39.99502 60.00414
31.71667 329.0672 1.678987 40.00656 59.99688
31.78333 329.7294 1.672701 39.98620 60.00933
31.85000 330.3914 1.666985 40.00240 59.99959
31.91666 331.0512 1.661344 39.99289 59.99771
31.98334 331.7156 1.656424 39.99953 59.99816
32.05000 332.3800 1.651300 39.98780 60.00368
32.11666 333.0540 1.647203 40.00594 59.98906
32.18334 333.7244 1.642809 39.99646 59.99824
32.25000 334.3982 1.638999 39.99094 60.00504
32.31666 335.0605 1.634079 40.00728 59.99307
32.38334 335.7269 1.630414 40.00211 59.99765
32.45000 336.3900 1.626288 40.00878 59.98928
32.51666 337.0572 1.622737 39.99657 59.99970
32.58333 337.7190 1.618775 40.01519 59.98796
32.65000 338.3850 1.615479 40.00032 60.00132
32.71667 339.0536 1.612352 39.98842 60.02053
32.78333 339.7262 1.609557 40.01623 59.99082
32.85000 340.3959 1.606703 40.00518 59.99724
32.91667 341.0622 1.603620 40.00052 60.00440
32.98334 341.7274 1.600649 40.01258 59.98944
33.05000 342.3944 1.598182 40.00532 60.00097
33.11666 343.0596 1.595468 40.00857 59.99288
33.18334 343.7290 1.593306 39.99009 60.00912
33.25000 344.3952 1.590777 39.99927 59.99740
33.31666 345.0574 1.588118 40.01500 59.98972
33.38334 345.7258 1.586258 40.00528 60.00543
33.45000 346.4011 1.584581 39.98724 60.00380
33.51666 347.0653 1.581844 40.01514 59.99060
33.58333 347.7308 1.579974 40.00220 59.98451
33.65000 348.3970 1.577830 40.00356 59.98115
33.71667 349.0626 1.575904 39.99405 60.00163
33.78333 349.7281 1.573755 39.99289 59.99895
33.85000 350.3977 1.572087 39.99348 59.99897
33.91667 351.0632 1.569964 40.00125 59.99313
33.98334 351.7283 1.568071 39.99784 59.99130
34.05000 352.3943 1.566198 40.00550 60.00410
34.11666 353.0626 1.564648 39.99610 60.00782
34.18334 353.7317 1.562819 40.00217 59.99954
34.25000 354.3994 1.561017 39.99234 60.00390
34.31666 355.0690 1.559569 40.00232 60.00622
34.38334 355.7312 1.557460 40.00020 60.00549
34.45000 356.3989 1.555906 39.99156 60.00709
34.51666 357.0721 1.554737 39.99347 59.99788
34.58333 357.7318 1.552273 40.00328 59.99724
34.65000 358.4024 1.551166 40.00700 60.00468
34.71667 359.0743 1.549780 40.00592 60.00115
34.78333 359.7308 1.547079 40.00878 59.99498
34.85000 360.3956 1.545777 39.99496 60.00361
34.91667 361.0600 1.543855 40.00825 60.01145
34.98334 361.7240 1.541785 40.00156 60.00115
35.05000 362.4014 1.541079 39.99358 59.99974
35.11666 363.0750 1.539639 40.00000 60.00230
35.18334 363.7418 1.537842 39.98820 60.00769
35.25000 364.4066 1.536145 39.99158 60.01204
35.31666 365.0726 1.534496 40.00202 60.01179
35.38334 365.7380 1.532692 40.00020 59.99745
35.45000 366.4048 1.531129 40.00141 59.99646
35.51666 367.0683 1.529152 39.99150 59.97426
35.58333 367.7336 1.527496 39.99594 59.99809
35.65000 368.4031 1.526404 40.00209 59.99747
35.71667 369.0650 1.524372 39.98290 60.00961
35.78333 369.7290 1.522920 40.01772 59.99444
35.85000 370.3876 1.521123 39.99670 59.99978
35.91667 371.0509 1.519792 40.00308 59.99039
35.98334 371.7181 1.518360 40.01820 59.99148
36.05000 372.3875 1.516691 40.00750 59.99798
36.11666 373.0614 1.515331 40.00554 59.98599
36.18334 373.7284 1.513390 39.99822 59.99206
36.25000 374.3956 1.511470 40.00878 59.99468
36.31666 375.0584 1.509214 39.99469 60.00926
36.38334 375.7294 1.508022 40.00344 60.01074
36.45000 376.4087 1.507364 39.98614 59.99615
36.51666 377.0842 1.506014 39.99006 59.98954
36.58333 377.7506 1.504217 40.00591 60.00692
36.65000 378.4140 1.502272 39.99896 59.99711
36.71667 379.0728 1.500438 40.00247 60.00627
36.78333 379.7345 1.498710 40.00183 60.00938
36.85000 380.4000 1.497108 40.01111 60.00063
36.91667 381.0656 1.495312 40.00163 60.00865
36.98334 381.7336 1.493999 40.00678 60.00274
37.05000 382.4033 1.492510 40.00663 60.01232
37.11666 383.0683 1.490674 40.00266 59.99441
37.18334 383.7366 1.489347 40.00470 59.98780
37.25000 384.4048 1.487808 40.01354 59.99096
37.31666 385.0716 1.486156 40.00754 59.99727
37.38334 385.7410 1.484963 40.00388 59.99820
37.45000 386.4086 1.483358 40.00319 60.00476
37.51666 387.0768 1.482016 40.00016 60.00666
37.58333 387.7383 1.479912 39.99550 59.99363
37.65000 388.4039 1.478481 39.99752 60.00272
37.71667 389.0702 1.476980 39.99413 59.99836
37.78333 389.7369 1.475362 40.00031 60.00118
37.85000 390.4032 1.473836 39.99560 60.00170
37.91667 391.0697 1.472230 39.99878 59.99457
37.98334 391.7370 1.470706 39.99226 59.99470
38.05000 392.4017 1.469064 40.01117 59.99200
38.11666 393.0691 1.467461 39.99896 60.00515
38.18334 393.7354 1.465921 39.99914 60.01470
38.25000 394.4006 1.464306 40.01365 60.00512
38.31666 395.0695 1.462880 39.99368 60.00283
38.38334 395.7390 1.461475 39.98860 59.99728
38.45000 396.4048 1.459734 39.99850 59.99874
38.51666 397.0700 1.457982 40.00400 60.00251
38.58333 397.7352 1.456440 40.01352 60.00202
38.65000 398.4038 1.455132 39.98663 59.99864
38.71667 399.0722 1.453625 39.98746 59.99852
38.78333 399.7355 1.451749 40.01468 59.98950
38.85000 400.4056 1.450572 40.00800 59.99402
38.91667 401.0764 1.449082 39.99590 59.99872
38.98334 401.7442 1.447752 39.99649 59.98838
39.05000 402.4058 1.445714 40.00104 59.99658
39.11666 403.0721 1.444224 39.99745 59.98213
39.18334 403.7405 1.442823 39.98566 59.98283
39.25000 404.4074 1.441186 39.98350 59.98943
39.31666 405.0742 1.439577 39.99048 59.98564
39.38334 405.7426 1.437994 40.01076 60.02092
39.45000 406.4125 1.436896 40.00035 60.00913
39.51666 407.0774 1.435017 40.01434 59.99754
39.58333 407.7388 1.433034 39.98935 59.98513
39.65000 408.4066 1.431912 40.00488 59.99230
39.71667 409.0729 1.430136 39.99117 59.99826
39.78333 409.7465 1.429274 39.99714 59.99820
39.85000 410.4170 1.427769 39.99414 59.99012
39.91667 411.0800 1.425886 39.98019 59.99541
39.98334 411.7374 1.423476 39.99186 60.01125
40.05000 412.4038 1.422158 40.00147 59.98316
40.11666 413.0728 1.420886 39.99863 59.99628
40.18334 413.7465 1.419658 40.00144 59.99372
40.25000 414.4124 1.417839 40.00562 59.98980
40.31666 415.0778 1.416106 40.00044 59.99754
40.38334 415.7428 1.414561 40.00220 59.99687
40.45000 416.4128 1.413224 40.00832 60.01248
40.51666 417.0777 1.411540 39.99128 59.99824
40.58333 417.7387 1.409290 40.00210 59.99868
40.65000 418.4140 1.408715 40.00912 60.00576
40.71667 419.0832 1.407014 40.01286 60.00709
40.78333 419.7502 1.405497 40.00494 59.99766
40.85000 420.4098 1.403177 39.99884 60.00669
40.91667 421.0768 1.401937 40.00666 59.98863
40.98334 421.7416 1.400156 40.00298 59.99074
41.05000 422.4058 1.398089 40.00437 59.99488
41.11666 423.0796 1.397144 39.98639 59.99318
41.18334 423.7506 1.395746 39.99806 59.99835
41.25000 424.4148 1.393658 40.00120 59.99824
41.31666 425.0850 1.392511 39.99691 59.98496
41.38334 425.7491 1.390539 39.99524 59.99684
41.45000 426.4122 1.388754 39.98553 59.98799
41.51666 427.0816 1.387359 39.99491 60.00718
41.58333 427.7507 1.385902 40.00134 59.99688
41.65000 428.4150 1.384022 40.00674 60.00984
41.71667 429.0816 1.382485 40.00369 59.99352
41.78333 429.7486 1.380869 39.99466 60.00101
41.85000 430.4098 1.378634 39.99785 59.99424
41.91667 431.0824 1.377794 40.00081 59.99598
41.98334 431.7522 1.376109 39.99970 60.01608
42.05000 432.4212 1.374563 39.99020 59.99680
42.11666 433.0840 1.372512 40.01056 59.99433
42.18334 433.7475 1.370536 40.01556 60.00596
42.25000 434.4142 1.368874 39.99228 59.98075
42.31666 435.0814 1.367044 39.99897 59.99854
42.38334 435.7490 1.365523 39.99809 60.00193
42.45000 436.4168 1.363708 39.98760 59.99701
42.51666 437.0890 1.362471 40.00405 60.00414
42.58333 437.7562 1.360456 40.00688 59.99826
42.65000 438.4246 1.359048 40.00701 60.00302
42.71667 439.0944 1.357752 39.98368 60.00227
42.78333 439.7598 1.356000 39.99250 59.99969
42.85000 440.4121 1.352669 39.99012 60.00651
42.91667 441.0824 1.351858 39.99893 60.00014
42.98334 441.7488 1.350083 40.00470 59.99804
43.05000 442.4140 1.347698 40.00319 60.00782
43.11666 443.0838 1.346204 39.99082 59.99282
43.18334 443.7480 1.343772 39.99617 59.99692
43.25000 444.4189 1.342452 39.99662 59.99602
43.31666 445.0867 1.340270 40.00331 60.00163
43.38334 445.7554 1.338516 39.99338 60.00276
43.45000 446.4231 1.336687 39.99528 60.00818
43.51666 447.0902 1.334833 40.00874 59.99330
43.58333 447.7522 1.332413 40.00180 60.00230
43.65000 448.4172 1.330331 39.99823 60.00753
43.71667 449.0842 1.328182 39.99412 59.99560
43.78333 449.7506 1.326188 39.99352 60.00422
43.85000 450.4205 1.324124 40.00598 59.99070
43.91667 451.0953 1.322666 40.00580 60.00310
43.98334 451.7658 1.320678 39.99714 60.00141
44.05000 452.4283 1.318184 40.00398 59.99384
44.11666 453.0943 1.316083 40.01428 60.00059
44.18334 453.7566 1.313663 40.01503 59.99450
44.25000 454.4234 1.311499 40.01422 60.01476
44.31666 455.0894 1.308936 39.98664 59.98691
44.38334 455.7561 1.306704 39.99370 60.00224
44.45000 456.4288 1.304662 39.99158 59.99844
44.51666 457.1068 1.303347 40.01855 59.99730
44.58333 457.7656 1.299914 39.99046 59.98922
44.65000 458.4269 1.297242 39.98539 59.98321
44.71667 459.0939 1.295040 40.00994 59.98188
44.78333 459.7610 1.292342 40.00956 60.00101
44.85000 460.4333 1.290133 40.00788 60.00100
44.91667 461.0976 1.287276 40.00728 59.98359
44.98334 461.7691 1.285402 39.99116 60.00526
45.05000 462.4370 1.282785 39.99864 59.99722
45.11666 463.1036 1.280303 39.98726 60.00729
45.18334 463.7716 1.277912 40.00516 60.00551
45.25000 464.4333 1.274905 39.99850 60.00508
45.31666 465.0964 1.271943 39.99610 60.00571
45.38334 465.7610 1.268980 39.99403 60.00037
45.45000 466.4353 1.266935 40.00386 59.97432
45.51666 467.1062 1.264395 39.99875 59.99800
45.58333 467.7747 1.261736 40.01617 60.00430
45.65000 468.4386 1.258505 39.99690 59.99494
45.71667 469.1043 1.255854 40.00713 59.99776
45.78333 469.7728 1.253146 40.00014 59.99876
45.85000 470.4354 1.249881 40.00154 60.00240
45.91667 471.1032 1.246979 39.99477 59.98515
45.98334 471.7785 1.244837 39.99859 60.00506
46.05000 472.4428 1.241319 39.99542 60.00108
46.11666 473.1068 1.237930 40.01263 60.00391
46.18334 473.7704 1.234919 40.00774 59.99355
46.25000 474.4394 1.231905 40.00272 59.99444
46.31666 475.1061 1.228712 39.99817 60.00476
46.38334 475.7762 1.225537 39.99680 60.00699
46.45000 476.4464 1.222534 39.99913 59.99944
46.51666 477.1107 1.218662 40.01434 59.99717
46.58333 477.7758 1.215344 39.98413 60.00539
46.65000 478.4409 1.211769 39.99730 60.00192
46.71667 479.1134 1.208763 40.00212 59.99302
46.78333 479.7802 1.204844 39.98715 60.01250
46.85000 480.4480 1.201165 40.00700 59.98342
46.91667 481.1131 1.197321 39.99288 59.99982
46.98334 481.7800 1.193680 40.01067 60.00807
47.05000 482.4490 1.189806 40.01308 59.98784
47.11666 483.1148 1.185759 39.98168 60.01063
47.18334 483.7873 1.182378 40.00996 60.00020
47.25000 484.4482 1.176955 40.01288 60.00008
47.31666 485.1191 1.173450 39.99675 60.00076
47.38334 485.7833 1.168310 39.99534 60.00108
47.45000 486.4540 1.164425 40.01460 60.01057
47.51666 487.1156 1.158921 40.01360 59.98719
47.58333 487.7896 1.155035 40.00336 59.99473
47.65000 488.4544 1.149191 39.99204 60.00698
47.71667 489.1230 1.144305 40.01478 59.99104
47.78333 489.7957 1.139388 39.99870 59.99590
47.85000 490.4640 1.133967 39.99302 59.99609
47.91667 491.1275 1.127812 39.99839 59.99459
47.98334 491.7903 1.121534 40.00117 59.99562
48.05000 492.4590 1.115335 40.00168 59.99853
48.11666 493.1279 1.109023 40.00167 59.99560
48.18334 493.7963 1.102272 40.01009 59.99778
48.25000 494.4667 1.095574 40.00694 59.99410
48.31666 495.1430 1.089436 40.00424 59.99052
48.38334 495.8017 1.080659 40.00631 59.99560
48.45000 496.4650 1.073102 39.99744 60.00150
48.51666 497.1294 1.064723 39.99822 60.00079
48.58333 497.7997 1.056528 40.00462 60.00352
48.65000 498.4692 1.047648 40.00684 59.99726
48.71667 499.1372 1.038397 40.00586 60.00179
48.78333 499.8062 1.029042 40.00040 59.98680
48.85000 500.4770 1.019810 39.98878 59.99642
48.91667 501.1413 1.009612 40.00082 59.99515
48.98334 501.8064 0.9988556 39.99875 60.00081
49.05000 502.4725 0.9882141 39.99454 59.99265
49.11666 503.1319 0.9763149 39.99555 59.99182
49.18334 503.8006 0.9654004 39.98572 59.99015
49.25000 504.4731 0.9543024 40.00525 60.01113
49.31666 505.1450 0.9429202 40.00746 59.99698
49.38334 505.7970 0.9292528 39.98146 60.00902
49.45000 506.4704 0.9183447 40.02445 59.98666
49.51666 507.1348 0.9054660 40.01196 60.01116
49.58333 507.8033 0.8931894 39.98299 60.00499
49.65000 508.4662 0.8803749 39.98288 60.00070
49.71667 509.1264 0.8672535 39.99434 59.99731
49.78333 509.7918 0.8546028 40.00097 60.00140
49.85000 510.4610 0.8423681 39.98867 59.99794
49.91667 511.1287 0.8296416 40.00586 59.98790
49.98334 511.7976 0.8175157 39.99451 60.01063
50.05000 512.4602 0.8048030 40.00898 59.99238
50.11666 513.1240 0.7922043 40.00044 59.98332
50.18334 513.7862 0.7796820 39.99228 59.99918
50.25000 514.4486 0.7687126 40.00010 60.00129
50.31666 515.1166 0.7598722 40.00916 60.00296
50.38334 515.7902 0.7488055 40.00036 59.98305
50.45000 516.4567 0.7371516 39.97992 60.00297
50.51666 517.1175 0.7250032 39.99907 60.00340
50.58333 517.7856 0.7136988 39.99844 59.99672
50.65000 518.4553 0.7034282 39.99182 59.99213
50.71667 519.1206 0.6916800 40.00420 59.99899
50.78333 519.7852 0.6806996 40.00094 59.99384
50.85000 520.4537 0.6704080 40.00503 60.00510
50.91667 521.1221 0.6601371 39.99808 60.01179
50.98334 521.7890 0.6499818 39.99434 60.00590
51.05000 522.4494 0.6399114 39.99365 60.00234
51.11666 523.1219 0.6311666 39.99143 59.98739
51.18334 523.7904 0.6216060 39.99586 59.99901
51.25000 524.4582 0.6116636 39.99038 60.00342
51.31666 525.1256 0.6024988 40.00938 60.00130
51.38334 525.7929 0.5939143 40.01671 60.00524
51.45000 526.4594 0.5851610 39.99163 59.98774
51.51667 527.1294 0.5770750 39.98831 59.99468
51.58333 527.7955 0.5686033 39.97732 59.98601
51.65000 528.4602 0.5607704 40.01140 60.00616
51.71667 529.1238 0.5528635 39.99866 59.99374
51.78333 529.7968 0.5464139 39.99738 60.01943
51.85000 530.4712 0.5396597 39.99979 60.00664
51.91667 531.1319 0.5312053 39.99782 59.99544
51.98333 531.7902 0.5224375 39.99412 59.99922
52.05000 532.4698 0.5078980 39.99058 59.99875
52.11666 533.1326 0.4991962 40.00888 60.00438
52.18334 533.8057 0.4938576 39.99242 59.99722
52.25000 534.4734 0.4874396 40.00093 59.99580
52.31666 535.1404 0.4812666 40.00082 60.00234
52.38334 535.8116 0.4758326 40.00552 60.00755
52.45000 536.4708 0.4687662 39.99946 59.99694
52.51668 537.1390 0.4636510 39.99903 60.01113
52.58332 537.8090 0.4581171 40.00468 60.00127
52.65000 538.4770 0.4527004 40.00685 59.99907
52.71668 539.1394 0.4469734 39.99642 59.99180
52.78332 539.8032 0.4416948 39.99544 59.99090
52.85000 540.4732 0.4369309 40.00706 60.00648
52.91668 541.1424 0.4322372 39.99776 60.00054
52.98332 541.8142 0.4281733 39.99389 59.99876
53.05000 542.4838 0.4240556 40.00864 60.01316
53.11666 543.1450 0.4192850 40.00415 60.00894
53.18334 543.8067 0.4149392 40.00261 60.00172
53.25000 544.4746 0.4110574 40.00894 59.99570
53.31666 545.1452 0.4076761 40.00200 60.01124
53.38334 545.8140 0.4040800 40.00174 60.00668
53.45000 546.4790 0.4004040 39.99290 60.00578
53.51668 547.1451 0.3971748 40.00676 60.01372
53.58332 547.8140 0.3942270 40.01382 60.01082
53.65000 548.4854 0.3916508 40.00487 60.01518
53.71668 549.1465 0.3882110 40.00075 59.98585
53.78332 549.8120 0.3856040 40.00436 60.01448
53.85000 550.4812 0.3830945 40.01578 60.00230
53.91668 551.1528 0.3810166 40.01386 60.01752
53.98332 551.8200 0.3786747 39.99553 59.99872
54.05000 552.4829 0.3761466 39.98694 60.00166
54.11666 553.1513 0.3744070 39.99172 59.99126
54.18334 553.8224 0.3729044 39.99740 60.01080
54.25000 554.4815 0.3701487 39.99687 59.99538
54.31666 555.1438 0.3679154 39.99461 60.00074
54.38334 555.8241 0.3676118 40.00018 60.00951
54.45000 556.4972 0.3663263 39.99046 59.99352
54.51668 557.1589 0.3642674 39.99286 60.00380
54.58332 557.8178 0.3622582 39.99470 60.00011
54.65000 558.4869 0.3612076 39.99533 59.99990
54.71668 559.1580 0.3602338 40.00117 59.99814
54.78332 559.8293 0.3593388 40.00158 60.00574
54.85000 560.4934 0.3578008 40.00154 59.99685
54.91668 561.1627 0.3570417 39.99648 59.99726
54.98332 561.8347 0.3565459 40.00482 59.98970
55.05000 562.4970 0.3550398 40.00568 59.99168
55.11666 563.1639 0.3543041 40.00359 59.99988
55.18334 563.8305 0.3531955 39.99331 60.00066
55.25000 564.5026 0.3529563 40.00474 60.00014
55.31666 565.1670 0.3517242 39.99579 59.99630
55.38334 565.8346 0.3510933 39.99644 59.99390
55.45000 566.4972 0.3499655 39.99836 60.00097
55.51668 567.1701 0.3496609 39.99580 60.01171
55.58332 567.8409 0.3492665 39.99478 59.99976
55.65000 568.5068 0.3488090 40.01802 60.00708
55.71668 569.1759 0.3487430 40.01180 60.01103
55.78332 569.8370 0.3475808 40.00876 59.99921
55.85000 570.5012 0.3469314 40.00681 59.98779
55.91668 571.1672 0.3459962 39.98539 60.00509
55.98332 571.8391 0.3460901 40.01172 59.99650
56.05000 572.5040 0.3449975 40.00641 59.99475
56.11666 573.1812 0.3457950 39.99485 60.00262
56.18334 573.8501 0.3457624 40.01283 60.00048
56.25000 574.5141 0.3452404 40.00228 59.98784
56.31666 575.1684 0.3433008 39.99756 59.99940
56.38334 575.8390 0.3435650 39.99784 59.99980
56.45000 576.5135 0.3436942 40.00388 59.99816
56.51668 577.1724 0.3421048 39.99023 60.00278
56.58332 577.8414 0.3423319 40.00348 59.99026
56.65000 578.5142 0.3423120 40.00122 59.99487
56.71668 579.1873 0.3425846 39.99520 59.99559
56.78332 579.8464 0.3415580 40.00482 59.99870
56.85000 580.5141 0.3414303 39.98918 60.01308
56.91668 581.1807 0.3411112 40.00114 60.00988
56.98332 581.8476 0.3408197 40.00294 59.99196
57.05000 582.5170 0.3409016 39.99825 59.98861
57.11666 583.1822 0.3402203 39.99405 60.00722
57.18334 583.8489 0.3397047 40.00174 59.99536
57.25000 584.5182 0.3401764 40.00300 60.00251
57.31666 585.1852 0.3396545 39.98266 59.99484
57.38334 585.8564 0.3399626 40.00093 59.98855
57.45000 586.5180 0.3392590 39.99495 60.00429
57.51668 587.1826 0.3389361 40.00294 60.00076
57.58332 587.8490 0.3385816 39.99841 60.01182
57.65000 588.5190 0.3387456 40.01365 60.00144
57.71668 589.1884 0.3385612 40.01636 59.99406
57.78332 589.8584 0.3383635 40.01220 59.99014
57.85000 590.5308 0.3393550 40.01816 59.97474
57.91668 591.1834 0.3374836 39.98692 60.00203
57.98332 591.8444 0.3365982 39.98465 60.01438
58.05000 592.5266 0.3382362 39.99460 60.01120
58.11666 593.2022 0.3385440 39.99544 59.99860
58.18334 593.8662 0.3381024 39.99230 59.99855
58.25000 594.5238 0.3375567 40.00199 60.00250
58.31666 595.1843 0.3365884 40.00140 60.00080
58.35000 595.5208 0.3369034 39.99248 60.00650